Workbook

Sheet Cover
B4: RESELLER TOOLKIT • KIT PARA REVENDEDORES
B6: ProfitTrack
B9: Reseller Expense & Mileage Tracker
B10: Registro de Gastos y Millaje para Revendedores
B11: eBay • Facebook Marketplace • Etsy • Poshmark • Mercari • Depop
B15: WHAT'S INSIDE / CONTENIDO (click to open • clic para abrir)
C17: 📊 Dashboard / Panel
C18: Tax-year totals, deductions by category, monthly chart / Totales del año fiscal, deducciones por categoría, gráfica mensual
C20: 🧾 Expenses / Gastos
C21: Log every business expense – deductible amount auto-calculated / Registra cada gasto – monto deducible automático
C23: 🚗 Mileage / Millaje
C24: Log trips – miles × IRS rate by date, automatically / Registra viajes – millas × tarifa del IRS por fecha, automático
C26: ⚙️ Settings / Configuración
C27: IRS mileage rates & your expense categories / Tarifas del IRS y tus categorías de gastos
C29: 🚀 Quick Start Guide / Guía Rápida
C30: Step-by-step setup in 5 minutes / Configuración paso a paso en 5 minutos
B33: 💻 PC / Mac • 📱 iPhone / Android — Excel • Google Sheets | Computadora y celular — Excel • Google Sheets
B35: Start here → Quick Start Guide | Empieza aquí → Guía Rápida
B38: © ProfitTrack • v1.0 • For personal use only – do not resell or redistribute / Solo para uso personal – prohibida su reventa o distribución

Sheet Dashboard
B1: ProfitTrack
B2: Dashboard / Panel de Control
B3: Your tax-year deductions at a glance. Updates automatically. • Tus deducciones del año fiscal de un vistazo. Se actualiza solo.
B6: Tax Year / Año Fiscal: | C6: =IF(COUNT(Expenses!$B$6:$B$505,Mileage!$B$6:$B$505)=0,YEAR(TODAY()),YEAR(MAX(Expenses!$B$6:$B$505,Mileage!$B$6:$B$505))) -> 2026 | D6: ← type a year to change / escribe un año para cambiar
B8: DEDUCTIBLE EXPENSES | C8: BUSINESS MILES | E8: MILEAGE DEDUCTION | H8: TOTAL DEDUCTIONS
B9: Gastos Deducibles | C9: Millas de Negocio | E9: Deducción por Millaje | H9: Deducciones Totales
B10: =ROUND(SUMIFS(Expenses!$I$6:$I$505,Expenses!$O$6:$O$505,$C$6),2) -> 618.85 | C10: =SUMIFS(Mileage!$J$6:$J$505,Mileage!$Q$6:$Q$505,$C$6) -> 341.3 | E10: =ROUND(SUMIFS(Mileage!$L$6:$L$505,Mileage!$Q$6:$Q$505,$C$6),2) -> 252.44 | H10: =B10+E10 -> 871.29
B11: =SUMIFS(Expenses!$G$6:$G$505,Expenses!$O$6:$O$505,$C$6) -> 707.85 | C11: =COUNTIF(Mileage!$Q$6:$Q$505,$C$6) -> 16 | E11: =IF(C10=0,0,E10/C10) -> 0.73964254 | H11: =SUMIFS(Expenses!$Q$6:$Q$505,Expenses!$O$6:$O$505,$C$6) -> 2
B13: Deductible Expenses by Category / Gastos Deducibles por Categoría
B14: Category Categoría | C14: Entries Registros | D14: Spent Gastado | E14: Deductible Deducible | F14: % of Total % del Total
B15: =IF(Settings!$F$8="","",Settings!$F$8) -> Shipping Supplies / Materiales de Envío | C15: =IF($B15="",0,COUNTIFS(Expenses!$O$6:$O$505,$C$6,Expenses!$E$6:$E$505,$B15)) -> 3 | D15: =IF($B15="",0,ROUND(SUMIFS(Expenses!$G$6:$G$505,Expenses!$O$6:$O$505,$C$6,Expenses!$E$6:$E$505,$B15),2)) -> 94.84 | E15: =IF($B15="",0,ROUND(SUMIFS(Expenses!$I$6:$I$505,Expenses!$O$6:$O$505,$C$6,Expenses!$E$6:$E$505,$B15),2)) -> 94.84 | F15: =IF($E$30=0,0,E15/$E$30) -> 0.153252
B16: =IF(Settings!$F$9="","",Settings!$F$9) -> Postage & Shipping Labels / Envíos y Etiquetas | C16: =IF($B16="",0,COUNTIFS(Expenses!$O$6:$O$505,$C$6,Expenses!$E$6:$E$505,$B16)) -> 1 | D16: =IF($B16="",0,ROUND(SUMIFS(Expenses!$G$6:$G$505,Expenses!$O$6:$O$505,$C$6,Expenses!$E$6:$E$505,$B16),2)) -> 42.75 | E16: =IF($B16="",0,ROUND(SUMIFS(Expenses!$I$6:$I$505,Expenses!$O$6:$O$505,$C$6,Expenses!$E$6:$E$505,$B16),2)) -> 42.75 | F16: =IF($E$30=0,0,E16/$E$30) -> 0.069079745
B17: =IF(Settings!$F$10="","",Settings!$F$10) -> Platform & Subscription Fees / Tarifas y Suscripciones | C17: =IF($B17="",0,COUNTIFS(Expenses!$O$6:$O$505,$C$6,Expenses!$E$6:$E$505,$B17)) -> 1 | D17: =IF($B17="",0,ROUND(SUMIFS(Expenses!$G$6:$G$505,Expenses!$O$6:$O$505,$C$6,Expenses!$E$6:$E$505,$B17),2)) -> 27.95 | E17: =IF($B17="",0,ROUND(SUMIFS(Expenses!$I$6:$I$505,Expenses!$O$6:$O$505,$C$6,Expenses!$E$6:$E$505,$B17),2)) -> 27.95 | F17: =IF($E$30=0,0,E17/$E$30) -> 0.045164418
B18: =IF(Settings!$F$11="","",Settings!$F$11) -> Advertising & Promoted Listings / Publicidad | C18: =IF($B18="",0,COUNTIFS(Expenses!$O$6:$O$505,$C$6,Expenses!$E$6:$E$505,$B18)) -> 2 | D18: =IF($B18="",0,ROUND(SUMIFS(Expenses!$G$6:$G$505,Expenses!$O$6:$O$505,$C$6,Expenses!$E$6:$E$505,$B18),2)) -> 25 | E18: =IF($B18="",0,ROUND(SUMIFS(Expenses!$I$6:$I$505,Expenses!$O$6:$O$505,$C$6,Expenses!$E$6:$E$505,$B18),2)) -> 25 | F18: =IF($E$30=0,0,E18/$E$30) -> 0.040397512
B19: =IF(Settings!$F$12="","",Settings!$F$12) -> Office Supplies / Artículos de Oficina | C19: =IF($B19="",0,COUNTIFS(Expenses!$O$6:$O$505,$C$6,Expenses!$E$6:$E$505,$B19)) -> 2 | D19: =IF($B19="",0,ROUND(SUMIFS(Expenses!$G$6:$G$505,Expenses!$O$6:$O$505,$C$6,Expenses!$E$6:$E$505,$B19),2)) -> 60.89 | E19: =IF($B19="",0,ROUND(SUMIFS(Expenses!$I$6:$I$505,Expenses!$O$6:$O$505,$C$6,Expenses!$E$6:$E$505,$B19),2)) -> 60.89 | F19: =IF($E$30=0,0,E19/$E$30) -> 0.098392179
B20: =IF(Settings!$F$13="","",Settings!$F$13) -> Equipment & Tools / Equipo y Herramientas | C20: =IF($B20="",0,COUNTIFS(Expenses!$O$6:$O$505,$C$6,Expenses!$E$6:$E$505,$B20)) -> 2 | D20: =IF($B20="",0,ROUND(SUMIFS(Expenses!$G$6:$G$505,Expenses!$O$6:$O$505,$C$6,Expenses!$E$6:$E$505,$B20),2)) -> 142.47 | E20: =IF($B20="",0,ROUND(SUMIFS(Expenses!$I$6:$I$505,Expenses!$O$6:$O$505,$C$6,Expenses!$E$6:$E$505,$B20),2)) -> 142.47 | F20: =IF($E$30=0,0,E20/$E$30) -> 0.23021734
B21: =IF(Settings!$F$14="","",Settings!$F$14) -> Phone & Internet / Teléfono e Internet | C21: =IF($B21="",0,COUNTIFS(Expenses!$O$6:$O$505,$C$6,Expenses!$E$6:$E$505,$B21)) -> 2 | D21: =IF($B21="",0,ROUND(SUMIFS(Expenses!$G$6:$G$505,Expenses!$O$6:$O$505,$C$6,Expenses!$E$6:$E$505,$B21),2)) -> 150 | E21: =IF($B21="",0,ROUND(SUMIFS(Expenses!$I$6:$I$505,Expenses!$O$6:$O$505,$C$6,Expenses!$E$6:$E$505,$B21),2)) -> 61 | F21: =IF($E$30=0,0,E21/$E$30) -> 0.098569928
B22: =IF(Settings!$F$15="","",Settings!$F$15) -> Storage & Rent / Almacenaje y Renta | C22: =IF($B22="",0,COUNTIFS(Expenses!$O$6:$O$505,$C$6,Expenses!$E$6:$E$505,$B22)) -> 1 | D22: =IF($B22="",0,ROUND(SUMIFS(Expenses!$G$6:$G$505,Expenses!$O$6:$O$505,$C$6,Expenses!$E$6:$E$505,$B22),2)) -> 65 | E22: =IF($B22="",0,ROUND(SUMIFS(Expenses!$I$6:$I$505,Expenses!$O$6:$O$505,$C$6,Expenses!$E$6:$E$505,$B22),2)) -> 65 | F22: =IF($E$30=0,0,E22/$E$30) -> 0.10503353
B23: =IF(Settings!$F$16="","",Settings!$F$16) -> Cleaning & Repairs / Limpieza y Reparaciones | C23: =IF($B23="",0,COUNTIFS(Expenses!$O$6:$O$505,$C$6,Expenses!$E$6:$E$505,$B23)) -> 1 | D23: =IF($B23="",0,ROUND(SUMIFS(Expenses!$G$6:$G$505,Expenses!$O$6:$O$505,$C$6,Expenses!$E$6:$E$505,$B23),2)) -> 34.97 | E23: =IF($B23="",0,ROUND(SUMIFS(Expenses!$I$6:$I$505,Expenses!$O$6:$O$505,$C$6,Expenses!$E$6:$E$505,$B23),2)) -> 34.97 | F23: =IF($E$30=0,0,E23/$E$30) -> 0.056508039
B24: =IF(Settings!$F$17="","",Settings!$F$17) -> Software & Apps / Software y Aplicaciones | C24: =IF($B24="",0,COUNTIFS(Expenses!$O$6:$O$505,$C$6,Expenses!$E$6:$E$505,$B24)) -> 2 | D24: =IF($B24="",0,ROUND(SUMIFS(Expenses!$G$6:$G$505,Expenses!$O$6:$O$505,$C$6,Expenses!$E$6:$E$505,$B24),2)) -> 43.99 | E24: =IF($B24="",0,ROUND(SUMIFS(Expenses!$I$6:$I$505,Expenses!$O$6:$O$505,$C$6,Expenses!$E$6:$E$505,$B24),2)) -> 43.99 | F24: =IF($E$30=0,0,E24/$E$30) -> 0.071083461
B25: =IF(Settings!$F$18="","",Settings!$F$18) -> Education & Courses / Educación y Cursos | C25: =IF($B25="",0,COUNTIFS(Expenses!$O$6:$O$505,$C$6,Expenses!$E$6:$E$505,$B25)) -> 1 | D25: =IF($B25="",0,ROUND(SUMIFS(Expenses!$G$6:$G$505,Expenses!$O$6:$O$505,$C$6,Expenses!$E$6:$E$505,$B25),2)) -> 19.99 | E25: =IF($B25="",0,ROUND(SUMIFS(Expenses!$I$6:$I$505,Expenses!$O$6:$O$505,$C$6,Expenses!$E$6:$E$505,$B25),2)) -> 19.99 | F25: =IF($E$30=0,0,E25/$E$30) -> 0.03230185
B26: =IF(Settings!$F$19="","",Settings!$F$19) -> Other / Otro | C26: =IF($B26="",0,COUNTIFS(Expenses!$O$6:$O$505,$C$6,Expenses!$E$6:$E$505,$B26)) -> 0 | D26: =IF($B26="",0,ROUND(SUMIFS(Expenses!$G$6:$G$505,Expenses!$O$6:$O$505,$C$6,Expenses!$E$6:$E$505,$B26),2)) -> 0 | E26: =IF($B26="",0,ROUND(SUMIFS(Expenses!$I$6:$I$505,Expenses!$O$6:$O$505,$C$6,Expenses!$E$6:$E$505,$B26),2)) -> 0 | F26: =IF($E$30=0,0,E26/$E$30) -> 0
B27: =IF(Settings!$F$20="","",Settings!$F$20) | C27: =IF($B27="",0,COUNTIFS(Expenses!$O$6:$O$505,$C$6,Expenses!$E$6:$E$505,$B27)) -> 0 | D27: =IF($B27="",0,ROUND(SUMIFS(Expenses!$G$6:$G$505,Expenses!$O$6:$O$505,$C$6,Expenses!$E$6:$E$505,$B27),2)) -> 0 | E27: =IF($B27="",0,ROUND(SUMIFS(Expenses!$I$6:$I$505,Expenses!$O$6:$O$505,$C$6,Expenses!$E$6:$E$505,$B27),2)) -> 0 | F27: =IF($E$30=0,0,E27/$E$30) -> 0
B28: =IF(Settings!$F$21="","",Settings!$F$21) | C28: =IF($B28="",0,COUNTIFS(Expenses!$O$6:$O$505,$C$6,Expenses!$E$6:$E$505,$B28)) -> 0 | D28: =IF($B28="",0,ROUND(SUMIFS(Expenses!$G$6:$G$505,Expenses!$O$6:$O$505,$C$6,Expenses!$E$6:$E$505,$B28),2)) -> 0 | E28: =IF($B28="",0,ROUND(SUMIFS(Expenses!$I$6:$I$505,Expenses!$O$6:$O$505,$C$6,Expenses!$E$6:$E$505,$B28),2)) -> 0 | F28: =IF($E$30=0,0,E28/$E$30) -> 0
B29: Uncategorized / Sin categoría | C29: =C30-SUM(C15:C28) -> 0 | D29: =ROUND(D30-SUM(D15:D28),2) -> 0 | E29: =ROUND(E30-SUM(E15:E28),2) -> 0 | F29: =IF($E$30=0,0,E29/$E$30) -> 0
B30: TOTAL | C30: =COUNTIF(Expenses!$O$6:$O$505,$C$6) -> 18 | D30: =ROUND(SUMIFS(Expenses!$G$6:$G$505,Expenses!$O$6:$O$505,$C$6),2) -> 707.85 | E30: =ROUND(SUMIFS(Expenses!$I$6:$I$505,Expenses!$O$6:$O$505,$C$6),2) -> 618.85 | F30: =IF(E30=0,0,1) -> 1
B31: Categories come from the Settings sheet. / Las categorías vienen de la hoja Configuración.
B33: Monthly Deductions / Deducciones Mensuales
B34: Month Mes | C34: Expenses Gastos | D34: Miles Millas | E34: Mileage $ Millaje $ | F34: Total Total
B35: Jan / Ene | C35: =ROUND(SUMIFS(Expenses!$I$6:$I$505,Expenses!$P$6:$P$505,$C$6*100+1),2) -> 91.34 | D35: =SUMIFS(Mileage!$J$6:$J$505,Mileage!$R$6:$R$505,$C$6*100+1) -> 38.4 | E35: =ROUND(SUMIFS(Mileage!$L$6:$L$505,Mileage!$R$6:$R$505,$C$6*100+1),2) -> 27.84 | F35: =C35+E35 -> 119.18
B36: Feb / Feb | C36: =ROUND(SUMIFS(Expenses!$I$6:$I$505,Expenses!$P$6:$P$505,$C$6*100+2),2) -> 69.99 | D36: =SUMIFS(Mileage!$J$6:$J$505,Mileage!$R$6:$R$505,$C$6*100+2) -> 33 | E36: =ROUND(SUMIFS(Mileage!$L$6:$L$505,Mileage!$R$6:$R$505,$C$6*100+2),2) -> 23.93 | F36: =C36+E36 -> 93.92
B37: Mar / Mar | C37: =ROUND(SUMIFS(Expenses!$I$6:$I$505,Expenses!$P$6:$P$505,$C$6*100+3),2) -> 57.75 | D37: =SUMIFS(Mileage!$J$6:$J$505,Mileage!$R$6:$R$505,$C$6*100+3) -> 39 | E37: =ROUND(SUMIFS(Mileage!$L$6:$L$505,Mileage!$R$6:$R$505,$C$6*100+3),2) -> 28.28 | F37: =C37+E37 -> 86.03
B38: Apr / Abr | C38: =ROUND(SUMIFS(Expenses!$I$6:$I$505,Expenses!$P$6:$P$505,$C$6*100+4),2) -> 177.48 | D38: =SUMIFS(Mileage!$J$6:$J$505,Mileage!$R$6:$R$505,$C$6*100+4) -> 30.7 | E38: =ROUND(SUMIFS(Mileage!$L$6:$L$505,Mileage!$R$6:$R$505,$C$6*100+4),2) -> 22.26 | F38: =C38+E38 -> 199.74
B39: May / May | C39: =ROUND(SUMIFS(Expenses!$I$6:$I$505,Expenses!$P$6:$P$505,$C$6*100+5),2) -> 40.25 | D39: =SUMIFS(Mileage!$J$6:$J$505,Mileage!$R$6:$R$505,$C$6*100+5) -> 5 | E39: =ROUND(SUMIFS(Mileage!$L$6:$L$505,Mileage!$R$6:$R$505,$C$6*100+5),2) -> 3.63 | F39: =C39+E39 -> 43.88
B40: Jun / Jun | C40: =ROUND(SUMIFS(Expenses!$I$6:$I$505,Expenses!$P$6:$P$505,$C$6*100+6),2) -> 19.99 | D40: =SUMIFS(Mileage!$J$6:$J$505,Mileage!$R$6:$R$505,$C$6*100+6) -> 53 | E40: =ROUND(SUMIFS(Mileage!$L$6:$L$505,Mileage!$R$6:$R$505,$C$6*100+6),2) -> 38.43 | F40: =C40+E40 -> 58.42
B41: Jul / Jul | C41: =ROUND(SUMIFS(Expenses!$I$6:$I$505,Expenses!$P$6:$P$505,$C$6*100+7),2) -> 55.97 | D41: =SUMIFS(Mileage!$J$6:$J$505,Mileage!$R$6:$R$505,$C$6*100+7) -> 50.4 | E41: =ROUND(SUMIFS(Mileage!$L$6:$L$505,Mileage!$R$6:$R$505,$C$6*100+7),2) -> 38.3 | F41: =C41+E41 -> 94.27
B42: Aug / Ago | C42: =ROUND(SUMIFS(Expenses!$I$6:$I$505,Expenses!$P$6:$P$505,$C$6*100+8),2) -> 68.6 | D42: =SUMIFS(Mileage!$J$6:$J$505,Mileage!$R$6:$R$505,$C$6*100+8) -> 41.8 | E42: =ROUND(SUMIFS(Mileage!$L$6:$L$505,Mileage!$R$6:$R$505,$C$6*100+8),2) -> 31.77 | F42: =C42+E42 -> 100.37
B43: Sep / Sep | C43: =ROUND(SUMIFS(Expenses!$I$6:$I$505,Expenses!$P$6:$P$505,$C$6*100+9),2) -> 37.48 | D43: =SUMIFS(Mileage!$J$6:$J$505,Mileage!$R$6:$R$505,$C$6*100+9) -> 50 | E43: =ROUND(SUMIFS(Mileage!$L$6:$L$505,Mileage!$R$6:$R$505,$C$6*100+9),2) -> 38 | F43: =C43+E43 -> 75.48
B44: Oct / Oct | C44: =ROUND(SUMIFS(Expenses!$I$6:$I$505,Expenses!$P$6:$P$505,$C$6*100+10),2) -> 0 | D44: =SUMIFS(Mileage!$J$6:$J$505,Mileage!$R$6:$R$505,$C$6*100+10) -> 0 | E44: =ROUND(SUMIFS(Mileage!$L$6:$L$505,Mileage!$R$6:$R$505,$C$6*100+10),2) -> 0 | F44: =C44+E44 -> 0
B45: Nov / Nov | C45: =ROUND(SUMIFS(Expenses!$I$6:$I$505,Expenses!$P$6:$P$505,$C$6*100+11),2) -> 0 | D45: =SUMIFS(Mileage!$J$6:$J$505,Mileage!$R$6:$R$505,$C$6*100+11) -> 0 | E45: =ROUND(SUMIFS(Mileage!$L$6:$L$505,Mileage!$R$6:$R$505,$C$6*100+11),2) -> 0 | F45: =C45+E45 -> 0
...

Sheet Expenses
B1: ProfitTrack
B2: Expenses / Gastos
B3: Type in the light-teal columns only. Grey columns calculate automatically. • Escribe solo en las columnas verde claro. Las columnas grises se calculan solas.
B5: Date Fecha | C5: Vendor / Store Proveedor / Tienda | D5: Description Descripción | E5: Category Categoría | F5: Payment Method Método de Pago | G5: Amount Monto | H5: Business Use % % Uso del Negocio | I5: Deductible $ Deducible $ | J5: Receipt Saved? ¿Recibo Guardado? | K5: Notes Notas | L5: Check Revisar | N5: Helper – do not edit: valid (1/0) | O5: Helper – do not edit: year | P5: Helper – do not edit: year-month | Q5: Helper – do not edit: no receipt (1/0)
B6: 46027 | C6: Uline | D6: Poly mailers 100-pack | E6: Shipping Supplies / Materiales de Envío | F6: Card / Tarjeta | G6: 24.99 | I6: =IF(G6="","",G6*IF(H6="",1,H6)) -> 24.99 | J6: Yes / Sí | L6: =IF(G6="","",IF(ISNUMBER(B6),IF(E6="","⚠ ADD CATEGORY / AGREGA CATEGORÍA",IF(J6="No","⚠ SAVE RECEIPT / GUARDA RECIBO","✔ OK")),"⚠ ADD DATE / AGREGA FECHA")) -> ✔ OK | N6: =IF(G6="",0,IF(ISNUMBER(B6),1,0)) -> 1 | O6: =IF(N6=1,YEAR(B6),0) -> 2026 | P6: =IF(N6=1,YEAR(B6)*100+MONTH(B6),0) -> 202601 | Q6: =IF(N6=1,IF(J6="No",1,0),0) -> 0
B7: 46034 | C7: eBay | D7: Store subscription – January | E7: Platform & Subscription Fees / Tarifas y Suscripciones | F7: Card / Tarjeta | G7: 27.95 | I7: =IF(G7="","",G7*IF(H7="",1,H7)) -> 27.95 | J7: Yes / Sí | K7: Basic store | L7: =IF(G7="","",IF(ISNUMBER(B7),IF(E7="","⚠ ADD CATEGORY / AGREGA CATEGORÍA",IF(J7="No","⚠ SAVE RECEIPT / GUARDA RECIBO","✔ OK")),"⚠ ADD DATE / AGREGA FECHA")) -> ✔ OK | N7: =IF(G7="",0,IF(ISNUMBER(B7),1,0)) -> 1 | O7: =IF(N7=1,YEAR(B7),0) -> 2026 | P7: =IF(N7=1,YEAR(B7)*100+MONTH(B7),0) -> 202601 | Q7: =IF(N7=1,IF(J7="No",1,0),0) -> 0
B8: 46042 | C8: Staples | D8: Printer ink + labels | E8: Office Supplies / Artículos de Oficina | F8: Card / Tarjeta | G8: 38.4 | I8: =IF(G8="","",G8*IF(H8="",1,H8)) -> 38.4 | J8: Yes / Sí | L8: =IF(G8="","",IF(ISNUMBER(B8),IF(E8="","⚠ ADD CATEGORY / AGREGA CATEGORÍA",IF(J8="No","⚠ SAVE RECEIPT / GUARDA RECIBO","✔ OK")),"⚠ ADD DATE / AGREGA FECHA")) -> ✔ OK | N8: =IF(G8="",0,IF(ISNUMBER(B8),1,0)) -> 1 | O8: =IF(N8=1,YEAR(B8),0) -> 2026 | P8: =IF(N8=1,YEAR(B8)*100+MONTH(B8),0) -> 202601 | Q8: =IF(N8=1,IF(J8="No",1,0),0) -> 0
B9: 46055 | C9: Verizon | D9: Phone bill – February | E9: Phone & Internet / Teléfono e Internet | F9: Card / Tarjeta | G9: 80 | H9: 0.5 | I9: =IF(G9="","",G9*IF(H9="",1,H9)) -> 40 | J9: Yes / Sí | K9: 50% business | L9: =IF(G9="","",IF(ISNUMBER(B9),IF(E9="","⚠ ADD CATEGORY / AGREGA CATEGORÍA",IF(J9="No","⚠ SAVE RECEIPT / GUARDA RECIBO","✔ OK")),"⚠ ADD DATE / AGREGA FECHA")) -> ✔ OK | N9: =IF(G9="",0,IF(ISNUMBER(B9),1,0)) -> 1 | O9: =IF(N9=1,YEAR(B9),0) -> 2026 | P9: =IF(N9=1,YEAR(B9)*100+MONTH(B9),0) -> 202602 | Q9: =IF(N9=1,IF(J9="No",1,0),0) -> 0
B10: 46067 | C10: Amazon | D10: Digital shipping scale | E10: Equipment & Tools / Equipo y Herramientas | F10: Card / Tarjeta | G10: 29.99 | I10: =IF(G10="","",G10*IF(H10="",1,H10)) -> 29.99 | J10: Yes / Sí | L10: =IF(G10="","",IF(ISNUMBER(B10),IF(E10="","⚠ ADD CATEGORY / AGREGA CATEGORÍA",IF(J10="No","⚠ SAVE RECEIPT / GUARDA RECIBO","✔ OK")),"⚠ ADD DATE / AGREGA FECHA")) -> ✔ OK | N10: =IF(G10="",0,IF(ISNUMBER(B10),1,0)) -> 1 | O10: =IF(N10=1,YEAR(B10),0) -> 2026 | P10: =IF(N10=1,YEAR(B10)*100+MONTH(B10),0) -> 202602 | Q10: =IF(N10=1,IF(J10="No",1,0),0) -> 0
B11: 46082 | C11: Poshmark | D11: Closet promotion | E11: Advertising & Promoted Listings / Publicidad | F11: PayPal | G11: 15 | I11: =IF(G11="","",G11*IF(H11="",1,H11)) -> 15 | J11: No | L11: =IF(G11="","",IF(ISNUMBER(B11),IF(E11="","⚠ ADD CATEGORY / AGREGA CATEGORÍA",IF(J11="No","⚠ SAVE RECEIPT / GUARDA RECIBO","✔ OK")),"⚠ ADD DATE / AGREGA FECHA")) -> ⚠ SAVE RECEIPT / GUARDA RECIBO | N11: =IF(G11="",0,IF(ISNUMBER(B11),1,0)) -> 1 | O11: =IF(N11=1,YEAR(B11),0) -> 2026 | P11: =IF(N11=1,YEAR(B11)*100+MONTH(B11),0) -> 202603 | Q11: =IF(N11=1,IF(J11="No",1,0),0) -> 1
B12: 46099 | C12: USPS | D12: Postage – unreimbursed labels | E12: Postage & Shipping Labels / Envíos y Etiquetas | F12: Cash / Efectivo | G12: 42.75 | I12: =IF(G12="","",G12*IF(H12="",1,H12)) -> 42.75 | J12: Yes / Sí | L12: =IF(G12="","",IF(ISNUMBER(B12),IF(E12="","⚠ ADD CATEGORY / AGREGA CATEGORÍA",IF(J12="No","⚠ SAVE RECEIPT / GUARDA RECIBO","✔ OK")),"⚠ ADD DATE / AGREGA FECHA")) -> ✔ OK | N12: =IF(G12="",0,IF(ISNUMBER(B12),1,0)) -> 1 | O12: =IF(N12=1,YEAR(B12),0) -> 2026 | P12: =IF(N12=1,YEAR(B12)*100+MONTH(B12),0) -> 202603 | Q12: =IF(N12=1,IF(J12="No",1,0),0) -> 0
B13: 46115 | C13: U-Haul | D13: Storage unit – April | E13: Storage & Rent / Almacenaje y Renta | F13: Bank / Banco | G13: 65 | I13: =IF(G13="","",G13*IF(H13="",1,H13)) -> 65 | J13: Yes / Sí | L13: =IF(G13="","",IF(ISNUMBER(B13),IF(E13="","⚠ ADD CATEGORY / AGREGA CATEGORÍA",IF(J13="No","⚠ SAVE RECEIPT / GUARDA RECIBO","✔ OK")),"⚠ ADD DATE / AGREGA FECHA")) -> ✔ OK | N13: =IF(G13="",0,IF(ISNUMBER(B13),1,0)) -> 1 | O13: =IF(N13=1,YEAR(B13),0) -> 2026 | P13: =IF(N13=1,YEAR(B13)*100+MONTH(B13),0) -> 202604 | Q13: =IF(N13=1,IF(J13="No",1,0),0) -> 0
B14: 46134 | C14: Home Depot | D14: Shelving + bins | E14: Equipment & Tools / Equipo y Herramientas | F14: Card / Tarjeta | G14: 112.48 | I14: =IF(G14="","",G14*IF(H14="",1,H14)) -> 112.48 | J14: Yes / Sí | K14: Inventory shelves | L14: =IF(G14="","",IF(ISNUMBER(B14),IF(E14="","⚠ ADD CATEGORY / AGREGA CATEGORÍA",IF(J14="No","⚠ SAVE RECEIPT / GUARDA RECIBO","✔ OK")),"⚠ ADD DATE / AGREGA FECHA")) -> ✔ OK | N14: =IF(G14="",0,IF(ISNUMBER(B14),1,0)) -> 1 | O14: =IF(N14=1,YEAR(B14),0) -> 2026 | P14: =IF(N14=1,YEAR(B14)*100+MONTH(B14),0) -> 202604 | Q14: =IF(N14=1,IF(J14="No",1,0),0) -> 0
B15: 46151 | C15: Vendoo | D15: Crosslisting app – monthly | E15: Software & Apps / Software y Aplicaciones | F15: Card / Tarjeta | G15: 29 | I15: =IF(G15="","",G15*IF(H15="",1,H15)) -> 29 | J15: Yes / Sí | L15: =IF(G15="","",IF(ISNUMBER(B15),IF(E15="","⚠ ADD CATEGORY / AGREGA CATEGORÍA",IF(J15="No","⚠ SAVE RECEIPT / GUARDA RECIBO","✔ OK")),"⚠ ADD DATE / AGREGA FECHA")) -> ✔ OK | N15: =IF(G15="",0,IF(ISNUMBER(B15),1,0)) -> 1 | O15: =IF(N15=1,YEAR(B15),0) -> 2026 | P15: =IF(N15=1,YEAR(B15)*100+MONTH(B15),0) -> 202605 | Q15: =IF(N15=1,IF(J15="No",1,0),0) -> 0
B16: 46169 | C16: Dollar Tree | D16: Tissue paper & tape | E16: Shipping Supplies / Materiales de Envío | F16: Cash / Efectivo | G16: 11.25 | I16: =IF(G16="","",G16*IF(H16="",1,H16)) -> 11.25 | J16: No | L16: =IF(G16="","",IF(ISNUMBER(B16),IF(E16="","⚠ ADD CATEGORY / AGREGA CATEGORÍA",IF(J16="No","⚠ SAVE RECEIPT / GUARDA RECIBO","✔ OK")),"⚠ ADD DATE / AGREGA FECHA")) -> ⚠ SAVE RECEIPT / GUARDA RECIBO | N16: =IF(G16="",0,IF(ISNUMBER(B16),1,0)) -> 1 | O16: =IF(N16=1,YEAR(B16),0) -> 2026 | P16: =IF(N16=1,YEAR(B16)*100+MONTH(B16),0) -> 202605 | Q16: =IF(N16=1,IF(J16="No",1,0),0) -> 1
B17: 46188 | C17: Udemy | D17: Reselling course | E17: Education & Courses / Educación y Cursos | F17: Card / Tarjeta | G17: 19.99 | I17: =IF(G17="","",G17*IF(H17="",1,H17)) -> 19.99 | J17: Yes / Sí | L17: =IF(G17="","",IF(ISNUMBER(B17),IF(E17="","⚠ ADD CATEGORY / AGREGA CATEGORÍA",IF(J17="No","⚠ SAVE RECEIPT / GUARDA RECIBO","✔ OK")),"⚠ ADD DATE / AGREGA FECHA")) -> ✔ OK | N17: =IF(G17="",0,IF(ISNUMBER(B17),1,0)) -> 1 | O17: =IF(N17=1,YEAR(B17),0) -> 2026 | P17: =IF(N17=1,YEAR(B17)*100+MONTH(B17),0) -> 202606 | Q17: =IF(N17=1,IF(J17="No",1,0),0) -> 0
B18: 46211 | C18: Walmart | D18: Steamer for clothes | E18: Cleaning & Repairs / Limpieza y Reparaciones | F18: Card / Tarjeta | G18: 34.97 | I18: =IF(G18="","",G18*IF(H18="",1,H18)) -> 34.97 | J18: Yes / Sí | L18: =IF(G18="","",IF(ISNUMBER(B18),IF(E18="","⚠ ADD CATEGORY / AGREGA CATEGORÍA",IF(J18="No","⚠ SAVE RECEIPT / GUARDA RECIBO","✔ OK")),"⚠ ADD DATE / AGREGA FECHA")) -> ✔ OK | N18: =IF(G18="",0,IF(ISNUMBER(B18),1,0)) -> 1 | O18: =IF(N18=1,YEAR(B18),0) -> 2026 | P18: =IF(N18=1,YEAR(B18)*100+MONTH(B18),0) -> 202607 | Q18: =IF(N18=1,IF(J18="No",1,0),0) -> 0
B19: 46233 | C19: Comcast | D19: Internet – July | E19: Phone & Internet / Teléfono e Internet | F19: Card / Tarjeta | G19: 70 | H19: 0.3 | I19: =IF(G19="","",G19*IF(H19="",1,H19)) -> 21 | J19: Yes / Sí | K19: 30% business | L19: =IF(G19="","",IF(ISNUMBER(B19),IF(E19="","⚠ ADD CATEGORY / AGREGA CATEGORÍA",IF(J19="No","⚠ SAVE RECEIPT / GUARDA RECIBO","✔ OK")),"⚠ ADD DATE / AGREGA FECHA")) -> ✔ OK | N19: =IF(G19="",0,IF(ISNUMBER(B19),1,0)) -> 1 | O19: =IF(N19=1,YEAR(B19),0) -> 2026 | P19: =IF(N19=1,YEAR(B19)*100+MONTH(B19),0) -> 202607 | Q19: =IF(N19=1,IF(J19="No",1,0),0) -> 0
B20: 46246 | C20: Uline | D20: Boxes – assorted | E20: Shipping Supplies / Materiales de Envío | F20: Card / Tarjeta | G20: 58.6 | I20: =IF(G20="","",G20*IF(H20="",1,H20)) -> 58.6 | J20: Yes / Sí | L20: =IF(G20="","",IF(ISNUMBER(B20),IF(E20="","⚠ ADD CATEGORY / AGREGA CATEGORÍA",IF(J20="No","⚠ SAVE RECEIPT / GUARDA RECIBO","✔ OK")),"⚠ ADD DATE / AGREGA FECHA")) -> ✔ OK | N20: =IF(G20="",0,IF(ISNUMBER(B20),1,0)) -> 1 | O20: =IF(N20=1,YEAR(B20),0) -> 2026 | P20: =IF(N20=1,YEAR(B20)*100+MONTH(B20),0) -> 202608 | Q20: =IF(N20=1,IF(J20="No",1,0),0) -> 0
B21: 46259 | C21: Facebook | D21: Boosted Marketplace post | E21: Advertising & Promoted Listings / Publicidad | F21: Card / Tarjeta | G21: 10 | I21: =IF(G21="","",G21*IF(H21="",1,H21)) -> 10 | J21: Yes / Sí | L21: =IF(G21="","",IF(ISNUMBER(B21),IF(E21="","⚠ ADD CATEGORY / AGREGA CATEGORÍA",IF(J21="No","⚠ SAVE RECEIPT / GUARDA RECIBO","✔ OK")),"⚠ ADD DATE / AGREGA FECHA")) -> ✔ OK | N21: =IF(G21="",0,IF(ISNUMBER(B21),1,0)) -> 1 | O21: =IF(N21=1,YEAR(B21),0) -> 2026 | P21: =IF(N21=1,YEAR(B21)*100+MONTH(B21),0) -> 202608 | Q21: =IF(N21=1,IF(J21="No",1,0),0) -> 0
B22: 46275 | C22: Canva | D22: Canva Pro – photo editing | E22: Software & Apps / Software y Aplicaciones | F22: Card / Tarjeta | G22: 14.99 | I22: =IF(G22="","",G22*IF(H22="",1,H22)) -> 14.99 | J22: Yes / Sí | L22: =IF(G22="","",IF(ISNUMBER(B22),IF(E22="","⚠ ADD CATEGORY / AGREGA CATEGORÍA",IF(J22="No","⚠ SAVE RECEIPT / GUARDA RECIBO","✔ OK")),"⚠ ADD DATE / AGREGA FECHA")) -> ✔ OK | N22: =IF(G22="",0,IF(ISNUMBER(B22),1,0)) -> 1 | O22: =IF(N22=1,YEAR(B22),0) -> 2026 | P22: =IF(N22=1,YEAR(B22)*100+MONTH(B22),0) -> 202609 | Q22: =IF(N22=1,IF(J22="No",1,0),0) -> 0
B23: 46289 | C23: Office Depot | D23: Label printer paper | E23: Office Supplies / Artículos de Oficina | F23: Card / Tarjeta | G23: 22.49 | I23: =IF(G23="","",G23*IF(H23="",1,H23)) -> 22.49 | L23: =IF(G23="","",IF(ISNUMBER(B23),IF(E23="","⚠ ADD CATEGORY / AGREGA CATEGORÍA",IF(J23="No","⚠ SAVE RECEIPT / GUARDA RECIBO","✔ OK")),"⚠ ADD DATE / AGREGA FECHA")) -> ✔ OK | N23: =IF(G23="",0,IF(ISNUMBER(B23),1,0)) -> 1 | O23: =IF(N23=1,YEAR(B23),0) -> 2026 | P23: =IF(N23=1,YEAR(B23)*100+MONTH(B23),0) -> 202609 | Q23: =IF(N23=1,IF(J23="No",1,0),0) -> 0
I24: =IF(G24="","",G24*IF(H24="",1,H24)) | L24: =IF(G24="","",IF(ISNUMBER(B24),IF(E24="","⚠ ADD CATEGORY / AGREGA CATEGORÍA",IF(J24="No","⚠ SAVE RECEIPT / GUARDA RECIBO","✔ OK")),"⚠ ADD DATE / AGREGA FECHA")) | N24: =IF(G24="",0,IF(ISNUMBER(B24),1,0)) -> 0 | O24: =IF(N24=1,YEAR(B24),0) -> 0 | P24: =IF(N24=1,YEAR(B24)*100+MONTH(B24),0) -> 0 | Q24: =IF(N24=1,IF(J24="No",1,0),0) -> 0
I25: =IF(G25="","",G25*IF(H25="",1,H25)) | L25: =IF(G25="","",IF(ISNUMBER(B25),IF(E25="","⚠ ADD CATEGORY / AGREGA CATEGORÍA",IF(J25="No","⚠ SAVE RECEIPT / GUARDA RECIBO","✔ OK")),"⚠ ADD DATE / AGREGA FECHA")) | N25: =IF(G25="",0,IF(ISNUMBER(B25),1,0)) -> 0 | O25: =IF(N25=1,YEAR(B25),0) -> 0 | P25: =IF(N25=1,YEAR(B25)*100+MONTH(B25),0) -> 0 | Q25: =IF(N25=1,IF(J25="No",1,0),0) -> 0
I26: =IF(G26="","",G26*IF(H26="",1,H26)) | L26: =IF(G26="","",IF(ISNUMBER(B26),IF(E26="","⚠ ADD CATEGORY / AGREGA CATEGORÍA",IF(J26="No","⚠ SAVE RECEIPT / GUARDA RECIBO","✔ OK")),"⚠ ADD DATE / AGREGA FECHA")) | N26: =IF(G26="",0,IF(ISNUMBER(B26),1,0)) -> 0 | O26: =IF(N26=1,YEAR(B26),0) -> 0 | P26: =IF(N26=1,YEAR(B26)*100+MONTH(B26),0) -> 0 | Q26: =IF(N26=1,IF(J26="No",1,0),0) -> 0
I27: =IF(G27="","",G27*IF(H27="",1,H27)) | L27: =IF(G27="","",IF(ISNUMBER(B27),IF(E27="","⚠ ADD CATEGORY / AGREGA CATEGORÍA",IF(J27="No","⚠ SAVE RECEIPT / GUARDA RECIBO","✔ OK")),"⚠ ADD DATE / AGREGA FECHA")) | N27: =IF(G27="",0,IF(ISNUMBER(B27),1,0)) -> 0 | O27: =IF(N27=1,YEAR(B27),0) -> 0 | P27: =IF(N27=1,YEAR(B27)*100+MONTH(B27),0) -> 0 | Q27: =IF(N27=1,IF(J27="No",1,0),0) -> 0
I28: =IF(G28="","",G28*IF(H28="",1,H28)) | L28: =IF(G28="","",IF(ISNUMBER(B28),IF(E28="","⚠ ADD CATEGORY / AGREGA CATEGORÍA",IF(J28="No","⚠ SAVE RECEIPT / GUARDA RECIBO","✔ OK")),"⚠ ADD DATE / AGREGA FECHA")) | N28: =IF(G28="",0,IF(ISNUMBER(B28),1,0)) -> 0 | O28: =IF(N28=1,YEAR(B28),0) -> 0 | P28: =IF(N28=1,YEAR(B28)*100+MONTH(B28),0) -> 0 | Q28: =IF(N28=1,IF(J28="No",1,0),0) -> 0
I29: =IF(G29="","",G29*IF(H29="",1,H29)) | L29: =IF(G29="","",IF(ISNUMBER(B29),IF(E29="","⚠ ADD CATEGORY / AGREGA CATEGORÍA",IF(J29="No","⚠ SAVE RECEIPT / GUARDA RECIBO","✔ OK")),"⚠ ADD DATE / AGREGA FECHA")) | N29: =IF(G29="",0,IF(ISNUMBER(B29),1,0)) -> 0 | O29: =IF(N29=1,YEAR(B29),0) -> 0 | P29: =IF(N29=1,YEAR(B29)*100+MONTH(B29),0) -> 0 | Q29: =IF(N29=1,IF(J29="No",1,0),0) -> 0
I30: =IF(G30="","",G30*IF(H30="",1,H30)) | L30: =IF(G30="","",IF(ISNUMBER(B30),IF(E30="","⚠ ADD CATEGORY / AGREGA CATEGORÍA",IF(J30="No","⚠ SAVE RECEIPT / GUARDA RECIBO","✔ OK")),"⚠ ADD DATE / AGREGA FECHA")) | N30: =IF(G30="",0,IF(ISNUMBER(B30),1,0)) -> 0 | O30: =IF(N30=1,YEAR(B30),0) -> 0 | P30: =IF(N30=1,YEAR(B30)*100+MONTH(B30),0) -> 0 | Q30: =IF(N30=1,IF(J30="No",1,0),0) -> 0
I31: =IF(G31="","",G31*IF(H31="",1,H31)) | L31: =IF(G31="","",IF(ISNUMBER(B31),IF(E31="","⚠ ADD CATEGORY / AGREGA CATEGORÍA",IF(J31="No","⚠ SAVE RECEIPT / GUARDA RECIBO","✔ OK")),"⚠ ADD DATE / AGREGA FECHA")) | N31: =IF(G31="",0,IF(ISNUMBER(B31),1,0)) -> 0 | O31: =IF(N31=1,YEAR(B31),0) -> 0 | P31: =IF(N31=1,YEAR(B31)*100+MONTH(B31),0) -> 0 | Q31: =IF(N31=1,IF(J31="No",1,0),0) -> 0
I32: =IF(G32="","",G32*IF(H32="",1,H32)) | L32: =IF(G32="","",IF(ISNUMBER(B32),IF(E32="","⚠ ADD CATEGORY / AGREGA CATEGORÍA",IF(J32="No","⚠ SAVE RECEIPT / GUARDA RECIBO","✔ OK")),"⚠ ADD DATE / AGREGA FECHA")) | N32: =IF(G32="",0,IF(ISNUMBER(B32),1,0)) -> 0 | O32: =IF(N32=1,YEAR(B32),0) -> 0 | P32: =IF(N32=1,YEAR(B32)*100+MONTH(B32),0) -> 0 | Q32: =IF(N32=1,IF(J32="No",1,0),0) -> 0
I33: =IF(G33="","",G33*IF(H33="",1,H33)) | L33: =IF(G33="","",IF(ISNUMBER(B33),IF(E33="","⚠ ADD CATEGORY / AGREGA CATEGORÍA",IF(J33="No","⚠ SAVE RECEIPT / GUARDA RECIBO","✔ OK")),"⚠ ADD DATE / AGREGA FECHA")) | N33: =IF(G33="",0,IF(ISNUMBER(B33),1,0)) -> 0 | O33: =IF(N33=1,YEAR(B33),0) -> 0 | P33: =IF(N33=1,YEAR(B33)*100+MONTH(B33),0) -> 0 | Q33: =IF(N33=1,IF(J33="No",1,0),0) -> 0
I34: =IF(G34="","",G34*IF(H34="",1,H34)) | L34: =IF(G34="","",IF(ISNUMBER(B34),IF(E34="","⚠ ADD CATEGORY / AGREGA CATEGORÍA",IF(J34="No","⚠ SAVE RECEIPT / GUARDA RECIBO","✔ OK")),"⚠ ADD DATE / AGREGA FECHA")) | N34: =IF(G34="",0,IF(ISNUMBER(B34),1,0)) -> 0 | O34: =IF(N34=1,YEAR(B34),0) -> 0 | P34: =IF(N34=1,YEAR(B34)*100+MONTH(B34),0) -> 0 | Q34: =IF(N34=1,IF(J34="No",1,0),0) -> 0
I35: =IF(G35="","",G35*IF(H35="",1,H35)) | L35: =IF(G35="","",IF(ISNUMBER(B35),IF(E35="","⚠ ADD CATEGORY / AGREGA CATEGORÍA",IF(J35="No","⚠ SAVE RECEIPT / GUARDA RECIBO","✔ OK")),"⚠ ADD DATE / AGREGA FECHA")) | N35: =IF(G35="",0,IF(ISNUMBER(B35),1,0)) -> 0 | O35: =IF(N35=1,YEAR(B35),0) -> 0 | P35: =IF(N35=1,YEAR(B35)*100+MONTH(B35),0) -> 0 | Q35: =IF(N35=1,IF(J35="No",1,0),0) -> 0
... I505: =IF(G505="","",G505*IF(H505="",1,H505)) | L505: =IF(G505="","",IF(ISNUMBER(B505),IF(E505="","⚠ ADD CATEGORY / AGREGA CATEGORÍA",IF(J505="No","⚠ SAVE RECEIPT / GUARDA RECIBO","✔ OK")),"⚠ ADD DATE / AGREGA FECHA")) | N505: =IF(G505="",0,IF(ISNUMBER(B505),1,0)) -> 0 | O505: =IF(N505=1,YEAR(B505),0) -> 0 | P505: =IF(N505=1,YEAR(B505)*100+MONTH(B505),0) -> 0 | Q505: =IF(N505=1,IF(J505="No",1,0),0) -> 0

Sheet Mileage
B1: ProfitTrack
B2: Mileage Log / Registro de Millaje
B3: Enter odometer readings OR the trip miles. The IRS rate for the trip date is applied automatically. • Escribe el odómetro O las millas del viaje. La tarifa del IRS de esa fecha se aplica sola.
B5: Date Fecha | C5: From Desde | D5: To Hasta | E5: Purpose Propósito | F5: Odometer Start Odómetro Inicial | G5: Odometer End Odómetro Final | H5: Miles (no odometer) Millas (sin odómetro) | I5: Round Trip? ¿Ida y Vuelta? | J5: Total Miles Millas Totales | K5: Rate $/mile Tarifa $/milla | L5: Deduction $ Deducción $ | M5: Check Revisar | N5: Notes Notas | P5: Helper – do not edit: valid (1/0) | Q5: Helper – do not edit: year | R5: Helper – do not edit: year-month
B6: 46032 | C6: Home | D6: Goodwill – Main St | E6: Sourcing / Compras | H6: 6.2 | I6: Yes / Sí | J6: =IF(AND(ISNUMBER(F6),ISNUMBER(G6)),MAX(0,G6-F6),IF(ISNUMBER(H6),H6*IF(I6="Yes / Sí",2,1),"")) -> 12.4 | K6: =IF(OR(J6="",NOT(ISNUMBER(B6))),"",IF(COUNTIF(Settings!$B$8:$B$17,"<="&B6)=0,Settings!$C$8,INDEX(Settings!$C$8:$C$17,COUNTIF(Settings!$B$8:$B$17,"<="&B6)))) -> 0.725 | L6: =IF(K6="","",ROUND(J6*K6,2)) -> 8.99 | M6: =IF(AND(B6="",F6="",G6="",H6=""),"",IF(NOT(ISNUMBER(B6)),"⚠ ADD DATE / AGREGA FECHA",IF(J6="","⚠ ADD MILES / AGREGA MILLAS",IF(AND(ISNUMBER(F6),ISNUMBER(G6)),IF(G6<F6,"⚠ CHECK ODOMETER / REVISA ODÓMETRO","✔ OK"),"✔ OK")))) -> ✔ OK | P6: =IF(ISNUMBER(L6),1,0) -> 1 | Q6: =IF(P6=1,YEAR(B6),0) -> 2026 | R6: =IF(P6=1,YEAR(B6)*100+MONTH(B6),0) -> 202601
B7: 46046 | C7: Home | D7: Estate sale – Oak Ave | E7: Sourcing / Compras | F7: 48210 | G7: 48236 | J7: =IF(AND(ISNUMBER(F7),ISNUMBER(G7)),MAX(0,G7-F7),IF(ISNUMBER(H7),H7*IF(I7="Yes / Sí",2,1),"")) -> 26 | K7: =IF(OR(J7="",NOT(ISNUMBER(B7))),"",IF(COUNTIF(Settings!$B$8:$B$17,"<="&B7)=0,Settings!$C$8,INDEX(Settings!$C$8:$C$17,COUNTIF(Settings!$B$8:$B$17,"<="&B7)))) -> 0.725 | L7: =IF(K7="","",ROUND(J7*K7,2)) -> 18.85 | M7: =IF(AND(B7="",F7="",G7="",H7=""),"",IF(NOT(ISNUMBER(B7)),"⚠ ADD DATE / AGREGA FECHA",IF(J7="","⚠ ADD MILES / AGREGA MILLAS",IF(AND(ISNUMBER(F7),ISNUMBER(G7)),IF(G7<F7,"⚠ CHECK ODOMETER / REVISA ODÓMETRO","✔ OK"),"✔ OK")))) -> ✔ OK | P7: =IF(ISNUMBER(L7),1,0) -> 1 | Q7: =IF(P7=1,YEAR(B7),0) -> 2026 | R7: =IF(P7=1,YEAR(B7)*100+MONTH(B7),0) -> 202601
B8: 46060 | C8: Home | D8: Post office | E8: Post Office / Correo | H8: 2.5 | I8: Yes / Sí | J8: =IF(AND(ISNUMBER(F8),ISNUMBER(G8)),MAX(0,G8-F8),IF(ISNUMBER(H8),H8*IF(I8="Yes / Sí",2,1),"")) -> 5 | K8: =IF(OR(J8="",NOT(ISNUMBER(B8))),"",IF(COUNTIF(Settings!$B$8:$B$17,"<="&B8)=0,Settings!$C$8,INDEX(Settings!$C$8:$C$17,COUNTIF(Settings!$B$8:$B$17,"<="&B8)))) -> 0.725 | L8: =IF(K8="","",ROUND(J8*K8,2)) -> 3.63 | M8: =IF(AND(B8="",F8="",G8="",H8=""),"",IF(NOT(ISNUMBER(B8)),"⚠ ADD DATE / AGREGA FECHA",IF(J8="","⚠ ADD MILES / AGREGA MILLAS",IF(AND(ISNUMBER(F8),ISNUMBER(G8)),IF(G8<F8,"⚠ CHECK ODOMETER / REVISA ODÓMETRO","✔ OK"),"✔ OK")))) -> ✔ OK | P8: =IF(ISNUMBER(L8),1,0) -> 1 | Q8: =IF(P8=1,YEAR(B8),0) -> 2026 | R8: =IF(P8=1,YEAR(B8)*100+MONTH(B8),0) -> 202602
B9: 46074 | C9: Home | D9: Flea market | E9: Sourcing / Compras | H9: 14 | I9: Yes / Sí | J9: =IF(AND(ISNUMBER(F9),ISNUMBER(G9)),MAX(0,G9-F9),IF(ISNUMBER(H9),H9*IF(I9="Yes / Sí",2,1),"")) -> 28 | K9: =IF(OR(J9="",NOT(ISNUMBER(B9))),"",IF(COUNTIF(Settings!$B$8:$B$17,"<="&B9)=0,Settings!$C$8,INDEX(Settings!$C$8:$C$17,COUNTIF(Settings!$B$8:$B$17,"<="&B9)))) -> 0.725 | L9: =IF(K9="","",ROUND(J9*K9,2)) -> 20.3 | M9: =IF(AND(B9="",F9="",G9="",H9=""),"",IF(NOT(ISNUMBER(B9)),"⚠ ADD DATE / AGREGA FECHA",IF(J9="","⚠ ADD MILES / AGREGA MILLAS",IF(AND(ISNUMBER(F9),ISNUMBER(G9)),IF(G9<F9,"⚠ CHECK ODOMETER / REVISA ODÓMETRO","✔ OK"),"✔ OK")))) -> ✔ OK | P9: =IF(ISNUMBER(L9),1,0) -> 1 | Q9: =IF(P9=1,YEAR(B9),0) -> 2026 | R9: =IF(P9=1,YEAR(B9)*100+MONTH(B9),0) -> 202602
B10: 46095 | C10: Home | D10: Salvation Army + Savers | E10: Sourcing / Compras | F10: 48702 | G10: 48741 | J10: =IF(AND(ISNUMBER(F10),ISNUMBER(G10)),MAX(0,G10-F10),IF(ISNUMBER(H10),H10*IF(I10="Yes / Sí",2,1),"")) -> 39 | K10: =IF(OR(J10="",NOT(ISNUMBER(B10))),"",IF(COUNTIF(Settings!$B$8:$B$17,"<="&B10)=0,Settings!$C$8,INDEX(Settings!$C$8:$C$17,COUNTIF(Settings!$B$8:$B$17,"<="&B10)))) -> 0.725 | L10: =IF(K10="","",ROUND(J10*K10,2)) -> 28.28 | M10: =IF(AND(B10="",F10="",G10="",H10=""),"",IF(NOT(ISNUMBER(B10)),"⚠ ADD DATE / AGREGA FECHA",IF(J10="","⚠ ADD MILES / AGREGA MILLAS",IF(AND(ISNUMBER(F10),ISNUMBER(G10)),IF(G10<F10,"⚠ CHECK ODOMETER / REVISA ODÓMETRO","✔ OK"),"✔ OK")))) -> ✔ OK | P10: =IF(ISNUMBER(L10),1,0) -> 1 | Q10: =IF(P10=1,YEAR(B10),0) -> 2026 | R10: =IF(P10=1,YEAR(B10)*100+MONTH(B10),0) -> 202603
B11: 46116 | C11: Home | D11: Staples | E11: Supplies / Materiales | H11: 4.1 | I11: Yes / Sí | J11: =IF(AND(ISNUMBER(F11),ISNUMBER(G11)),MAX(0,G11-F11),IF(ISNUMBER(H11),H11*IF(I11="Yes / Sí",2,1),"")) -> 8.2 | K11: =IF(OR(J11="",NOT(ISNUMBER(B11))),"",IF(COUNTIF(Settings!$B$8:$B$17,"<="&B11)=0,Settings!$C$8,INDEX(Settings!$C$8:$C$17,COUNTIF(Settings!$B$8:$B$17,"<="&B11)))) -> 0.725 | L11: =IF(K11="","",ROUND(J11*K11,2)) -> 5.95 | M11: =IF(AND(B11="",F11="",G11="",H11=""),"",IF(NOT(ISNUMBER(B11)),"⚠ ADD DATE / AGREGA FECHA",IF(J11="","⚠ ADD MILES / AGREGA MILLAS",IF(AND(ISNUMBER(F11),ISNUMBER(G11)),IF(G11<F11,"⚠ CHECK ODOMETER / REVISA ODÓMETRO","✔ OK"),"✔ OK")))) -> ✔ OK | P11: =IF(ISNUMBER(L11),1,0) -> 1 | Q11: =IF(P11=1,YEAR(B11),0) -> 2026 | R11: =IF(P11=1,YEAR(B11)*100+MONTH(B11),0) -> 202604
B12: 46137 | C12: Home | D12: Garage sales route | E12: Sourcing / Compras | H12: 22.5 | J12: =IF(AND(ISNUMBER(F12),ISNUMBER(G12)),MAX(0,G12-F12),IF(ISNUMBER(H12),H12*IF(I12="Yes / Sí",2,1),"")) -> 22.5 | K12: =IF(OR(J12="",NOT(ISNUMBER(B12))),"",IF(COUNTIF(Settings!$B$8:$B$17,"<="&B12)=0,Settings!$C$8,INDEX(Settings!$C$8:$C$17,COUNTIF(Settings!$B$8:$B$17,"<="&B12)))) -> 0.725 | L12: =IF(K12="","",ROUND(J12*K12,2)) -> 16.31 | M12: =IF(AND(B12="",F12="",G12="",H12=""),"",IF(NOT(ISNUMBER(B12)),"⚠ ADD DATE / AGREGA FECHA",IF(J12="","⚠ ADD MILES / AGREGA MILLAS",IF(AND(ISNUMBER(F12),ISNUMBER(G12)),IF(G12<F12,"⚠ CHECK ODOMETER / REVISA ODÓMETRO","✔ OK"),"✔ OK")))) -> ✔ OK | P12: =IF(ISNUMBER(L12),1,0) -> 1 | Q12: =IF(P12=1,YEAR(B12),0) -> 2026 | R12: =IF(P12=1,YEAR(B12)*100+MONTH(B12),0) -> 202604
B13: 46158 | C13: Home | D13: Post office | E13: Post Office / Correo | H13: 2.5 | I13: Yes / Sí | J13: =IF(AND(ISNUMBER(F13),ISNUMBER(G13)),MAX(0,G13-F13),IF(ISNUMBER(H13),H13*IF(I13="Yes / Sí",2,1),"")) -> 5 | K13: =IF(OR(J13="",NOT(ISNUMBER(B13))),"",IF(COUNTIF(Settings!$B$8:$B$17,"<="&B13)=0,Settings!$C$8,INDEX(Settings!$C$8:$C$17,COUNTIF(Settings!$B$8:$B$17,"<="&B13)))) -> 0.725 | L13: =IF(K13="","",ROUND(J13*K13,2)) -> 3.63 | M13: =IF(AND(B13="",F13="",G13="",H13=""),"",IF(NOT(ISNUMBER(B13)),"⚠ ADD DATE / AGREGA FECHA",IF(J13="","⚠ ADD MILES / AGREGA MILLAS",IF(AND(ISNUMBER(F13),ISNUMBER(G13)),IF(G13<F13,"⚠ CHECK ODOMETER / REVISA ODÓMETRO","✔ OK"),"✔ OK")))) -> ✔ OK | P13: =IF(ISNUMBER(L13),1,0) -> 1 | Q13: =IF(P13=1,YEAR(B13),0) -> 2026 | R13: =IF(P13=1,YEAR(B13)*100+MONTH(B13),0) -> 202605
B14: 46179 | C14: Home | D14: Bins outlet | E14: Sourcing / Compras | F14: 49655 | G14: 49702 | J14: =IF(AND(ISNUMBER(F14),ISNUMBER(G14)),MAX(0,G14-F14),IF(ISNUMBER(H14),H14*IF(I14="Yes / Sí",2,1),"")) -> 47 | K14: =IF(OR(J14="",NOT(ISNUMBER(B14))),"",IF(COUNTIF(Settings!$B$8:$B$17,"<="&B14)=0,Settings!$C$8,INDEX(Settings!$C$8:$C$17,COUNTIF(Settings!$B$8:$B$17,"<="&B14)))) -> 0.725 | L14: =IF(K14="","",ROUND(J14*K14,2)) -> 34.08 | M14: =IF(AND(B14="",F14="",G14="",H14=""),"",IF(NOT(ISNUMBER(B14)),"⚠ ADD DATE / AGREGA FECHA",IF(J14="","⚠ ADD MILES / AGREGA MILLAS",IF(AND(ISNUMBER(F14),ISNUMBER(G14)),IF(G14<F14,"⚠ CHECK ODOMETER / REVISA ODÓMETRO","✔ OK"),"✔ OK")))) -> ✔ OK | P14: =IF(ISNUMBER(L14),1,0) -> 1 | Q14: =IF(P14=1,YEAR(B14),0) -> 2026 | R14: =IF(P14=1,YEAR(B14)*100+MONTH(B14),0) -> 202606
B15: 46200 | C15: Home | D15: Bank deposit | E15: Bank / Banco | H15: 3 | I15: Yes / Sí | J15: =IF(AND(ISNUMBER(F15),ISNUMBER(G15)),MAX(0,G15-F15),IF(ISNUMBER(H15),H15*IF(I15="Yes / Sí",2,1),"")) -> 6 | K15: =IF(OR(J15="",NOT(ISNUMBER(B15))),"",IF(COUNTIF(Settings!$B$8:$B$17,"<="&B15)=0,Settings!$C$8,INDEX(Settings!$C$8:$C$17,COUNTIF(Settings!$B$8:$B$17,"<="&B15)))) -> 0.725 | L15: =IF(K15="","",ROUND(J15*K15,2)) -> 4.35 | M15: =IF(AND(B15="",F15="",G15="",H15=""),"",IF(NOT(ISNUMBER(B15)),"⚠ ADD DATE / AGREGA FECHA",IF(J15="","⚠ ADD MILES / AGREGA MILLAS",IF(AND(ISNUMBER(F15),ISNUMBER(G15)),IF(G15<F15,"⚠ CHECK ODOMETER / REVISA ODÓMETRO","✔ OK"),"✔ OK")))) -> ✔ OK | P15: =IF(ISNUMBER(L15),1,0) -> 1 | Q15: =IF(P15=1,YEAR(B15),0) -> 2026 | R15: =IF(P15=1,YEAR(B15)*100+MONTH(B15),0) -> 202606
B16: 46214 | C16: Home | D16: Goodwill – Main St | E16: Sourcing / Compras | H16: 6.2 | I16: Yes / Sí | J16: =IF(AND(ISNUMBER(F16),ISNUMBER(G16)),MAX(0,G16-F16),IF(ISNUMBER(H16),H16*IF(I16="Yes / Sí",2,1),"")) -> 12.4 | K16: =IF(OR(J16="",NOT(ISNUMBER(B16))),"",IF(COUNTIF(Settings!$B$8:$B$17,"<="&B16)=0,Settings!$C$8,INDEX(Settings!$C$8:$C$17,COUNTIF(Settings!$B$8:$B$17,"<="&B16)))) -> 0.76 | L16: =IF(K16="","",ROUND(J16*K16,2)) -> 9.42 | M16: =IF(AND(B16="",F16="",G16="",H16=""),"",IF(NOT(ISNUMBER(B16)),"⚠ ADD DATE / AGREGA FECHA",IF(J16="","⚠ ADD MILES / AGREGA MILLAS",IF(AND(ISNUMBER(F16),ISNUMBER(G16)),IF(G16<F16,"⚠ CHECK ODOMETER / REVISA ODÓMETRO","✔ OK"),"✔ OK")))) -> ✔ OK | P16: =IF(ISNUMBER(L16),1,0) -> 1 | Q16: =IF(P16=1,YEAR(B16),0) -> 2026 | R16: =IF(P16=1,YEAR(B16)*100+MONTH(B16),0) -> 202607
B17: 46228 | C17: Home | D17: Estate sale – Pine Rd | E17: Sourcing / Compras | F17: 50310 | G17: 50348 | J17: =IF(AND(ISNUMBER(F17),ISNUMBER(G17)),MAX(0,G17-F17),IF(ISNUMBER(H17),H17*IF(I17="Yes / Sí",2,1),"")) -> 38 | K17: =IF(OR(J17="",NOT(ISNUMBER(B17))),"",IF(COUNTIF(Settings!$B$8:$B$17,"<="&B17)=0,Settings!$C$8,INDEX(Settings!$C$8:$C$17,COUNTIF(Settings!$B$8:$B$17,"<="&B17)))) -> 0.76 | L17: =IF(K17="","",ROUND(J17*K17,2)) -> 28.88 | M17: =IF(AND(B17="",F17="",G17="",H17=""),"",IF(NOT(ISNUMBER(B17)),"⚠ ADD DATE / AGREGA FECHA",IF(J17="","⚠ ADD MILES / AGREGA MILLAS",IF(AND(ISNUMBER(F17),ISNUMBER(G17)),IF(G17<F17,"⚠ CHECK ODOMETER / REVISA ODÓMETRO","✔ OK"),"✔ OK")))) -> ✔ OK | P17: =IF(ISNUMBER(L17),1,0) -> 1 | Q17: =IF(P17=1,YEAR(B17),0) -> 2026 | R17: =IF(P17=1,YEAR(B17)*100+MONTH(B17),0) -> 202607
B18: 46242 | C18: Home | D18: Post office | E18: Post Office / Correo | H18: 2.5 | I18: Yes / Sí | J18: =IF(AND(ISNUMBER(F18),ISNUMBER(G18)),MAX(0,G18-F18),IF(ISNUMBER(H18),H18*IF(I18="Yes / Sí",2,1),"")) -> 5 | K18: =IF(OR(J18="",NOT(ISNUMBER(B18))),"",IF(COUNTIF(Settings!$B$8:$B$17,"<="&B18)=0,Settings!$C$8,INDEX(Settings!$C$8:$C$17,COUNTIF(Settings!$B$8:$B$17,"<="&B18)))) -> 0.76 | L18: =IF(K18="","",ROUND(J18*K18,2)) -> 3.8 | M18: =IF(AND(B18="",F18="",G18="",H18=""),"",IF(NOT(ISNUMBER(B18)),"⚠ ADD DATE / AGREGA FECHA",IF(J18="","⚠ ADD MILES / AGREGA MILLAS",IF(AND(ISNUMBER(F18),ISNUMBER(G18)),IF(G18<F18,"⚠ CHECK ODOMETER / REVISA ODÓMETRO","✔ OK"),"✔ OK")))) -> ✔ OK | P18: =IF(ISNUMBER(L18),1,0) -> 1 | Q18: =IF(P18=1,YEAR(B18),0) -> 2026 | R18: =IF(P18=1,YEAR(B18)*100+MONTH(B18),0) -> 202608
B19: 46263 | C19: Home | D19: Antique mall | E19: Sourcing / Compras | H19: 18.4 | I19: Yes / Sí | J19: =IF(AND(ISNUMBER(F19),ISNUMBER(G19)),MAX(0,G19-F19),IF(ISNUMBER(H19),H19*IF(I19="Yes / Sí",2,1),"")) -> 36.8 | K19: =IF(OR(J19="",NOT(ISNUMBER(B19))),"",IF(COUNTIF(Settings!$B$8:$B$17,"<="&B19)=0,Settings!$C$8,INDEX(Settings!$C$8:$C$17,COUNTIF(Settings!$B$8:$B$17,"<="&B19)))) -> 0.76 | L19: =IF(K19="","",ROUND(J19*K19,2)) -> 27.97 | M19: =IF(AND(B19="",F19="",G19="",H19=""),"",IF(NOT(ISNUMBER(B19)),"⚠ ADD DATE / AGREGA FECHA",IF(J19="","⚠ ADD MILES / AGREGA MILLAS",IF(AND(ISNUMBER(F19),ISNUMBER(G19)),IF(G19<F19,"⚠ CHECK ODOMETER / REVISA ODÓMETRO","✔ OK"),"✔ OK")))) -> ✔ OK | P19: =IF(ISNUMBER(L19),1,0) -> 1 | Q19: =IF(P19=1,YEAR(B19),0) -> 2026 | R19: =IF(P19=1,YEAR(B19)*100+MONTH(B19),0) -> 202608
B20: 46277 | C20: Home | D20: Uline pickup | E20: Supplies / Materiales | H20: 11 | I20: Yes / Sí | J20: =IF(AND(ISNUMBER(F20),ISNUMBER(G20)),MAX(0,G20-F20),IF(ISNUMBER(H20),H20*IF(I20="Yes / Sí",2,1),"")) -> 22 | K20: =IF(OR(J20="",NOT(ISNUMBER(B20))),"",IF(COUNTIF(Settings!$B$8:$B$17,"<="&B20)=0,Settings!$C$8,INDEX(Settings!$C$8:$C$17,COUNTIF(Settings!$B$8:$B$17,"<="&B20)))) -> 0.76 | L20: =IF(K20="","",ROUND(J20*K20,2)) -> 16.72 | M20: =IF(AND(B20="",F20="",G20="",H20=""),"",IF(NOT(ISNUMBER(B20)),"⚠ ADD DATE / AGREGA FECHA",IF(J20="","⚠ ADD MILES / AGREGA MILLAS",IF(AND(ISNUMBER(F20),ISNUMBER(G20)),IF(G20<F20,"⚠ CHECK ODOMETER / REVISA ODÓMETRO","✔ OK"),"✔ OK")))) -> ✔ OK | P20: =IF(ISNUMBER(L20),1,0) -> 1 | Q20: =IF(P20=1,YEAR(B20),0) -> 2026 | R20: =IF(P20=1,YEAR(B20)*100+MONTH(B20),0) -> 202609
B21: 46291 | C21: Home | D21: Flea market | E21: Sourcing / Compras | H21: 14 | I21: Yes / Sí | J21: =IF(AND(ISNUMBER(F21),ISNUMBER(G21)),MAX(0,G21-F21),IF(ISNUMBER(H21),H21*IF(I21="Yes / Sí",2,1),"")) -> 28 | K21: =IF(OR(J21="",NOT(ISNUMBER(B21))),"",IF(COUNTIF(Settings!$B$8:$B$17,"<="&B21)=0,Settings!$C$8,INDEX(Settings!$C$8:$C$17,COUNTIF(Settings!$B$8:$B$17,"<="&B21)))) -> 0.76 | L21: =IF(K21="","",ROUND(J21*K21,2)) -> 21.28 | M21: =IF(AND(B21="",F21="",G21="",H21=""),"",IF(NOT(ISNUMBER(B21)),"⚠ ADD DATE / AGREGA FECHA",IF(J21="","⚠ ADD MILES / AGREGA MILLAS",IF(AND(ISNUMBER(F21),ISNUMBER(G21)),IF(G21<F21,"⚠ CHECK ODOMETER / REVISA ODÓMETRO","✔ OK"),"✔ OK")))) -> ✔ OK | P21: =IF(ISNUMBER(L21),1,0) -> 1 | Q21: =IF(P21=1,YEAR(B21),0) -> 2026 | R21: =IF(P21=1,YEAR(B21)*100+MONTH(B21),0) -> 202609
J22: =IF(AND(ISNUMBER(F22),ISNUMBER(G22)),MAX(0,G22-F22),IF(ISNUMBER(H22),H22*IF(I22="Yes / Sí",2,1),"")) | K22: =IF(OR(J22="",NOT(ISNUMBER(B22))),"",IF(COUNTIF(Settings!$B$8:$B$17,"<="&B22)=0,Settings!$C$8,INDEX(Settings!$C$8:$C$17,COUNTIF(Settings!$B$8:$B$17,"<="&B22)))) | L22: =IF(K22="","",ROUND(J22*K22,2)) | M22: =IF(AND(B22="",F22="",G22="",H22=""),"",IF(NOT(ISNUMBER(B22)),"⚠ ADD DATE / AGREGA FECHA",IF(J22="","⚠ ADD MILES / AGREGA MILLAS",IF(AND(ISNUMBER(F22),ISNUMBER(G22)),IF(G22<F22,"⚠ CHECK ODOMETER / REVISA ODÓMETRO","✔ OK"),"✔ OK")))) | P22: =IF(ISNUMBER(L22),1,0) -> 0 | Q22: =IF(P22=1,YEAR(B22),0) -> 0 | R22: =IF(P22=1,YEAR(B22)*100+MONTH(B22),0) -> 0
J23: =IF(AND(ISNUMBER(F23),ISNUMBER(G23)),MAX(0,G23-F23),IF(ISNUMBER(H23),H23*IF(I23="Yes / Sí",2,1),"")) | K23: =IF(OR(J23="",NOT(ISNUMBER(B23))),"",IF(COUNTIF(Settings!$B$8:$B$17,"<="&B23)=0,Settings!$C$8,INDEX(Settings!$C$8:$C$17,COUNTIF(Settings!$B$8:$B$17,"<="&B23)))) | L23: =IF(K23="","",ROUND(J23*K23,2)) | M23: =IF(AND(B23="",F23="",G23="",H23=""),"",IF(NOT(ISNUMBER(B23)),"⚠ ADD DATE / AGREGA FECHA",IF(J23="","⚠ ADD MILES / AGREGA MILLAS",IF(AND(ISNUMBER(F23),ISNUMBER(G23)),IF(G23<F23,"⚠ CHECK ODOMETER / REVISA ODÓMETRO","✔ OK"),"✔ OK")))) | P23: =IF(ISNUMBER(L23),1,0) -> 0 | Q23: =IF(P23=1,YEAR(B23),0) -> 0 | R23: =IF(P23=1,YEAR(B23)*100+MONTH(B23),0) -> 0
J24: =IF(AND(ISNUMBER(F24),ISNUMBER(G24)),MAX(0,G24-F24),IF(ISNUMBER(H24),H24*IF(I24="Yes / Sí",2,1),"")) | K24: =IF(OR(J24="",NOT(ISNUMBER(B24))),"",IF(COUNTIF(Settings!$B$8:$B$17,"<="&B24)=0,Settings!$C$8,INDEX(Settings!$C$8:$C$17,COUNTIF(Settings!$B$8:$B$17,"<="&B24)))) | L24: =IF(K24="","",ROUND(J24*K24,2)) | M24: =IF(AND(B24="",F24="",G24="",H24=""),"",IF(NOT(ISNUMBER(B24)),"⚠ ADD DATE / AGREGA FECHA",IF(J24="","⚠ ADD MILES / AGREGA MILLAS",IF(AND(ISNUMBER(F24),ISNUMBER(G24)),IF(G24<F24,"⚠ CHECK ODOMETER / REVISA ODÓMETRO","✔ OK"),"✔ OK")))) | P24: =IF(ISNUMBER(L24),1,0) -> 0 | Q24: =IF(P24=1,YEAR(B24),0) -> 0 | R24: =IF(P24=1,YEAR(B24)*100+MONTH(B24),0) -> 0
J25: =IF(AND(ISNUMBER(F25),ISNUMBER(G25)),MAX(0,G25-F25),IF(ISNUMBER(H25),H25*IF(I25="Yes / Sí",2,1),"")) | K25: =IF(OR(J25="",NOT(ISNUMBER(B25))),"",IF(COUNTIF(Settings!$B$8:$B$17,"<="&B25)=0,Settings!$C$8,INDEX(Settings!$C$8:$C$17,COUNTIF(Settings!$B$8:$B$17,"<="&B25)))) | L25: =IF(K25="","",ROUND(J25*K25,2)) | M25: =IF(AND(B25="",F25="",G25="",H25=""),"",IF(NOT(ISNUMBER(B25)),"⚠ ADD DATE / AGREGA FECHA",IF(J25="","⚠ ADD MILES / AGREGA MILLAS",IF(AND(ISNUMBER(F25),ISNUMBER(G25)),IF(G25<F25,"⚠ CHECK ODOMETER / REVISA ODÓMETRO","✔ OK"),"✔ OK")))) | P25: =IF(ISNUMBER(L25),1,0) -> 0 | Q25: =IF(P25=1,YEAR(B25),0) -> 0 | R25: =IF(P25=1,YEAR(B25)*100+MONTH(B25),0) -> 0
J26: =IF(AND(ISNUMBER(F26),ISNUMBER(G26)),MAX(0,G26-F26),IF(ISNUMBER(H26),H26*IF(I26="Yes / Sí",2,1),"")) | K26: =IF(OR(J26="",NOT(ISNUMBER(B26))),"",IF(COUNTIF(Settings!$B$8:$B$17,"<="&B26)=0,Settings!$C$8,INDEX(Settings!$C$8:$C$17,COUNTIF(Settings!$B$8:$B$17,"<="&B26)))) | L26: =IF(K26="","",ROUND(J26*K26,2)) | M26: =IF(AND(B26="",F26="",G26="",H26=""),"",IF(NOT(ISNUMBER(B26)),"⚠ ADD DATE / AGREGA FECHA",IF(J26="","⚠ ADD MILES / AGREGA MILLAS",IF(AND(ISNUMBER(F26),ISNUMBER(G26)),IF(G26<F26,"⚠ CHECK ODOMETER / REVISA ODÓMETRO","✔ OK"),"✔ OK")))) | P26: =IF(ISNUMBER(L26),1,0) -> 0 | Q26: =IF(P26=1,YEAR(B26),0) -> 0 | R26: =IF(P26=1,YEAR(B26)*100+MONTH(B26),0) -> 0
J27: =IF(AND(ISNUMBER(F27),ISNUMBER(G27)),MAX(0,G27-F27),IF(ISNUMBER(H27),H27*IF(I27="Yes / Sí",2,1),"")) | K27: =IF(OR(J27="",NOT(ISNUMBER(B27))),"",IF(COUNTIF(Settings!$B$8:$B$17,"<="&B27)=0,Settings!$C$8,INDEX(Settings!$C$8:$C$17,COUNTIF(Settings!$B$8:$B$17,"<="&B27)))) | L27: =IF(K27="","",ROUND(J27*K27,2)) | M27: =IF(AND(B27="",F27="",G27="",H27=""),"",IF(NOT(ISNUMBER(B27)),"⚠ ADD DATE / AGREGA FECHA",IF(J27="","⚠ ADD MILES / AGREGA MILLAS",IF(AND(ISNUMBER(F27),ISNUMBER(G27)),IF(G27<F27,"⚠ CHECK ODOMETER / REVISA ODÓMETRO","✔ OK"),"✔ OK")))) | P27: =IF(ISNUMBER(L27),1,0) -> 0 | Q27: =IF(P27=1,YEAR(B27),0) -> 0 | R27: =IF(P27=1,YEAR(B27)*100+MONTH(B27),0) -> 0
J28: =IF(AND(ISNUMBER(F28),ISNUMBER(G28)),MAX(0,G28-F28),IF(ISNUMBER(H28),H28*IF(I28="Yes / Sí",2,1),"")) | K28: =IF(OR(J28="",NOT(ISNUMBER(B28))),"",IF(COUNTIF(Settings!$B$8:$B$17,"<="&B28)=0,Settings!$C$8,INDEX(Settings!$C$8:$C$17,COUNTIF(Settings!$B$8:$B$17,"<="&B28)))) | L28: =IF(K28="","",ROUND(J28*K28,2)) | M28: =IF(AND(B28="",F28="",G28="",H28=""),"",IF(NOT(ISNUMBER(B28)),"⚠ ADD DATE / AGREGA FECHA",IF(J28="","⚠ ADD MILES / AGREGA MILLAS",IF(AND(ISNUMBER(F28),ISNUMBER(G28)),IF(G28<F28,"⚠ CHECK ODOMETER / REVISA ODÓMETRO","✔ OK"),"✔ OK")))) | P28: =IF(ISNUMBER(L28),1,0) -> 0 | Q28: =IF(P28=1,YEAR(B28),0) -> 0 | R28: =IF(P28=1,YEAR(B28)*100+MONTH(B28),0) -> 0
J29: =IF(AND(ISNUMBER(F29),ISNUMBER(G29)),MAX(0,G29-F29),IF(ISNUMBER(H29),H29*IF(I29="Yes / Sí",2,1),"")) | K29: =IF(OR(J29="",NOT(ISNUMBER(B29))),"",IF(COUNTIF(Settings!$B$8:$B$17,"<="&B29)=0,Settings!$C$8,INDEX(Settings!$C$8:$C$17,COUNTIF(Settings!$B$8:$B$17,"<="&B29)))) | L29: =IF(K29="","",ROUND(J29*K29,2)) | M29: =IF(AND(B29="",F29="",G29="",H29=""),"",IF(NOT(ISNUMBER(B29)),"⚠ ADD DATE / AGREGA FECHA",IF(J29="","⚠ ADD MILES / AGREGA MILLAS",IF(AND(ISNUMBER(F29),ISNUMBER(G29)),IF(G29<F29,"⚠ CHECK ODOMETER / REVISA ODÓMETRO","✔ OK"),"✔ OK")))) | P29: =IF(ISNUMBER(L29),1,0) -> 0 | Q29: =IF(P29=1,YEAR(B29),0) -> 0 | R29: =IF(P29=1,YEAR(B29)*100+MONTH(B29),0) -> 0
J30: =IF(AND(ISNUMBER(F30),ISNUMBER(G30)),MAX(0,G30-F30),IF(ISNUMBER(H30),H30*IF(I30="Yes / Sí",2,1),"")) | K30: =IF(OR(J30="",NOT(ISNUMBER(B30))),"",IF(COUNTIF(Settings!$B$8:$B$17,"<="&B30)=0,Settings!$C$8,INDEX(Settings!$C$8:$C$17,COUNTIF(Settings!$B$8:$B$17,"<="&B30)))) | L30: =IF(K30="","",ROUND(J30*K30,2)) | M30: =IF(AND(B30="",F30="",G30="",H30=""),"",IF(NOT(ISNUMBER(B30)),"⚠ ADD DATE / AGREGA FECHA",IF(J30="","⚠ ADD MILES / AGREGA MILLAS",IF(AND(ISNUMBER(F30),ISNUMBER(G30)),IF(G30<F30,"⚠ CHECK ODOMETER / REVISA ODÓMETRO","✔ OK"),"✔ OK")))) | P30: =IF(ISNUMBER(L30),1,0) -> 0 | Q30: =IF(P30=1,YEAR(B30),0) -> 0 | R30: =IF(P30=1,YEAR(B30)*100+MONTH(B30),0) -> 0
J31: =IF(AND(ISNUMBER(F31),ISNUMBER(G31)),MAX(0,G31-F31),IF(ISNUMBER(H31),H31*IF(I31="Yes / Sí",2,1),"")) | K31: =IF(OR(J31="",NOT(ISNUMBER(B31))),"",IF(COUNTIF(Settings!$B$8:$B$17,"<="&B31)=0,Settings!$C$8,INDEX(Settings!$C$8:$C$17,COUNTIF(Settings!$B$8:$B$17,"<="&B31)))) | L31: =IF(K31="","",ROUND(J31*K31,2)) | M31: =IF(AND(B31="",F31="",G31="",H31=""),"",IF(NOT(ISNUMBER(B31)),"⚠ ADD DATE / AGREGA FECHA",IF(J31="","⚠ ADD MILES / AGREGA MILLAS",IF(AND(ISNUMBER(F31),ISNUMBER(G31)),IF(G31<F31,"⚠ CHECK ODOMETER / REVISA ODÓMETRO","✔ OK"),"✔ OK")))) | P31: =IF(ISNUMBER(L31),1,0) -> 0 | Q31: =IF(P31=1,YEAR(B31),0) -> 0 | R31: =IF(P31=1,YEAR(B31)*100+MONTH(B31),0) -> 0
J32: =IF(AND(ISNUMBER(F32),ISNUMBER(G32)),MAX(0,G32-F32),IF(ISNUMBER(H32),H32*IF(I32="Yes / Sí",2,1),"")) | K32: =IF(OR(J32="",NOT(ISNUMBER(B32))),"",IF(COUNTIF(Settings!$B$8:$B$17,"<="&B32)=0,Settings!$C$8,INDEX(Settings!$C$8:$C$17,COUNTIF(Settings!$B$8:$B$17,"<="&B32)))) | L32: =IF(K32="","",ROUND(J32*K32,2)) | M32: =IF(AND(B32="",F32="",G32="",H32=""),"",IF(NOT(ISNUMBER(B32)),"⚠ ADD DATE / AGREGA FECHA",IF(J32="","⚠ ADD MILES / AGREGA MILLAS",IF(AND(ISNUMBER(F32),ISNUMBER(G32)),IF(G32<F32,"⚠ CHECK ODOMETER / REVISA ODÓMETRO","✔ OK"),"✔ OK")))) | P32: =IF(ISNUMBER(L32),1,0) -> 0 | Q32: =IF(P32=1,YEAR(B32),0) -> 0 | R32: =IF(P32=1,YEAR(B32)*100+MONTH(B32),0) -> 0
J33: =IF(AND(ISNUMBER(F33),ISNUMBER(G33)),MAX(0,G33-F33),IF(ISNUMBER(H33),H33*IF(I33="Yes / Sí",2,1),"")) | K33: =IF(OR(J33="",NOT(ISNUMBER(B33))),"",IF(COUNTIF(Settings!$B$8:$B$17,"<="&B33)=0,Settings!$C$8,INDEX(Settings!$C$8:$C$17,COUNTIF(Settings!$B$8:$B$17,"<="&B33)))) | L33: =IF(K33="","",ROUND(J33*K33,2)) | M33: =IF(AND(B33="",F33="",G33="",H33=""),"",IF(NOT(ISNUMBER(B33)),"⚠ ADD DATE / AGREGA FECHA",IF(J33="","⚠ ADD MILES / AGREGA MILLAS",IF(AND(ISNUMBER(F33),ISNUMBER(G33)),IF(G33<F33,"⚠ CHECK ODOMETER / REVISA ODÓMETRO","✔ OK"),"✔ OK")))) | P33: =IF(ISNUMBER(L33),1,0) -> 0 | Q33: =IF(P33=1,YEAR(B33),0) -> 0 | R33: =IF(P33=1,YEAR(B33)*100+MONTH(B33),0) -> 0
... J505: =IF(AND(ISNUMBER(F505),ISNUMBER(G505)),MAX(0,G505-F505),IF(ISNUMBER(H505),H505*IF(I505="Yes / Sí",2,1),"")) | K505: =IF(OR(J505="",NOT(ISNUMBER(B505))),"",IF(COUNTIF(Settings!$B$8:$B$17,"<="&B505)=0,Settings!$C$8,INDEX(Settings!$C$8:$C$17,COUNTIF(Settings!$B$8:$B$17,"<="&B505)))) | L505: =IF(K505="","",ROUND(J505*K505,2)) | M505: =IF(AND(B505="",F505="",G505="",H505=""),"",IF(NOT(ISNUMBER(B505)),"⚠ ADD DATE / AGREGA FECHA",IF(J505="","⚠ ADD MILES / AGREGA MILLAS",IF(AND(ISNUMBER(F505),ISNUMBER(G505)),IF(G505<F505,"⚠ CHECK ODOMETER / REVISA ODÓMETRO","✔ OK"),"✔ OK")))) | P505: =IF(ISNUMBER(L505),1,0) -> 0 | Q505: =IF(P505=1,YEAR(B505),0) -> 0 | R505: =IF(P505=1,YEAR(B505)*100+MONTH(B505),0) -> 0

Sheet Settings
B1: ProfitTrack
B2: Settings / Configuración
B3: Mileage rates and expense categories. • Tarifas por milla y categorías de gastos.
B6: IRS Mileage Rates / Tarifas por Milla del IRS | F6: Expense Categories / Categorías de Gastos
B7: Effective From Vigente Desde | C7: Rate $ / mile Tarifa $ / milla | D7: Source / Fuente | F7: Category (edit or add your own) Categoría (edita o agrega)
B8: 45658 | C8: 0.7 | D8: IRS – 2025 business rate | F8: Shipping Supplies / Materiales de Envío
B9: 46023 | C9: 0.725 | D9: IRS Notice 2026-10 | F9: Postage & Shipping Labels / Envíos y Etiquetas
B10: 46204 | C10: 0.76 | D10: IRS Announcement 2026-11 (mid-year increase) | F10: Platform & Subscription Fees / Tarifas y Suscripciones
F11: Advertising & Promoted Listings / Publicidad
F12: Office Supplies / Artículos de Oficina
F13: Equipment & Tools / Equipo y Herramientas
F14: Phone & Internet / Teléfono e Internet
F15: Storage & Rent / Almacenaje y Renta
F16: Cleaning & Repairs / Limpieza y Reparaciones
F17: Software & Apps / Software y Aplicaciones
B18: Keep dates oldest → newest. When the IRS announces a new rate, add it on the next empty row – each trip uses the rate in effect on its date. Using kilometres? Enter your rate per km and log km in the Mileage sheet. Mantén las fechas de la más antigua a la más reciente. Cuando el IRS anuncie una nueva tarifa, agrégala en la siguiente fila vacía. ¿Usas kilómetros? Escribe tu tarifa por km. | F18: Education & Courses / Educación y Cursos
F19: Other / Otro
F22: Rows 20–21 are free for your own categories. / Las filas 20–21 son para tus propias categorías.

Sheet Quick Start Guide
B1: ProfitTrack
B2: Quick Start Guide / Guía Rápida
B3: Up and running in 5 minutes. • Listo en 5 minutos.
B6: # | C6: ENGLISH | D6: ESPAÑOL
B7: 1 | C7: Clear the example data: on Expenses select B6:K23 and press Delete; on Mileage select B6:I21 and press Delete. Never delete whole rows or the grey columns. | D7: Borra los datos de ejemplo: en Expenses selecciona B6:K23 y presiona Suprimir; en Mileage selecciona B6:I21 y presiona Suprimir. Nunca borres filas completas ni las columnas grises.
B8: 2 | C8: Check Settings. The IRS mileage table is filled in (2026: 72.5¢/mile Jan 1 – Jun 30 and 76¢/mile from Jul 1). When the IRS announces a new rate, add it on the next empty row. Rename or add expense categories if you like. | D8: Revisa Settings (Configuración). La tabla de tarifas del IRS ya está llena (2026: 72.5¢/milla del 1 ene al 30 jun y 76¢/milla desde el 1 jul). Cuando el IRS anuncie una nueva tarifa, agrégala en la siguiente fila vacía. Puedes renombrar o agregar categorías.
B9: 3 | C9: Log every business expense on Expenses: date, vendor, description, category (dropdown), payment method and amount. For mixed-use items (like your phone) enter the Business Use % – blank means 100%. | D9: Registra cada gasto del negocio en Expenses: fecha, proveedor, descripción, categoría (lista), método de pago y monto. Para artículos de uso mixto (como tu teléfono) escribe el % de Uso del Negocio – vacío significa 100%.
B10: 4 | C10: Mark 'Receipt Saved?' Yes or No. The Check column flags anything missing: date, category or receipt. | D10: Marca '¿Recibo Guardado?' Sí o No. La columna Revisar marca lo que falte: fecha, categoría o recibo.
B11: 5 | C11: Log every business trip on Mileage: date, from, to and purpose. Enter the odometer start & end, OR just the miles (e.g. from Google Maps). 'Round Trip? = Yes' doubles the miles you typed. | D11: Registra cada viaje de negocio en Mileage: fecha, desde, hasta y propósito. Escribe el odómetro inicial y final, O solo las millas (ej. de Google Maps). '¿Ida y Vuelta? = Sí' duplica las millas escritas.
B12: 6 | C12: The correct IRS rate for each trip date is applied automatically, and Deduction $ = Total Miles × Rate. | D12: La tarifa correcta del IRS para la fecha de cada viaje se aplica sola, y Deducción $ = Millas Totales × Tarifa.
B13: 7 | C13: Open the Dashboard: deductible expenses, business miles, mileage deduction and total deductions for the tax year, plus category and monthly charts. It's locked to protect formulas – only the yellow Tax Year cell can be changed. | D13: Abre el Dashboard (Panel): gastos deducibles, millas de negocio, deducción por millaje y deducciones totales del año fiscal, más gráficas por categoría y por mes. Está bloqueado para proteger las fórmulas – solo se puede cambiar la celda amarilla del Año Fiscal.
B14: 8 | C14: At tax time, share the Dashboard totals (and your receipts) with your tax preparer. | D14: En temporada de impuestos, comparte los totales del Panel (y tus recibos) con tu preparador de impuestos.
B15: 9 | C15: Don't log inventory purchases here – those are your cost of goods. Track them per item in ProfitTrack Profit Tracker or ProfitTrack Inventory. | D15: No registres aquí la compra de mercancía – eso es tu costo de ventas. Regístrala por artículo en ProfitTrack Profit Tracker o ProfitTrack Inventory.
B16: 10 | C16: Google Sheets: upload to Google Drive → Open with Google Sheets → File → Save as Google Sheets. Tip: save a blank copy first and back up monthly. | D16: Google Sheets: súbelo a Google Drive → Abrir con Google Sheets → Archivo → Guardar como Hojas de cálculo de Google. Consejo: guarda una copia en blanco y respalda cada mes.
B18: Color Legend / Leyenda de Colores
C19: Light teal = type your data here | D19: Verde claro = escribe tus datos aquí
C20: Grey = automatic formula – don't type here | D20: Gris = fórmula automática – no escribas aquí
C21: Yellow = settings you can change | D21: Amarillo = ajustes que puedes cambiar
B23: FAQ / Preguntas Frecuentes
C24: Q: I use kilometres. A: Put your rate per km in Settings and type km in the Mileage sheet – the math is the same. | D24: P: Uso kilómetros. R: Pon tu tarifa por km en Settings y escribe km en la hoja Mileage – el cálculo es igual.
C25: Q: Which trips count? A: Generally trips for business – sourcing, post office, supplies, bank. Regular commuting usually doesn't. Ask your tax professional about your situation. | D25: P: ¿Qué viajes cuentan? R: En general los viajes de negocio – compras, correo, materiales, banco. El traslado habitual normalmente no. Consulta a tu profesional de impuestos.
C26: Q: Why can't I type on the Dashboard? A: It's locked so formulas can't be erased by accident. To unlock (no password): Excel → Review → Unprotect Sheet. | D26: P: ¿Por qué no puedo escribir en el Panel? R: Está bloqueado para no borrar fórmulas por accidente. Para desbloquear (sin contraseña): Excel → Revisar → Desproteger hoja.
C27: Q: How many rows? A: 500 expenses and 500 trips per file. Start a fresh copy each tax year. | D27: P: ¿Cuántas filas? R: 500 gastos y 500 viajes por archivo. Usa una copia nueva cada año fiscal.
B29: Important / Importante
C30: This template helps you organize records. It is not tax, legal or accounting advice. Deduction rules depend on your situation – consult a qualified tax professional. Mileage rates: IRS Notice 2026-10 and Announcement 2026-11 (verify at irs.gov). | D30: Esta plantilla te ayuda a organizar tus registros. No es asesoría fiscal, legal ni contable. Las reglas de deducción dependen de tu situación – consulta a un profesional de impuestos calificado. Tarifas: IRS Notice 2026-10 y Announcement 2026-11 (verifica en irs.gov).
B32: Phone, Tablet & Computer / Celular, Tableta y Computadora
C33: 💻 Computer (Windows / Mac): open in Microsoft Excel, or in Google Sheets from any browser. Everything works. | D33: 💻 Computadora (Windows / Mac): ábrelo en Microsoft Excel o en Google Sheets desde cualquier navegador. Todo funciona.
C34: 📱 iPhone, iPad & Android — RECOMMENDED: the free Microsoft Excel app or the free Google Sheets app. Formulas, dropdowns, charts and alerts all work. | D34: 📱 iPhone, iPad y Android — RECOMENDADO: la app gratuita Microsoft Excel o la app gratuita Google Sheets. Fórmulas, listas, gráficas y alertas funcionan.
C35: 🍎 Apple Numbers: formulas, Dashboard, charts and alerts work, but Numbers removes dropdown lists from Excel files (you'll see a message – this is normal). Type the option exactly as listed, or re-add a menu: select the cells → Format → Cell → Data Format → Pop-Up Menu. | D35: 🍎 Apple Numbers: las fórmulas, el Panel, las gráficas y las alertas funcionan, pero Numbers elimina las listas desplegables de los archivos de Excel (verás un aviso – es normal). Escribe la opción tal como aparece, o vuelve a crear el menú: selecciona las celdas → Formato → Celda → Formato de datos → Menú desplegable.
