Workbook

Sheet Cover
B4: FAMILY FINANCES • FINANZAS FAMILIARES
B6: ProfitTrack
B9: Bilingual Budget Planner
B10: Planificador de Presupuesto Bilingüe
B11: English + Español — every heading, every instruction / cada título, cada instrucción
B15: WHAT'S INSIDE / CONTENIDO (click to open • clic para abrir)
C17: 📊 Dashboard / Panel
C18: Month at a glance, budget vs. actual, 50/30/20, year overview / Tu mes de un vistazo
C20: 🧾 Transactions / Movimientos
C21: Log income & spending in seconds / Registra ingresos y gastos en segundos
C23: 🎯 Budget / Presupuesto
C24: Your monthly plan by category / Tu plan mensual por categoría
C26: 🐷 Savings Goals / Metas de Ahorro
C27: Progress bars & how much to save each month / Cuánto ahorrar cada mes
C29: 💳 Debts / Deudas
C30: Payoff date, interest, snowball & avalanche order / Fecha de pago e intereses
C32: 🚀 Quick Start Guide / Guía Rápida
C33: Step-by-step setup in 5 minutes / Configuración paso a paso
B36: 💻 PC / Mac • 📱 iPhone / Android — Excel • Google Sheets | Computadora y celular — Excel • Google Sheets
B38: Start here → Quick Start Guide | Empieza aquí → Guía Rápida
B41: © ProfitTrack • v1.0 • For personal use only – do not resell or redistribute / Solo para uso personal – prohibida su reventa o distribución

Sheet Dashboard
B1: ProfitTrack
B2: Dashboard / Panel de Control
B3: Pick a month to see where your money went. Updates automatically. • Elige un mes para ver a dónde fue tu dinero. Se actualiza solo.
B6: Month / Mes: | C6: =INDEX($B$58:$B$69,IF(COUNT(Transactions!$B$6:$B$1005)=0,MONTH(TODAY()),MONTH(MAX(Transactions!$B$6:$B$1005)))) -> Sep / Sep | E6: Year / Año: | F6: =IF(COUNT(Transactions!$B$6:$B$1005)=0,YEAR(TODAY()),YEAR(MAX(Transactions!$B$6:$B$1005))) -> 2026 | G6: ← pick month & year / elige mes y año | Q6: =IFERROR(MATCH($C$6,$B$58:$B$69,0),1) -> 9
Q7: =$F$6*100+$Q$6 -> 202609
B8: INCOME THIS MONTH | C8: SPENDING THIS MONTH | E8: LEFT OVER | G8: CATEGORIES OVER BUDGET
B9: Ingresos del Mes | C9: Gastos del Mes | E9: Sobrante | G9: Categorías Excedidas
B10: =SUMIFS(Transactions!$E$6:$E$1005,Transactions!$L$6:$L$1005,$Q$7,Transactions!$H$6:$H$1005,"Income / Ingreso") -> 6050 | C10: =SUMIFS(Transactions!$E$6:$E$1005,Transactions!$L$6:$L$1005,$Q$7,Transactions!$H$6:$H$1005,"Expense / Gasto") -> 4592.73 | E10: =B10-C10 -> 1457.27 | G10: =SUM($S$21:$S$50) -> 2
B11: =SUM(Budget!$E$7:$E$11) -> 5900 | C11: =SUM(C21:C50) -> 5850 | E11: =IF(B10=0,0,E10/B10) -> 0.24087107 | G11: ✔ under = green · ⚠ over = red
B13: INCOME THIS YEAR | C13: SPENDING THIS YEAR | E13: SAVED TOWARD GOALS | G13: TOTAL DEBT
B14: Ingresos del Año | C14: Gastos del Año | E14: Ahorrado para Metas | G14: Deuda Total
B15: =SUMIFS(Transactions!$E$6:$E$1005,Transactions!$M$6:$M$1005,$F$6,Transactions!$H$6:$H$1005,"Income / Ingreso") -> 51750 | C15: =SUMIFS(Transactions!$E$6:$E$1005,Transactions!$M$6:$M$1005,$F$6,Transactions!$H$6:$H$1005,"Expense / Gasto") -> 42070.74 | E15: =SUM('Savings Goals'!$D$6:$D$25) -> 3000 | G15: =Debts!$G$27 -> 24850
E16: =SUM('Savings Goals'!$C$6:$C$25) -> 10400 | G16: =Debts!$G$28 -> 625
B18: Budget vs. Actual – Selected Month / Presupuesto vs. Real – Mes Elegido | I18: 50 / 30 / 20 Check – Selected Month / Regla 50/30/20
B20: Category Categoría | C20: Budget Presupuesto | D20: Actual Real | E20: Difference Diferencia | F20: % Used % Usado | G20: Status Estado | I20: Group Grupo | J20: Spent Gastado | K20: % of Income % del Ingreso | L20: Ideal Ideal | M20: Result Resultado
B21: =IF(Budget!$B$12="","",Budget!$B$12) -> Rent / Mortgage – Renta / Hipoteca | C21: =IF($B21="",0,IF(Budget!$E$12="",0,Budget!$E$12)) -> 1650 | D21: =IF($B21="",0,SUMIFS(Transactions!$E$6:$E$1005,Transactions!$L$6:$L$1005,$Q$7,Transactions!$D$6:$D$1005,$B21)) -> 1650 | E21: =C21-D21 -> 0 | F21: =IF($B21="","",IF(C21=0,IF(D21>0,1,0),D21/C21)) -> 1 | G21: =IF($B21="","",IF(D21>C21,"⚠ OVER / EXCEDIDO",IF(D21=0,"– not used / sin uso","✔ UNDER / BAJO"))) -> ✔ UNDER / BAJO | I21: Needs / Necesidades | J21: =ROUND(SUMIFS(Transactions!$E$6:$E$1005,Transactions!$L$6:$L$1005,$Q$7,Transactions!$N$6:$N$1005,I21,Transactions!$H$6:$H$1005,"Expense / Gasto"),2) -> 3655.23 | K21: =IF($B$10=0,0,J21/$B$10) -> 0.60417025 | L21: 0.5 | M21: =IF(K21<=L21,"✔ ON TRACK / BIEN","● TOO HIGH / MUY ALTO") -> ● TOO HIGH / MUY ALTO | S21: =IF($B21="",0,IF(D21>C21,1,0)) -> 0
B22: =IF(Budget!$B$13="","",Budget!$B$13) -> Utilities / Servicios (luz, agua, gas) | C22: =IF($B22="",0,IF(Budget!$E$13="",0,Budget!$E$13)) -> 220 | D22: =IF($B22="",0,SUMIFS(Transactions!$E$6:$E$1005,Transactions!$L$6:$L$1005,$Q$7,Transactions!$D$6:$D$1005,$B22)) -> 259.06 | E22: =C22-D22 -> -39.06 | F22: =IF($B22="","",IF(C22=0,IF(D22>0,1,0),D22/C22)) -> 1.1775455 | G22: =IF($B22="","",IF(D22>C22,"⚠ OVER / EXCEDIDO",IF(D22=0,"– not used / sin uso","✔ UNDER / BAJO"))) -> ⚠ OVER / EXCEDIDO | I22: Wants / Gustos | J22: =ROUND(SUMIFS(Transactions!$E$6:$E$1005,Transactions!$L$6:$L$1005,$Q$7,Transactions!$N$6:$N$1005,I22,Transactions!$H$6:$H$1005,"Expense / Gasto"),2) -> 162.5 | K22: =IF($B$10=0,0,J22/$B$10) -> 0.026859504 | L22: 0.3 | M22: =IF(K22<=L22,"✔ ON TRACK / BIEN","● TOO HIGH / MUY ALTO") -> ✔ ON TRACK / BIEN | S22: =IF($B22="",0,IF(D22>C22,1,0)) -> 1
B23: =IF(Budget!$B$14="","",Budget!$B$14) -> Groceries / Supermercado | C23: =IF($B23="",0,IF(Budget!$E$14="",0,Budget!$E$14)) -> 650 | D23: =IF($B23="",0,SUMIFS(Transactions!$E$6:$E$1005,Transactions!$L$6:$L$1005,$Q$7,Transactions!$D$6:$D$1005,$B23)) -> 581.42 | E23: =C23-D23 -> 68.58 | F23: =IF($B23="","",IF(C23=0,IF(D23>0,1,0),D23/C23)) -> 0.89449231 | G23: =IF($B23="","",IF(D23>C23,"⚠ OVER / EXCEDIDO",IF(D23=0,"– not used / sin uso","✔ UNDER / BAJO"))) -> ✔ UNDER / BAJO | I23: Savings & Debt / Ahorro y Deuda | J23: =ROUND(SUMIFS(Transactions!$E$6:$E$1005,Transactions!$L$6:$L$1005,$Q$7,Transactions!$N$6:$N$1005,I23,Transactions!$H$6:$H$1005,"Expense / Gasto"),2) -> 775 | K23: =IF($B$10=0,0,J23/$B$10) -> 0.12809917 | L23: 0.2 | M23: =IF(K23>=L23,"✔ GREAT / EXCELENTE","● SAVE MORE / AHORRA MÁS") -> ● SAVE MORE / AHORRA MÁS | S23: =IF($B23="",0,IF(D23>C23,1,0)) -> 0
B24: =IF(Budget!$B$15="","",Budget!$B$15) -> Transportation / Transporte | C24: =IF($B24="",0,IF(Budget!$E$15="",0,Budget!$E$15)) -> 180 | D24: =IF($B24="",0,SUMIFS(Transactions!$E$6:$E$1005,Transactions!$L$6:$L$1005,$Q$7,Transactions!$D$6:$D$1005,$B24)) -> 0 | E24: =C24-D24 -> 180 | F24: =IF($B24="","",IF(C24=0,IF(D24>0,1,0),D24/C24)) -> 0 | G24: =IF($B24="","",IF(D24>C24,"⚠ OVER / EXCEDIDO",IF(D24=0,"– not used / sin uso","✔ UNDER / BAJO"))) -> – not used / sin uso | I24: Groups come from the Budget sheet. / Los grupos vienen de la hoja Presupuesto. | S24: =IF($B24="",0,IF(D24>C24,1,0)) -> 0
B25: =IF(Budget!$B$16="","",Budget!$B$16) -> Gas / Gasolina | C25: =IF($B25="",0,IF(Budget!$E$16="",0,Budget!$E$16)) -> 200 | D25: =IF($B25="",0,SUMIFS(Transactions!$E$6:$E$1005,Transactions!$L$6:$L$1005,$Q$7,Transactions!$D$6:$D$1005,$B25)) -> 214.75 | E25: =C25-D25 -> -14.75 | F25: =IF($B25="","",IF(C25=0,IF(D25>0,1,0),D25/C25)) -> 1.07375 | G25: =IF($B25="","",IF(D25>C25,"⚠ OVER / EXCEDIDO",IF(D25=0,"– not used / sin uso","✔ UNDER / BAJO"))) -> ⚠ OVER / EXCEDIDO | S25: =IF($B25="",0,IF(D25>C25,1,0)) -> 1
B26: =IF(Budget!$B$17="","",Budget!$B$17) -> Insurance / Seguros | C26: =IF($B26="",0,IF(Budget!$E$17="",0,Budget!$E$17)) -> 260 | D26: =IF($B26="",0,SUMIFS(Transactions!$E$6:$E$1005,Transactions!$L$6:$L$1005,$Q$7,Transactions!$D$6:$D$1005,$B26)) -> 260 | E26: =C26-D26 -> 0 | F26: =IF($B26="","",IF(C26=0,IF(D26>0,1,0),D26/C26)) -> 1 | G26: =IF($B26="","",IF(D26>C26,"⚠ OVER / EXCEDIDO",IF(D26=0,"– not used / sin uso","✔ UNDER / BAJO"))) -> ✔ UNDER / BAJO | S26: =IF($B26="",0,IF(D26>C26,1,0)) -> 0
B27: =IF(Budget!$B$18="","",Budget!$B$18) -> Phone & Internet / Teléfono e Internet | C27: =IF($B27="",0,IF(Budget!$E$18="",0,Budget!$E$18)) -> 140 | D27: =IF($B27="",0,SUMIFS(Transactions!$E$6:$E$1005,Transactions!$L$6:$L$1005,$Q$7,Transactions!$D$6:$D$1005,$B27)) -> 140 | E27: =C27-D27 -> 0 | F27: =IF($B27="","",IF(C27=0,IF(D27>0,1,0),D27/C27)) -> 1 | G27: =IF($B27="","",IF(D27>C27,"⚠ OVER / EXCEDIDO",IF(D27=0,"– not used / sin uso","✔ UNDER / BAJO"))) -> ✔ UNDER / BAJO | S27: =IF($B27="",0,IF(D27>C27,1,0)) -> 0
B28: =IF(Budget!$B$19="","",Budget!$B$19) -> Health / Salud | C28: =IF($B28="",0,IF(Budget!$E$19="",0,Budget!$E$19)) -> 120 | D28: =IF($B28="",0,SUMIFS(Transactions!$E$6:$E$1005,Transactions!$L$6:$L$1005,$Q$7,Transactions!$D$6:$D$1005,$B28)) -> 0 | E28: =C28-D28 -> 120 | F28: =IF($B28="","",IF(C28=0,IF(D28>0,1,0),D28/C28)) -> 0 | G28: =IF($B28="","",IF(D28>C28,"⚠ OVER / EXCEDIDO",IF(D28=0,"– not used / sin uso","✔ UNDER / BAJO"))) -> – not used / sin uso | S28: =IF($B28="",0,IF(D28>C28,1,0)) -> 0
B29: =IF(Budget!$B$20="","",Budget!$B$20) -> Childcare & School / Niños y Escuela | C29: =IF($B29="",0,IF(Budget!$E$20="",0,Budget!$E$20)) -> 300 | D29: =IF($B29="",0,SUMIFS(Transactions!$E$6:$E$1005,Transactions!$L$6:$L$1005,$Q$7,Transactions!$D$6:$D$1005,$B29)) -> 300 | E29: =C29-D29 -> 0 | F29: =IF($B29="","",IF(C29=0,IF(D29>0,1,0),D29/C29)) -> 1 | G29: =IF($B29="","",IF(D29>C29,"⚠ OVER / EXCEDIDO",IF(D29=0,"– not used / sin uso","✔ UNDER / BAJO"))) -> ✔ UNDER / BAJO | S29: =IF($B29="",0,IF(D29>C29,1,0)) -> 0
B30: =IF(Budget!$B$21="","",Budget!$B$21) -> Family support / Apoyo a la familia (remesas) | C30: =IF($B30="",0,IF(Budget!$E$21="",0,Budget!$E$21)) -> 250 | D30: =IF($B30="",0,SUMIFS(Transactions!$E$6:$E$1005,Transactions!$L$6:$L$1005,$Q$7,Transactions!$D$6:$D$1005,$B30)) -> 250 | E30: =C30-D30 -> 0 | F30: =IF($B30="","",IF(C30=0,IF(D30>0,1,0),D30/C30)) -> 1 | G30: =IF($B30="","",IF(D30>C30,"⚠ OVER / EXCEDIDO",IF(D30=0,"– not used / sin uso","✔ UNDER / BAJO"))) -> ✔ UNDER / BAJO | S30: =IF($B30="",0,IF(D30>C30,1,0)) -> 0
B31: =IF(Budget!$B$22="","",Budget!$B$22) -> Dining out / Comer fuera | C31: =IF($B31="",0,IF(Budget!$E$22="",0,Budget!$E$22)) -> 220 | D31: =IF($B31="",0,SUMIFS(Transactions!$E$6:$E$1005,Transactions!$L$6:$L$1005,$Q$7,Transactions!$D$6:$D$1005,$B31)) -> 133.52 | E31: =C31-D31 -> 86.48 | F31: =IF($B31="","",IF(C31=0,IF(D31>0,1,0),D31/C31)) -> 0.60690909 | G31: =IF($B31="","",IF(D31>C31,"⚠ OVER / EXCEDIDO",IF(D31=0,"– not used / sin uso","✔ UNDER / BAJO"))) -> ✔ UNDER / BAJO | S31: =IF($B31="",0,IF(D31>C31,1,0)) -> 0
B32: =IF(Budget!$B$23="","",Budget!$B$23) -> Entertainment / Entretenimiento | C32: =IF($B32="",0,IF(Budget!$E$23="",0,Budget!$E$23)) -> 100 | D32: =IF($B32="",0,SUMIFS(Transactions!$E$6:$E$1005,Transactions!$L$6:$L$1005,$Q$7,Transactions!$D$6:$D$1005,$B32)) -> 0 | E32: =C32-D32 -> 100 | F32: =IF($B32="","",IF(C32=0,IF(D32>0,1,0),D32/C32)) -> 0 | G32: =IF($B32="","",IF(D32>C32,"⚠ OVER / EXCEDIDO",IF(D32=0,"– not used / sin uso","✔ UNDER / BAJO"))) -> – not used / sin uso | S32: =IF($B32="",0,IF(D32>C32,1,0)) -> 0
B33: =IF(Budget!$B$24="","",Budget!$B$24) -> Shopping & Clothes / Compras y Ropa | C33: =IF($B33="",0,IF(Budget!$E$24="",0,Budget!$E$24)) -> 150 | D33: =IF($B33="",0,SUMIFS(Transactions!$E$6:$E$1005,Transactions!$L$6:$L$1005,$Q$7,Transactions!$D$6:$D$1005,$B33)) -> 0 | E33: =C33-D33 -> 150 | F33: =IF($B33="","",IF(C33=0,IF(D33>0,1,0),D33/C33)) -> 0 | G33: =IF($B33="","",IF(D33>C33,"⚠ OVER / EXCEDIDO",IF(D33=0,"– not used / sin uso","✔ UNDER / BAJO"))) -> – not used / sin uso | S33: =IF($B33="",0,IF(D33>C33,1,0)) -> 0
B34: =IF(Budget!$B$25="","",Budget!$B$25) -> Subscriptions / Suscripciones | C34: =IF($B34="",0,IF(Budget!$E$25="",0,Budget!$E$25)) -> 45 | D34: =IF($B34="",0,SUMIFS(Transactions!$E$6:$E$1005,Transactions!$L$6:$L$1005,$Q$7,Transactions!$D$6:$D$1005,$B34)) -> 28.98 | E34: =C34-D34 -> 16.02 | F34: =IF($B34="","",IF(C34=0,IF(D34>0,1,0),D34/C34)) -> 0.644 | G34: =IF($B34="","",IF(D34>C34,"⚠ OVER / EXCEDIDO",IF(D34=0,"– not used / sin uso","✔ UNDER / BAJO"))) -> ✔ UNDER / BAJO | S34: =IF($B34="",0,IF(D34>C34,1,0)) -> 0
B35: =IF(Budget!$B$26="","",Budget!$B$26) -> Personal care / Cuidado personal | C35: =IF($B35="",0,IF(Budget!$E$26="",0,Budget!$E$26)) -> 60 | D35: =IF($B35="",0,SUMIFS(Transactions!$E$6:$E$1005,Transactions!$L$6:$L$1005,$Q$7,Transactions!$D$6:$D$1005,$B35)) -> 0 | E35: =C35-D35 -> 60 | F35: =IF($B35="","",IF(C35=0,IF(D35>0,1,0),D35/C35)) -> 0 | G35: =IF($B35="","",IF(D35>C35,"⚠ OVER / EXCEDIDO",IF(D35=0,"– not used / sin uso","✔ UNDER / BAJO"))) -> – not used / sin uso | S35: =IF($B35="",0,IF(D35>C35,1,0)) -> 0
B36: =IF(Budget!$B$27="","",Budget!$B$27) -> Gifts & Donations / Regalos y Donaciones | C36: =IF($B36="",0,IF(Budget!$E$27="",0,Budget!$E$27)) -> 80 | D36: =IF($B36="",0,SUMIFS(Transactions!$E$6:$E$1005,Transactions!$L$6:$L$1005,$Q$7,Transactions!$D$6:$D$1005,$B36)) -> 0 | E36: =C36-D36 -> 80 | F36: =IF($B36="","",IF(C36=0,IF(D36>0,1,0),D36/C36)) -> 0 | G36: =IF($B36="","",IF(D36>C36,"⚠ OVER / EXCEDIDO",IF(D36=0,"– not used / sin uso","✔ UNDER / BAJO"))) -> – not used / sin uso | S36: =IF($B36="",0,IF(D36>C36,1,0)) -> 0
B37: =IF(Budget!$B$28="","",Budget!$B$28) -> Travel / Viajes | C37: =IF($B37="",0,IF(Budget!$E$28="",0,Budget!$E$28)) -> 100 | D37: =IF($B37="",0,SUMIFS(Transactions!$E$6:$E$1005,Transactions!$L$6:$L$1005,$Q$7,Transactions!$D$6:$D$1005,$B37)) -> 0 | E37: =C37-D37 -> 100 | F37: =IF($B37="","",IF(C37=0,IF(D37>0,1,0),D37/C37)) -> 0 | G37: =IF($B37="","",IF(D37>C37,"⚠ OVER / EXCEDIDO",IF(D37=0,"– not used / sin uso","✔ UNDER / BAJO"))) -> – not used / sin uso | S37: =IF($B37="",0,IF(D37>C37,1,0)) -> 0
B38: =IF(Budget!$B$29="","",Budget!$B$29) -> Pets / Mascotas | C38: =IF($B38="",0,IF(Budget!$E$29="",0,Budget!$E$29)) -> 50 | D38: =IF($B38="",0,SUMIFS(Transactions!$E$6:$E$1005,Transactions!$L$6:$L$1005,$Q$7,Transactions!$D$6:$D$1005,$B38)) -> 0 | E38: =C38-D38 -> 50 | F38: =IF($B38="","",IF(C38=0,IF(D38>0,1,0),D38/C38)) -> 0 | G38: =IF($B38="","",IF(D38>C38,"⚠ OVER / EXCEDIDO",IF(D38=0,"– not used / sin uso","✔ UNDER / BAJO"))) -> – not used / sin uso | S38: =IF($B38="",0,IF(D38>C38,1,0)) -> 0
B39: =IF(Budget!$B$30="","",Budget!$B$30) -> Debt payments / Pagos de deudas | C39: =IF($B39="",0,IF(Budget!$E$30="",0,Budget!$E$30)) -> 575 | D39: =IF($B39="",0,SUMIFS(Transactions!$E$6:$E$1005,Transactions!$L$6:$L$1005,$Q$7,Transactions!$D$6:$D$1005,$B39)) -> 575 | E39: =C39-D39 -> 0 | F39: =IF($B39="","",IF(C39=0,IF(D39>0,1,0),D39/C39)) -> 1 | G39: =IF($B39="","",IF(D39>C39,"⚠ OVER / EXCEDIDO",IF(D39=0,"– not used / sin uso","✔ UNDER / BAJO"))) -> ✔ UNDER / BAJO | S39: =IF($B39="",0,IF(D39>C39,1,0)) -> 0
B40: =IF(Budget!$B$31="","",Budget!$B$31) -> Emergency fund / Fondo de emergencia | C40: =IF($B40="",0,IF(Budget!$E$31="",0,Budget!$E$31)) -> 200 | D40: =IF($B40="",0,SUMIFS(Transactions!$E$6:$E$1005,Transactions!$L$6:$L$1005,$Q$7,Transactions!$D$6:$D$1005,$B40)) -> 200 | E40: =C40-D40 -> 0 | F40: =IF($B40="","",IF(C40=0,IF(D40>0,1,0),D40/C40)) -> 1 | G40: =IF($B40="","",IF(D40>C40,"⚠ OVER / EXCEDIDO",IF(D40=0,"– not used / sin uso","✔ UNDER / BAJO"))) -> ✔ UNDER / BAJO | S40: =IF($B40="",0,IF(D40>C40,1,0)) -> 0
B41: =IF(Budget!$B$32="","",Budget!$B$32) -> Savings goals / Metas de ahorro | C41: =IF($B41="",0,IF(Budget!$E$32="",0,Budget!$E$32)) -> 150 | D41: =IF($B41="",0,SUMIFS(Transactions!$E$6:$E$1005,Transactions!$L$6:$L$1005,$Q$7,Transactions!$D$6:$D$1005,$B41)) -> 0 | E41: =C41-D41 -> 150 | F41: =IF($B41="","",IF(C41=0,IF(D41>0,1,0),D41/C41)) -> 0 | G41: =IF($B41="","",IF(D41>C41,"⚠ OVER / EXCEDIDO",IF(D41=0,"– not used / sin uso","✔ UNDER / BAJO"))) -> – not used / sin uso | S41: =IF($B41="",0,IF(D41>C41,1,0)) -> 0
B42: =IF(Budget!$B$33="","",Budget!$B$33) -> Retirement / Retiro | C42: =IF($B42="",0,IF(Budget!$E$33="",0,Budget!$E$33)) -> 100 | D42: =IF($B42="",0,SUMIFS(Transactions!$E$6:$E$1005,Transactions!$L$6:$L$1005,$Q$7,Transactions!$D$6:$D$1005,$B42)) -> 0 | E42: =C42-D42 -> 100 | F42: =IF($B42="","",IF(C42=0,IF(D42>0,1,0),D42/C42)) -> 0 | G42: =IF($B42="","",IF(D42>C42,"⚠ OVER / EXCEDIDO",IF(D42=0,"– not used / sin uso","✔ UNDER / BAJO"))) -> – not used / sin uso | S42: =IF($B42="",0,IF(D42>C42,1,0)) -> 0
B43: =IF(Budget!$B$34="","",Budget!$B$34) -> Other / Otro | C43: =IF($B43="",0,IF(Budget!$E$34="",0,Budget!$E$34)) -> 50 | D43: =IF($B43="",0,SUMIFS(Transactions!$E$6:$E$1005,Transactions!$L$6:$L$1005,$Q$7,Transactions!$D$6:$D$1005,$B43)) -> 0 | E43: =C43-D43 -> 50 | F43: =IF($B43="","",IF(C43=0,IF(D43>0,1,0),D43/C43)) -> 0 | G43: =IF($B43="","",IF(D43>C43,"⚠ OVER / EXCEDIDO",IF(D43=0,"– not used / sin uso","✔ UNDER / BAJO"))) -> – not used / sin uso | S43: =IF($B43="",0,IF(D43>C43,1,0)) -> 0
B44: =IF(Budget!$B$35="","",Budget!$B$35) | C44: =IF($B44="",0,IF(Budget!$E$35="",0,Budget!$E$35)) -> 0 | D44: =IF($B44="",0,SUMIFS(Transactions!$E$6:$E$1005,Transactions!$L$6:$L$1005,$Q$7,Transactions!$D$6:$D$1005,$B44)) -> 0 | E44: =C44-D44 -> 0 | F44: =IF($B44="","",IF(C44=0,IF(D44>0,1,0),D44/C44)) | G44: =IF($B44="","",IF(D44>C44,"⚠ OVER / EXCEDIDO",IF(D44=0,"– not used / sin uso","✔ UNDER / BAJO"))) | S44: =IF($B44="",0,IF(D44>C44,1,0)) -> 0
B45: =IF(Budget!$B$36="","",Budget!$B$36) | C45: =IF($B45="",0,IF(Budget!$E$36="",0,Budget!$E$36)) -> 0 | D45: =IF($B45="",0,SUMIFS(Transactions!$E$6:$E$1005,Transactions!$L$6:$L$1005,$Q$7,Transactions!$D$6:$D$1005,$B45)) -> 0 | E45: =C45-D45 -> 0 | F45: =IF($B45="","",IF(C45=0,IF(D45>0,1,0),D45/C45)) | G45: =IF($B45="","",IF(D45>C45,"⚠ OVER / EXCEDIDO",IF(D45=0,"– not used / sin uso","✔ UNDER / BAJO"))) | S45: =IF($B45="",0,IF(D45>C45,1,0)) -> 0
...

Sheet Transactions
B1: ProfitTrack
B2: Transactions / Movimientos
B3: One row per income or expense. Pick a category – the type and group fill in automatically. • Una fila por ingreso o gasto. Elige la categoría – el tipo y el grupo se llenan solos.
B5: Date Fecha | C5: Description Descripción | D5: Category Categoría | E5: Amount Monto | F5: Payment Method Método de Pago | G5: Notes Notas | H5: Type Tipo | I5: Check Revisar | K5: Helper – do not edit: category row | L5: Helper – do not edit: year-month | M5: Helper – do not edit: year | N5: Helper – do not edit: group
B6: 46023 | C6: Paycheck / Cheque | D6: Salary / Salario | E6: 1700 | F6: Other / Otro | H6: =IF(OR(E6="",D6=""),"",IF(K6=0,"Expense / Gasto",INDEX(Budget!$C$7:$C$41,K6))) -> Income / Ingreso | I6: =IF(AND(B6="",E6=""),"",IF(NOT(ISNUMBER(B6)),"⚠ ADD DATE / AGREGA FECHA",IF(E6="","⚠ ADD AMOUNT / AGREGA MONTO",IF(D6="","⚠ ADD CATEGORY / AGREGA CATEGORÍA",IF(K6=0,"● NEW CATEGORY? / ¿CATEGORÍA NUEVA?","✔ OK"))))) -> ✔ OK | K6: =IF(D6="","",IFERROR(MATCH(D6,Budget!$B$7:$B$41,0),0)) -> 1 | L6: =IF(AND(ISNUMBER(B6),ISNUMBER(E6),D6<>""),YEAR(B6)*100+MONTH(B6),0) -> 202601 | M6: =IF(L6=0,0,YEAR(B6)) -> 2026 | N6: =IF(L6=0,"",IF(K6=0,"Wants / Gustos",INDEX(Budget!$D$7:$D$41,K6))) -> —
B7: 46023 | C7: Rent / Renta | D7: Rent / Mortgage – Renta / Hipoteca | E7: 1650 | F7: Transfer / Transferencia | H7: =IF(OR(E7="",D7=""),"",IF(K7=0,"Expense / Gasto",INDEX(Budget!$C$7:$C$41,K7))) -> Expense / Gasto | I7: =IF(AND(B7="",E7=""),"",IF(NOT(ISNUMBER(B7)),"⚠ ADD DATE / AGREGA FECHA",IF(E7="","⚠ ADD AMOUNT / AGREGA MONTO",IF(D7="","⚠ ADD CATEGORY / AGREGA CATEGORÍA",IF(K7=0,"● NEW CATEGORY? / ¿CATEGORÍA NUEVA?","✔ OK"))))) -> ✔ OK | K7: =IF(D7="","",IFERROR(MATCH(D7,Budget!$B$7:$B$41,0),0)) -> 6 | L7: =IF(AND(ISNUMBER(B7),ISNUMBER(E7),D7<>""),YEAR(B7)*100+MONTH(B7),0) -> 202601 | M7: =IF(L7=0,0,YEAR(B7)) -> 2026 | N7: =IF(L7=0,"",IF(K7=0,"Wants / Gustos",INDEX(Budget!$D$7:$D$41,K7))) -> Needs / Necesidades
B8: 46025 | C8: Netflix + Spotify | D8: Subscriptions / Suscripciones | E8: 28.98 | F8: Credit / Crédito | H8: =IF(OR(E8="",D8=""),"",IF(K8=0,"Expense / Gasto",INDEX(Budget!$C$7:$C$41,K8))) -> Expense / Gasto | I8: =IF(AND(B8="",E8=""),"",IF(NOT(ISNUMBER(B8)),"⚠ ADD DATE / AGREGA FECHA",IF(E8="","⚠ ADD AMOUNT / AGREGA MONTO",IF(D8="","⚠ ADD CATEGORY / AGREGA CATEGORÍA",IF(K8=0,"● NEW CATEGORY? / ¿CATEGORÍA NUEVA?","✔ OK"))))) -> ✔ OK | K8: =IF(D8="","",IFERROR(MATCH(D8,Budget!$B$7:$B$41,0),0)) -> 19 | L8: =IF(AND(ISNUMBER(B8),ISNUMBER(E8),D8<>""),YEAR(B8)*100+MONTH(B8),0) -> 202601 | M8: =IF(L8=0,0,YEAR(B8)) -> 2026 | N8: =IF(L8=0,"",IF(K8=0,"Wants / Gustos",INDEX(Budget!$D$7:$D$41,K8))) -> Wants / Gustos
B9: 46027 | C9: Paycheck / Cheque | D9: Partner salary / Salario de pareja | E9: 2200 | F9: Other / Otro | H9: =IF(OR(E9="",D9=""),"",IF(K9=0,"Expense / Gasto",INDEX(Budget!$C$7:$C$41,K9))) -> Income / Ingreso | I9: =IF(AND(B9="",E9=""),"",IF(NOT(ISNUMBER(B9)),"⚠ ADD DATE / AGREGA FECHA",IF(E9="","⚠ ADD AMOUNT / AGREGA MONTO",IF(D9="","⚠ ADD CATEGORY / AGREGA CATEGORÍA",IF(K9=0,"● NEW CATEGORY? / ¿CATEGORÍA NUEVA?","✔ OK"))))) -> ✔ OK | K9: =IF(D9="","",IFERROR(MATCH(D9,Budget!$B$7:$B$41,0),0)) -> 2 | L9: =IF(AND(ISNUMBER(B9),ISNUMBER(E9),D9<>""),YEAR(B9)*100+MONTH(B9),0) -> 202601 | M9: =IF(L9=0,0,YEAR(B9)) -> 2026 | N9: =IF(L9=0,"",IF(K9=0,"Wants / Gustos",INDEX(Budget!$D$7:$D$41,K9))) -> —
B10: 46028 | C10: Walmart | D10: Groceries / Supermercado | E10: 151.5 | F10: Debit / Débito | H10: =IF(OR(E10="",D10=""),"",IF(K10=0,"Expense / Gasto",INDEX(Budget!$C$7:$C$41,K10))) -> Expense / Gasto | I10: =IF(AND(B10="",E10=""),"",IF(NOT(ISNUMBER(B10)),"⚠ ADD DATE / AGREGA FECHA",IF(E10="","⚠ ADD AMOUNT / AGREGA MONTO",IF(D10="","⚠ ADD CATEGORY / AGREGA CATEGORÍA",IF(K10=0,"● NEW CATEGORY? / ¿CATEGORÍA NUEVA?","✔ OK"))))) -> ✔ OK | K10: =IF(D10="","",IFERROR(MATCH(D10,Budget!$B$7:$B$41,0),0)) -> 8 | L10: =IF(AND(ISNUMBER(B10),ISNUMBER(E10),D10<>""),YEAR(B10)*100+MONTH(B10),0) -> 202601 | M10: =IF(L10=0,0,YEAR(B10)) -> 2026 | N10: =IF(L10=0,"",IF(K10=0,"Wants / Gustos",INDEX(Budget!$D$7:$D$41,K10))) -> Needs / Necesidades
B11: 46030 | C11: Electric + water / Luz y agua | D11: Utilities / Servicios (luz, agua, gas) | E11: 227.55 | F11: Debit / Débito | H11: =IF(OR(E11="",D11=""),"",IF(K11=0,"Expense / Gasto",INDEX(Budget!$C$7:$C$41,K11))) -> Expense / Gasto | I11: =IF(AND(B11="",E11=""),"",IF(NOT(ISNUMBER(B11)),"⚠ ADD DATE / AGREGA FECHA",IF(E11="","⚠ ADD AMOUNT / AGREGA MONTO",IF(D11="","⚠ ADD CATEGORY / AGREGA CATEGORÍA",IF(K11=0,"● NEW CATEGORY? / ¿CATEGORÍA NUEVA?","✔ OK"))))) -> ✔ OK | K11: =IF(D11="","",IFERROR(MATCH(D11,Budget!$B$7:$B$41,0),0)) -> 7 | L11: =IF(AND(ISNUMBER(B11),ISNUMBER(E11),D11<>""),YEAR(B11)*100+MONTH(B11),0) -> 202601 | M11: =IF(L11=0,0,YEAR(B11)) -> 2026 | N11: =IF(L11=0,"",IF(K11=0,"Wants / Gustos",INDEX(Budget!$D$7:$D$41,K11))) -> Needs / Necesidades
B12: 46032 | C12: Shell | D12: Gas / Gasolina | E12: 109.46 | F12: Credit / Crédito | H12: =IF(OR(E12="",D12=""),"",IF(K12=0,"Expense / Gasto",INDEX(Budget!$C$7:$C$41,K12))) -> Expense / Gasto | I12: =IF(AND(B12="",E12=""),"",IF(NOT(ISNUMBER(B12)),"⚠ ADD DATE / AGREGA FECHA",IF(E12="","⚠ ADD AMOUNT / AGREGA MONTO",IF(D12="","⚠ ADD CATEGORY / AGREGA CATEGORÍA",IF(K12=0,"● NEW CATEGORY? / ¿CATEGORÍA NUEVA?","✔ OK"))))) -> ✔ OK | K12: =IF(D12="","",IFERROR(MATCH(D12,Budget!$B$7:$B$41,0),0)) -> 10 | L12: =IF(AND(ISNUMBER(B12),ISNUMBER(E12),D12<>""),YEAR(B12)*100+MONTH(B12),0) -> 202601 | M12: =IF(L12=0,0,YEAR(B12)) -> 2026 | N12: =IF(L12=0,"",IF(K12=0,"Wants / Gustos",INDEX(Budget!$D$7:$D$41,K12))) -> Needs / Necesidades
B13: 46034 | C13: Car insurance / Seguro | D13: Insurance / Seguros | E13: 260 | F13: Debit / Débito | H13: =IF(OR(E13="",D13=""),"",IF(K13=0,"Expense / Gasto",INDEX(Budget!$C$7:$C$41,K13))) -> Expense / Gasto | I13: =IF(AND(B13="",E13=""),"",IF(NOT(ISNUMBER(B13)),"⚠ ADD DATE / AGREGA FECHA",IF(E13="","⚠ ADD AMOUNT / AGREGA MONTO",IF(D13="","⚠ ADD CATEGORY / AGREGA CATEGORÍA",IF(K13=0,"● NEW CATEGORY? / ¿CATEGORÍA NUEVA?","✔ OK"))))) -> ✔ OK | K13: =IF(D13="","",IFERROR(MATCH(D13,Budget!$B$7:$B$41,0),0)) -> 11 | L13: =IF(AND(ISNUMBER(B13),ISNUMBER(E13),D13<>""),YEAR(B13)*100+MONTH(B13),0) -> 202601 | M13: =IF(L13=0,0,YEAR(B13)) -> 2026 | N13: =IF(L13=0,"",IF(K13=0,"Wants / Gustos",INDEX(Budget!$D$7:$D$41,K13))) -> Needs / Necesidades
B14: 46035 | C14: Costco | D14: Groceries / Supermercado | E14: 182 | F14: Credit / Crédito | H14: =IF(OR(E14="",D14=""),"",IF(K14=0,"Expense / Gasto",INDEX(Budget!$C$7:$C$41,K14))) -> Expense / Gasto | I14: =IF(AND(B14="",E14=""),"",IF(NOT(ISNUMBER(B14)),"⚠ ADD DATE / AGREGA FECHA",IF(E14="","⚠ ADD AMOUNT / AGREGA MONTO",IF(D14="","⚠ ADD CATEGORY / AGREGA CATEGORÍA",IF(K14=0,"● NEW CATEGORY? / ¿CATEGORÍA NUEVA?","✔ OK"))))) -> ✔ OK | K14: =IF(D14="","",IFERROR(MATCH(D14,Budget!$B$7:$B$41,0),0)) -> 8 | L14: =IF(AND(ISNUMBER(B14),ISNUMBER(E14),D14<>""),YEAR(B14)*100+MONTH(B14),0) -> 202601 | M14: =IF(L14=0,0,YEAR(B14)) -> 2026 | N14: =IF(L14=0,"",IF(K14=0,"Wants / Gustos",INDEX(Budget!$D$7:$D$41,K14))) -> Needs / Necesidades
B15: 46036 | C15: Restaurant / Restaurante | D15: Dining out / Comer fuera | E15: 259.51 | F15: Credit / Crédito | H15: =IF(OR(E15="",D15=""),"",IF(K15=0,"Expense / Gasto",INDEX(Budget!$C$7:$C$41,K15))) -> Expense / Gasto | I15: =IF(AND(B15="",E15=""),"",IF(NOT(ISNUMBER(B15)),"⚠ ADD DATE / AGREGA FECHA",IF(E15="","⚠ ADD AMOUNT / AGREGA MONTO",IF(D15="","⚠ ADD CATEGORY / AGREGA CATEGORÍA",IF(K15=0,"● NEW CATEGORY? / ¿CATEGORÍA NUEVA?","✔ OK"))))) -> ✔ OK | K15: =IF(D15="","",IFERROR(MATCH(D15,Budget!$B$7:$B$41,0),0)) -> 16 | L15: =IF(AND(ISNUMBER(B15),ISNUMBER(E15),D15<>""),YEAR(B15)*100+MONTH(B15),0) -> 202601 | M15: =IF(L15=0,0,YEAR(B15)) -> 2026 | N15: =IF(L15=0,"",IF(K15=0,"Wants / Gustos",INDEX(Budget!$D$7:$D$41,K15))) -> Wants / Gustos
B16: 46037 | C16: Paycheck / Cheque | D16: Salary / Salario | E16: 1700 | F16: Other / Otro | H16: =IF(OR(E16="",D16=""),"",IF(K16=0,"Expense / Gasto",INDEX(Budget!$C$7:$C$41,K16))) -> Income / Ingreso | I16: =IF(AND(B16="",E16=""),"",IF(NOT(ISNUMBER(B16)),"⚠ ADD DATE / AGREGA FECHA",IF(E16="","⚠ ADD AMOUNT / AGREGA MONTO",IF(D16="","⚠ ADD CATEGORY / AGREGA CATEGORÍA",IF(K16=0,"● NEW CATEGORY? / ¿CATEGORÍA NUEVA?","✔ OK"))))) -> ✔ OK | K16: =IF(D16="","",IFERROR(MATCH(D16,Budget!$B$7:$B$41,0),0)) -> 1 | L16: =IF(AND(ISNUMBER(B16),ISNUMBER(E16),D16<>""),YEAR(B16)*100+MONTH(B16),0) -> 202601 | M16: =IF(L16=0,0,YEAR(B16)) -> 2026 | N16: =IF(L16=0,"",IF(K16=0,"Wants / Gustos",INDEX(Budget!$D$7:$D$41,K16))) -> —
B17: 46038 | C17: Daycare / Guardería | D17: Childcare & School / Niños y Escuela | E17: 300 | F17: Debit / Débito | H17: =IF(OR(E17="",D17=""),"",IF(K17=0,"Expense / Gasto",INDEX(Budget!$C$7:$C$41,K17))) -> Expense / Gasto | I17: =IF(AND(B17="",E17=""),"",IF(NOT(ISNUMBER(B17)),"⚠ ADD DATE / AGREGA FECHA",IF(E17="","⚠ ADD AMOUNT / AGREGA MONTO",IF(D17="","⚠ ADD CATEGORY / AGREGA CATEGORÍA",IF(K17=0,"● NEW CATEGORY? / ¿CATEGORÍA NUEVA?","✔ OK"))))) -> ✔ OK | K17: =IF(D17="","",IFERROR(MATCH(D17,Budget!$B$7:$B$41,0),0)) -> 14 | L17: =IF(AND(ISNUMBER(B17),ISNUMBER(E17),D17<>""),YEAR(B17)*100+MONTH(B17),0) -> 202601 | M17: =IF(L17=0,0,YEAR(B17)) -> 2026 | N17: =IF(L17=0,"",IF(K17=0,"Wants / Gustos",INDEX(Budget!$D$7:$D$41,K17))) -> Needs / Necesidades
... B175: 46291 | C175: Savings transfer / Ahorro | D175: Emergency fund / Fondo de emergencia | E175: 200 | F175: Transfer / Transferencia | H175: =IF(OR(E175="",D175=""),"",IF(K175=0,"Expense / Gasto",INDEX(Budget!$C$7:$C$41,K175))) -> Expense / Gasto | I175: =IF(AND(B175="",E175=""),"",IF(NOT(ISNUMBER(B175)),"⚠ ADD DATE / AGREGA FECHA",IF(E175="","⚠ ADD AMOUNT / AGREGA MONTO",IF(D175="","⚠ ADD CATEGORY / AGREGA CATEGORÍA",IF(K175=0,"● NEW CATEGORY? / ¿CATEGORÍA NUEVA?","✔ OK"))))) -> ✔ OK | K175: =IF(D175="","",IFERROR(MATCH(D175,Budget!$B$7:$B$41,0),0)) -> 25 | L175: =IF(AND(ISNUMBER(B175),ISNUMBER(E175),D175<>""),YEAR(B175)*100+MONTH(B175),0) -> 202609 | M175: =IF(L175=0,0,YEAR(B175)) -> 2026 | N175: =IF(L175=0,"",IF(K175=0,"Wants / Gustos",INDEX(Budget!$D$7:$D$41,K175))) -> Savings & Debt / Ahorro y Deuda
H176: =IF(OR(E176="",D176=""),"",IF(K176=0,"Expense / Gasto",INDEX(Budget!$C$7:$C$41,K176))) | I176: =IF(AND(B176="",E176=""),"",IF(NOT(ISNUMBER(B176)),"⚠ ADD DATE / AGREGA FECHA",IF(E176="","⚠ ADD AMOUNT / AGREGA MONTO",IF(D176="","⚠ ADD CATEGORY / AGREGA CATEGORÍA",IF(K176=0,"● NEW CATEGORY? / ¿CATEGORÍA NUEVA?","✔ OK"))))) | K176: =IF(D176="","",IFERROR(MATCH(D176,Budget!$B$7:$B$41,0),0)) | L176: =IF(AND(ISNUMBER(B176),ISNUMBER(E176),D176<>""),YEAR(B176)*100+MONTH(B176),0) -> 0 | M176: =IF(L176=0,0,YEAR(B176)) -> 0 | N176: =IF(L176=0,"",IF(K176=0,"Wants / Gustos",INDEX(Budget!$D$7:$D$41,K176)))
H177: =IF(OR(E177="",D177=""),"",IF(K177=0,"Expense / Gasto",INDEX(Budget!$C$7:$C$41,K177))) | I177: =IF(AND(B177="",E177=""),"",IF(NOT(ISNUMBER(B177)),"⚠ ADD DATE / AGREGA FECHA",IF(E177="","⚠ ADD AMOUNT / AGREGA MONTO",IF(D177="","⚠ ADD CATEGORY / AGREGA CATEGORÍA",IF(K177=0,"● NEW CATEGORY? / ¿CATEGORÍA NUEVA?","✔ OK"))))) | K177: =IF(D177="","",IFERROR(MATCH(D177,Budget!$B$7:$B$41,0),0)) | L177: =IF(AND(ISNUMBER(B177),ISNUMBER(E177),D177<>""),YEAR(B177)*100+MONTH(B177),0) -> 0 | M177: =IF(L177=0,0,YEAR(B177)) -> 0 | N177: =IF(L177=0,"",IF(K177=0,"Wants / Gustos",INDEX(Budget!$D$7:$D$41,K177)))
H178: =IF(OR(E178="",D178=""),"",IF(K178=0,"Expense / Gasto",INDEX(Budget!$C$7:$C$41,K178))) | I178: =IF(AND(B178="",E178=""),"",IF(NOT(ISNUMBER(B178)),"⚠ ADD DATE / AGREGA FECHA",IF(E178="","⚠ ADD AMOUNT / AGREGA MONTO",IF(D178="","⚠ ADD CATEGORY / AGREGA CATEGORÍA",IF(K178=0,"● NEW CATEGORY? / ¿CATEGORÍA NUEVA?","✔ OK"))))) | K178: =IF(D178="","",IFERROR(MATCH(D178,Budget!$B$7:$B$41,0),0)) | L178: =IF(AND(ISNUMBER(B178),ISNUMBER(E178),D178<>""),YEAR(B178)*100+MONTH(B178),0) -> 0 | M178: =IF(L178=0,0,YEAR(B178)) -> 0 | N178: =IF(L178=0,"",IF(K178=0,"Wants / Gustos",INDEX(Budget!$D$7:$D$41,K178)))
H179: =IF(OR(E179="",D179=""),"",IF(K179=0,"Expense / Gasto",INDEX(Budget!$C$7:$C$41,K179))) | I179: =IF(AND(B179="",E179=""),"",IF(NOT(ISNUMBER(B179)),"⚠ ADD DATE / AGREGA FECHA",IF(E179="","⚠ ADD AMOUNT / AGREGA MONTO",IF(D179="","⚠ ADD CATEGORY / AGREGA CATEGORÍA",IF(K179=0,"● NEW CATEGORY? / ¿CATEGORÍA NUEVA?","✔ OK"))))) | K179: =IF(D179="","",IFERROR(MATCH(D179,Budget!$B$7:$B$41,0),0)) | L179: =IF(AND(ISNUMBER(B179),ISNUMBER(E179),D179<>""),YEAR(B179)*100+MONTH(B179),0) -> 0 | M179: =IF(L179=0,0,YEAR(B179)) -> 0 | N179: =IF(L179=0,"",IF(K179=0,"Wants / Gustos",INDEX(Budget!$D$7:$D$41,K179)))
H180: =IF(OR(E180="",D180=""),"",IF(K180=0,"Expense / Gasto",INDEX(Budget!$C$7:$C$41,K180))) | I180: =IF(AND(B180="",E180=""),"",IF(NOT(ISNUMBER(B180)),"⚠ ADD DATE / AGREGA FECHA",IF(E180="","⚠ ADD AMOUNT / AGREGA MONTO",IF(D180="","⚠ ADD CATEGORY / AGREGA CATEGORÍA",IF(K180=0,"● NEW CATEGORY? / ¿CATEGORÍA NUEVA?","✔ OK"))))) | K180: =IF(D180="","",IFERROR(MATCH(D180,Budget!$B$7:$B$41,0),0)) | L180: =IF(AND(ISNUMBER(B180),ISNUMBER(E180),D180<>""),YEAR(B180)*100+MONTH(B180),0) -> 0 | M180: =IF(L180=0,0,YEAR(B180)) -> 0 | N180: =IF(L180=0,"",IF(K180=0,"Wants / Gustos",INDEX(Budget!$D$7:$D$41,K180)))
H181: =IF(OR(E181="",D181=""),"",IF(K181=0,"Expense / Gasto",INDEX(Budget!$C$7:$C$41,K181))) | I181: =IF(AND(B181="",E181=""),"",IF(NOT(ISNUMBER(B181)),"⚠ ADD DATE / AGREGA FECHA",IF(E181="","⚠ ADD AMOUNT / AGREGA MONTO",IF(D181="","⚠ ADD CATEGORY / AGREGA CATEGORÍA",IF(K181=0,"● NEW CATEGORY? / ¿CATEGORÍA NUEVA?","✔ OK"))))) | K181: =IF(D181="","",IFERROR(MATCH(D181,Budget!$B$7:$B$41,0),0)) | L181: =IF(AND(ISNUMBER(B181),ISNUMBER(E181),D181<>""),YEAR(B181)*100+MONTH(B181),0) -> 0 | M181: =IF(L181=0,0,YEAR(B181)) -> 0 | N181: =IF(L181=0,"",IF(K181=0,"Wants / Gustos",INDEX(Budget!$D$7:$D$41,K181)))
H182: =IF(OR(E182="",D182=""),"",IF(K182=0,"Expense / Gasto",INDEX(Budget!$C$7:$C$41,K182))) | I182: =IF(AND(B182="",E182=""),"",IF(NOT(ISNUMBER(B182)),"⚠ ADD DATE / AGREGA FECHA",IF(E182="","⚠ ADD AMOUNT / AGREGA MONTO",IF(D182="","⚠ ADD CATEGORY / AGREGA CATEGORÍA",IF(K182=0,"● NEW CATEGORY? / ¿CATEGORÍA NUEVA?","✔ OK"))))) | K182: =IF(D182="","",IFERROR(MATCH(D182,Budget!$B$7:$B$41,0),0)) | L182: =IF(AND(ISNUMBER(B182),ISNUMBER(E182),D182<>""),YEAR(B182)*100+MONTH(B182),0) -> 0 | M182: =IF(L182=0,0,YEAR(B182)) -> 0 | N182: =IF(L182=0,"",IF(K182=0,"Wants / Gustos",INDEX(Budget!$D$7:$D$41,K182)))
H183: =IF(OR(E183="",D183=""),"",IF(K183=0,"Expense / Gasto",INDEX(Budget!$C$7:$C$41,K183))) | I183: =IF(AND(B183="",E183=""),"",IF(NOT(ISNUMBER(B183)),"⚠ ADD DATE / AGREGA FECHA",IF(E183="","⚠ ADD AMOUNT / AGREGA MONTO",IF(D183="","⚠ ADD CATEGORY / AGREGA CATEGORÍA",IF(K183=0,"● NEW CATEGORY? / ¿CATEGORÍA NUEVA?","✔ OK"))))) | K183: =IF(D183="","",IFERROR(MATCH(D183,Budget!$B$7:$B$41,0),0)) | L183: =IF(AND(ISNUMBER(B183),ISNUMBER(E183),D183<>""),YEAR(B183)*100+MONTH(B183),0) -> 0 | M183: =IF(L183=0,0,YEAR(B183)) -> 0 | N183: =IF(L183=0,"",IF(K183=0,"Wants / Gustos",INDEX(Budget!$D$7:$D$41,K183)))
H184: =IF(OR(E184="",D184=""),"",IF(K184=0,"Expense / Gasto",INDEX(Budget!$C$7:$C$41,K184))) | I184: =IF(AND(B184="",E184=""),"",IF(NOT(ISNUMBER(B184)),"⚠ ADD DATE / AGREGA FECHA",IF(E184="","⚠ ADD AMOUNT / AGREGA MONTO",IF(D184="","⚠ ADD CATEGORY / AGREGA CATEGORÍA",IF(K184=0,"● NEW CATEGORY? / ¿CATEGORÍA NUEVA?","✔ OK"))))) | K184: =IF(D184="","",IFERROR(MATCH(D184,Budget!$B$7:$B$41,0),0)) | L184: =IF(AND(ISNUMBER(B184),ISNUMBER(E184),D184<>""),YEAR(B184)*100+MONTH(B184),0) -> 0 | M184: =IF(L184=0,0,YEAR(B184)) -> 0 | N184: =IF(L184=0,"",IF(K184=0,"Wants / Gustos",INDEX(Budget!$D$7:$D$41,K184)))
H185: =IF(OR(E185="",D185=""),"",IF(K185=0,"Expense / Gasto",INDEX(Budget!$C$7:$C$41,K185))) | I185: =IF(AND(B185="",E185=""),"",IF(NOT(ISNUMBER(B185)),"⚠ ADD DATE / AGREGA FECHA",IF(E185="","⚠ ADD AMOUNT / AGREGA MONTO",IF(D185="","⚠ ADD CATEGORY / AGREGA CATEGORÍA",IF(K185=0,"● NEW CATEGORY? / ¿CATEGORÍA NUEVA?","✔ OK"))))) | K185: =IF(D185="","",IFERROR(MATCH(D185,Budget!$B$7:$B$41,0),0)) | L185: =IF(AND(ISNUMBER(B185),ISNUMBER(E185),D185<>""),YEAR(B185)*100+MONTH(B185),0) -> 0 | M185: =IF(L185=0,0,YEAR(B185)) -> 0 | N185: =IF(L185=0,"",IF(K185=0,"Wants / Gustos",INDEX(Budget!$D$7:$D$41,K185)))
H186: =IF(OR(E186="",D186=""),"",IF(K186=0,"Expense / Gasto",INDEX(Budget!$C$7:$C$41,K186))) | I186: =IF(AND(B186="",E186=""),"",IF(NOT(ISNUMBER(B186)),"⚠ ADD DATE / AGREGA FECHA",IF(E186="","⚠ ADD AMOUNT / AGREGA MONTO",IF(D186="","⚠ ADD CATEGORY / AGREGA CATEGORÍA",IF(K186=0,"● NEW CATEGORY? / ¿CATEGORÍA NUEVA?","✔ OK"))))) | K186: =IF(D186="","",IFERROR(MATCH(D186,Budget!$B$7:$B$41,0),0)) | L186: =IF(AND(ISNUMBER(B186),ISNUMBER(E186),D186<>""),YEAR(B186)*100+MONTH(B186),0) -> 0 | M186: =IF(L186=0,0,YEAR(B186)) -> 0 | N186: =IF(L186=0,"",IF(K186=0,"Wants / Gustos",INDEX(Budget!$D$7:$D$41,K186)))
H187: =IF(OR(E187="",D187=""),"",IF(K187=0,"Expense / Gasto",INDEX(Budget!$C$7:$C$41,K187))) | I187: =IF(AND(B187="",E187=""),"",IF(NOT(ISNUMBER(B187)),"⚠ ADD DATE / AGREGA FECHA",IF(E187="","⚠ ADD AMOUNT / AGREGA MONTO",IF(D187="","⚠ ADD CATEGORY / AGREGA CATEGORÍA",IF(K187=0,"● NEW CATEGORY? / ¿CATEGORÍA NUEVA?","✔ OK"))))) | K187: =IF(D187="","",IFERROR(MATCH(D187,Budget!$B$7:$B$41,0),0)) | L187: =IF(AND(ISNUMBER(B187),ISNUMBER(E187),D187<>""),YEAR(B187)*100+MONTH(B187),0) -> 0 | M187: =IF(L187=0,0,YEAR(B187)) -> 0 | N187: =IF(L187=0,"",IF(K187=0,"Wants / Gustos",INDEX(Budget!$D$7:$D$41,K187)))
... H1005: =IF(OR(E1005="",D1005=""),"",IF(K1005=0,"Expense / Gasto",INDEX(Budget!$C$7:$C$41,K1005))) | I1005: =IF(AND(B1005="",E1005=""),"",IF(NOT(ISNUMBER(B1005)),"⚠ ADD DATE / AGREGA FECHA",IF(E1005="","⚠ ADD AMOUNT / AGREGA MONTO",IF(D1005="","⚠ ADD CATEGORY / AGREGA CATEGORÍA",IF(K1005=0,"● NEW CATEGORY? / ¿CATEGORÍA NUEVA?","✔ OK"))))) | K1005: =IF(D1005="","",IFERROR(MATCH(D1005,Budget!$B$7:$B$41,0),0)) | L1005: =IF(AND(ISNUMBER(B1005),ISNUMBER(E1005),D1005<>""),YEAR(B1005)*100+MONTH(B1005),0) -> 0 | M1005: =IF(L1005=0,0,YEAR(B1005)) -> 0 | N1005: =IF(L1005=0,"",IF(K1005=0,"Wants / Gustos",INDEX(Budget!$D$7:$D$41,K1005)))

Sheet Budget
B1: ProfitTrack
B2: Monthly Budget / Presupuesto Mensual
B3: Plan how much you expect to earn and spend each month. Rename categories or add your own. • Planea cuánto esperas ganar y gastar cada mes. Renombra categorías o agrega las tuyas.
B6: Category Categoría | C6: Type Tipo | D6: Group (50/30/20) Grupo | E6: Monthly Budget Presupuesto Mensual | F6: Notes Notas
B7: Salary / Salario | C7: Income / Ingreso | D7: — | E7: 3400
B8: Partner salary / Salario de pareja | C8: Income / Ingreso | D8: — | E8: 2200
B9: Side income / Ingreso extra | C9: Income / Ingreso | D9: — | E9: 300
B10: Other income / Otros ingresos | C10: Income / Ingreso | D10: — | E10: 0
C11: Income / Ingreso | D11: —
B12: Rent / Mortgage – Renta / Hipoteca | C12: Expense / Gasto | D12: Needs / Necesidades | E12: 1650
B13: Utilities / Servicios (luz, agua, gas) | C13: Expense / Gasto | D13: Needs / Necesidades | E13: 220
B14: Groceries / Supermercado | C14: Expense / Gasto | D14: Needs / Necesidades | E14: 650
B15: Transportation / Transporte | C15: Expense / Gasto | D15: Needs / Necesidades | E15: 180
B16: Gas / Gasolina | C16: Expense / Gasto | D16: Needs / Necesidades | E16: 200
B17: Insurance / Seguros | C17: Expense / Gasto | D17: Needs / Necesidades | E17: 260
B18: Phone & Internet / Teléfono e Internet | C18: Expense / Gasto | D18: Needs / Necesidades | E18: 140
B19: Health / Salud | C19: Expense / Gasto | D19: Needs / Necesidades | E19: 120
B20: Childcare & School / Niños y Escuela | C20: Expense / Gasto | D20: Needs / Necesidades | E20: 300
B21: Family support / Apoyo a la familia (remesas) | C21: Expense / Gasto | D21: Needs / Necesidades | E21: 250
B22: Dining out / Comer fuera | C22: Expense / Gasto | D22: Wants / Gustos | E22: 220
B23: Entertainment / Entretenimiento | C23: Expense / Gasto | D23: Wants / Gustos | E23: 100
... B34: Other / Otro | C34: Expense / Gasto | D34: Wants / Gustos | E34: 50
C35: Expense / Gasto
C36: Expense / Gasto
C37: Expense / Gasto
C38: Expense / Gasto
C39: Expense / Gasto
C40: Expense / Gasto
C41: Expense / Gasto
B42: TOTAL PLANNED INCOME / INGRESO PLANEADO | E42: =SUM(E7:E11) -> 5900
B43: TOTAL PLANNED SPENDING / GASTO PLANEADO | E43: =SUM(E12:E41) -> 5850
B44: LEFT TO PLAN / POR ASIGNAR (aim for $0 / ideal $0) | E44: =E42-E43 -> 50
B46: Zero-based budget: give every dollar a job until 'Left to plan' is $0. / Presupuesto base cero: asigna cada dólar hasta que 'Por asignar' sea $0.

Sheet Savings Goals
B1: ProfitTrack
B2: Savings Goals / Metas de Ahorro
B3: Set a target and a date – see your progress and how much to save each month. • Pon una meta y una fecha – mira tu avance y cuánto ahorrar cada mes.
B5: Goal Meta | C5: Target $ Meta $ | D5: Saved So Far $ Ahorrado $ | E5: Target Date Fecha Meta | F5: Still Needed $ Falta $ | G5: Progress Avance | H5: Progress Bar Barra de Avance | I5: Months Left Meses | J5: Save per Month Ahorro Mensual | L5: Helper – do not edit: goal
B6: Emergency fund / Fondo de emergencia | C6: 3000 | D6: 1250 | E6: 46568 | F6: =IF(OR(B6="",C6=""),"",MAX(0,C6-IF(D6="",0,D6))) -> 1750 | G6: =IF(F6="","",IF(C6=0,0,MIN(1,IF(D6="",0,D6)/C6))) -> 0.41666667 | H6: =IF(G6="","",REPT("█",ROUND(G6*10,0))&REPT("░",10-ROUND(G6*10,0))) -> ████░░░░░░ | I6: =IF(OR(F6="",NOT(ISNUMBER(E6))),"",MAX(1,(YEAR(E6)-YEAR(TODAY()))*12+MONTH(E6)-MONTH(TODAY()))) -> 8 | J6: =IF(OR(F6="",I6=""),"",F6/I6) -> 218.75 | L6: =IF(F6="",0,1) -> 1
B7: Trip to Mexico / Viaje a México | C7: 1800 | D7: 600 | E7: 46447 | F7: =IF(OR(B7="",C7=""),"",MAX(0,C7-IF(D7="",0,D7))) -> 1200 | G7: =IF(F7="","",IF(C7=0,0,MIN(1,IF(D7="",0,D7)/C7))) -> 0.33333333 | H7: =IF(G7="","",REPT("█",ROUND(G7*10,0))&REPT("░",10-ROUND(G7*10,0))) -> ███░░░░░░░ | I7: =IF(OR(F7="",NOT(ISNUMBER(E7))),"",MAX(1,(YEAR(E7)-YEAR(TODAY()))*12+MONTH(E7)-MONTH(TODAY()))) -> 5 | J7: =IF(OR(F7="",I7=""),"",F7/I7) -> 240 | L7: =IF(F7="",0,1) -> 1
B8: Car down payment / Enganche del carro | C8: 5000 | D8: 900 | E8: 46753 | F8: =IF(OR(B8="",C8=""),"",MAX(0,C8-IF(D8="",0,D8))) -> 4100 | G8: =IF(F8="","",IF(C8=0,0,MIN(1,IF(D8="",0,D8)/C8))) -> 0.18 | H8: =IF(G8="","",REPT("█",ROUND(G8*10,0))&REPT("░",10-ROUND(G8*10,0))) -> ██░░░░░░░░ | I8: =IF(OR(F8="",NOT(ISNUMBER(E8))),"",MAX(1,(YEAR(E8)-YEAR(TODAY()))*12+MONTH(E8)-MONTH(TODAY()))) -> 15 | J8: =IF(OR(F8="",I8=""),"",F8/I8) -> 273.33333 | L8: =IF(F8="",0,1) -> 1
B9: Christmas gifts / Regalos de Navidad | C9: 600 | D9: 250 | E9: 46371 | F9: =IF(OR(B9="",C9=""),"",MAX(0,C9-IF(D9="",0,D9))) -> 350 | G9: =IF(F9="","",IF(C9=0,0,MIN(1,IF(D9="",0,D9)/C9))) -> 0.41666667 | H9: =IF(G9="","",REPT("█",ROUND(G9*10,0))&REPT("░",10-ROUND(G9*10,0))) -> ████░░░░░░ | I9: =IF(OR(F9="",NOT(ISNUMBER(E9))),"",MAX(1,(YEAR(E9)-YEAR(TODAY()))*12+MONTH(E9)-MONTH(TODAY()))) -> 2 | J9: =IF(OR(F9="",I9=""),"",F9/I9) -> 175 | L9: =IF(F9="",0,1) -> 1
F10: =IF(OR(B10="",C10=""),"",MAX(0,C10-IF(D10="",0,D10))) | G10: =IF(F10="","",IF(C10=0,0,MIN(1,IF(D10="",0,D10)/C10))) | H10: =IF(G10="","",REPT("█",ROUND(G10*10,0))&REPT("░",10-ROUND(G10*10,0))) | I10: =IF(OR(F10="",NOT(ISNUMBER(E10))),"",MAX(1,(YEAR(E10)-YEAR(TODAY()))*12+MONTH(E10)-MONTH(TODAY()))) | J10: =IF(OR(F10="",I10=""),"",F10/I10) | L10: =IF(F10="",0,1) -> 0
F11: =IF(OR(B11="",C11=""),"",MAX(0,C11-IF(D11="",0,D11))) | G11: =IF(F11="","",IF(C11=0,0,MIN(1,IF(D11="",0,D11)/C11))) | H11: =IF(G11="","",REPT("█",ROUND(G11*10,0))&REPT("░",10-ROUND(G11*10,0))) | I11: =IF(OR(F11="",NOT(ISNUMBER(E11))),"",MAX(1,(YEAR(E11)-YEAR(TODAY()))*12+MONTH(E11)-MONTH(TODAY()))) | J11: =IF(OR(F11="",I11=""),"",F11/I11) | L11: =IF(F11="",0,1) -> 0
F12: =IF(OR(B12="",C12=""),"",MAX(0,C12-IF(D12="",0,D12))) | G12: =IF(F12="","",IF(C12=0,0,MIN(1,IF(D12="",0,D12)/C12))) | H12: =IF(G12="","",REPT("█",ROUND(G12*10,0))&REPT("░",10-ROUND(G12*10,0))) | I12: =IF(OR(F12="",NOT(ISNUMBER(E12))),"",MAX(1,(YEAR(E12)-YEAR(TODAY()))*12+MONTH(E12)-MONTH(TODAY()))) | J12: =IF(OR(F12="",I12=""),"",F12/I12) | L12: =IF(F12="",0,1) -> 0
F13: =IF(OR(B13="",C13=""),"",MAX(0,C13-IF(D13="",0,D13))) | G13: =IF(F13="","",IF(C13=0,0,MIN(1,IF(D13="",0,D13)/C13))) | H13: =IF(G13="","",REPT("█",ROUND(G13*10,0))&REPT("░",10-ROUND(G13*10,0))) | I13: =IF(OR(F13="",NOT(ISNUMBER(E13))),"",MAX(1,(YEAR(E13)-YEAR(TODAY()))*12+MONTH(E13)-MONTH(TODAY()))) | J13: =IF(OR(F13="",I13=""),"",F13/I13) | L13: =IF(F13="",0,1) -> 0
F14: =IF(OR(B14="",C14=""),"",MAX(0,C14-IF(D14="",0,D14))) | G14: =IF(F14="","",IF(C14=0,0,MIN(1,IF(D14="",0,D14)/C14))) | H14: =IF(G14="","",REPT("█",ROUND(G14*10,0))&REPT("░",10-ROUND(G14*10,0))) | I14: =IF(OR(F14="",NOT(ISNUMBER(E14))),"",MAX(1,(YEAR(E14)-YEAR(TODAY()))*12+MONTH(E14)-MONTH(TODAY()))) | J14: =IF(OR(F14="",I14=""),"",F14/I14) | L14: =IF(F14="",0,1) -> 0
F15: =IF(OR(B15="",C15=""),"",MAX(0,C15-IF(D15="",0,D15))) | G15: =IF(F15="","",IF(C15=0,0,MIN(1,IF(D15="",0,D15)/C15))) | H15: =IF(G15="","",REPT("█",ROUND(G15*10,0))&REPT("░",10-ROUND(G15*10,0))) | I15: =IF(OR(F15="",NOT(ISNUMBER(E15))),"",MAX(1,(YEAR(E15)-YEAR(TODAY()))*12+MONTH(E15)-MONTH(TODAY()))) | J15: =IF(OR(F15="",I15=""),"",F15/I15) | L15: =IF(F15="",0,1) -> 0
F16: =IF(OR(B16="",C16=""),"",MAX(0,C16-IF(D16="",0,D16))) | G16: =IF(F16="","",IF(C16=0,0,MIN(1,IF(D16="",0,D16)/C16))) | H16: =IF(G16="","",REPT("█",ROUND(G16*10,0))&REPT("░",10-ROUND(G16*10,0))) | I16: =IF(OR(F16="",NOT(ISNUMBER(E16))),"",MAX(1,(YEAR(E16)-YEAR(TODAY()))*12+MONTH(E16)-MONTH(TODAY()))) | J16: =IF(OR(F16="",I16=""),"",F16/I16) | L16: =IF(F16="",0,1) -> 0
F17: =IF(OR(B17="",C17=""),"",MAX(0,C17-IF(D17="",0,D17))) | G17: =IF(F17="","",IF(C17=0,0,MIN(1,IF(D17="",0,D17)/C17))) | H17: =IF(G17="","",REPT("█",ROUND(G17*10,0))&REPT("░",10-ROUND(G17*10,0))) | I17: =IF(OR(F17="",NOT(ISNUMBER(E17))),"",MAX(1,(YEAR(E17)-YEAR(TODAY()))*12+MONTH(E17)-MONTH(TODAY()))) | J17: =IF(OR(F17="",I17=""),"",F17/I17) | L17: =IF(F17="",0,1) -> 0
F18: =IF(OR(B18="",C18=""),"",MAX(0,C18-IF(D18="",0,D18))) | G18: =IF(F18="","",IF(C18=0,0,MIN(1,IF(D18="",0,D18)/C18))) | H18: =IF(G18="","",REPT("█",ROUND(G18*10,0))&REPT("░",10-ROUND(G18*10,0))) | I18: =IF(OR(F18="",NOT(ISNUMBER(E18))),"",MAX(1,(YEAR(E18)-YEAR(TODAY()))*12+MONTH(E18)-MONTH(TODAY()))) | J18: =IF(OR(F18="",I18=""),"",F18/I18) | L18: =IF(F18="",0,1) -> 0
F19: =IF(OR(B19="",C19=""),"",MAX(0,C19-IF(D19="",0,D19))) | G19: =IF(F19="","",IF(C19=0,0,MIN(1,IF(D19="",0,D19)/C19))) | H19: =IF(G19="","",REPT("█",ROUND(G19*10,0))&REPT("░",10-ROUND(G19*10,0))) | I19: =IF(OR(F19="",NOT(ISNUMBER(E19))),"",MAX(1,(YEAR(E19)-YEAR(TODAY()))*12+MONTH(E19)-MONTH(TODAY()))) | J19: =IF(OR(F19="",I19=""),"",F19/I19) | L19: =IF(F19="",0,1) -> 0
F20: =IF(OR(B20="",C20=""),"",MAX(0,C20-IF(D20="",0,D20))) | G20: =IF(F20="","",IF(C20=0,0,MIN(1,IF(D20="",0,D20)/C20))) | H20: =IF(G20="","",REPT("█",ROUND(G20*10,0))&REPT("░",10-ROUND(G20*10,0))) | I20: =IF(OR(F20="",NOT(ISNUMBER(E20))),"",MAX(1,(YEAR(E20)-YEAR(TODAY()))*12+MONTH(E20)-MONTH(TODAY()))) | J20: =IF(OR(F20="",I20=""),"",F20/I20) | L20: =IF(F20="",0,1) -> 0
F21: =IF(OR(B21="",C21=""),"",MAX(0,C21-IF(D21="",0,D21))) | G21: =IF(F21="","",IF(C21=0,0,MIN(1,IF(D21="",0,D21)/C21))) | H21: =IF(G21="","",REPT("█",ROUND(G21*10,0))&REPT("░",10-ROUND(G21*10,0))) | I21: =IF(OR(F21="",NOT(ISNUMBER(E21))),"",MAX(1,(YEAR(E21)-YEAR(TODAY()))*12+MONTH(E21)-MONTH(TODAY()))) | J21: =IF(OR(F21="",I21=""),"",F21/I21) | L21: =IF(F21="",0,1) -> 0
... F25: =IF(OR(B25="",C25=""),"",MAX(0,C25-IF(D25="",0,D25))) | G25: =IF(F25="","",IF(C25=0,0,MIN(1,IF(D25="",0,D25)/C25))) | H25: =IF(G25="","",REPT("█",ROUND(G25*10,0))&REPT("░",10-ROUND(G25*10,0))) | I25: =IF(OR(F25="",NOT(ISNUMBER(E25))),"",MAX(1,(YEAR(E25)-YEAR(TODAY()))*12+MONTH(E25)-MONTH(TODAY()))) | J25: =IF(OR(F25="",I25=""),"",F25/I25) | L25: =IF(F25="",0,1) -> 0

Sheet Debts
B1: ProfitTrack
B2: Debt Payoff / Pago de Deudas
B3: See when each debt will be paid off and how much interest it costs. Extra payments make a big difference. • Mira cuándo terminas de pagar cada deuda y cuánto interés pagas. Los pagos extra hacen gran diferencia.
B5: Debt Deuda | C5: Balance $ Saldo $ | D5: APR % Interés Anual | E5: Minimum Payment Pago Mínimo | F5: Extra Payment Pago Extra | G5: Monthly Payment Pago Mensual | H5: Months to Pay Off Meses para Pagar | I5: Payoff Date Fecha de Pago | J5: Total Interest Interés Total | K5: Snowball Order Orden Bola de Nieve | L5: Avalanche Order Orden Avalancha | N5: Helper – do not edit: active | O5: Helper – do not edit: snowball key | P5: Helper – do not edit: avalanche key
B6: Credit card / Tarjeta de crédito | C6: 2400 | D6: 0.2499 | E6: 75 | F6: 50 | G6: =IF(OR(B6="",C6=""),"",IF(E6="",0,E6)+IF(F6="",0,F6)) -> 125 | H6: =IF(G6="","",IF(C6<=0,0,IF(G6<=C6*IF(D6="",0,D6)/12,"⚠ Payment too low / Pago muy bajo",ROUNDUP(NPER(IF(D6="",0,D6)/12,-G6,C6),0)))) -> 25 | I6: =IF(OR(H6="",NOT(ISNUMBER(H6))),"",EDATE(TODAY(),H6)) -> 47058 | J6: =IF(OR(H6="",NOT(ISNUMBER(H6))),"",IF(H6=0,0,MAX(0,G6*NPER(IF(D6="",0,D6)/12,-G6,C6)-C6))) -> 696.38011 | K6: =IF(N6=0,"",COUNTIF($O$6:$O$25,"<"&O6)+1) -> 2 | L6: =IF(N6=0,"",COUNTIF($P$6:$P$25,">"&P6)+1) -> 1 | N6: =IF(OR(B6="",C6="",C6<=0),0,1) -> 1 | O6: =IF(N6=1,C6+ROW()/1000000,"") -> 2400 | P6: =IF(N6=1,IF(D6="",0,D6)-ROW()/1000000,"") -> 0.249894
B7: Car loan / Préstamo del carro | C7: 9800 | D7: 0.075 | E7: 310 | F7: 0 | G7: =IF(OR(B7="",C7=""),"",IF(E7="",0,E7)+IF(F7="",0,F7)) -> 310 | H7: =IF(G7="","",IF(C7<=0,0,IF(G7<=C7*IF(D7="",0,D7)/12,"⚠ Payment too low / Pago muy bajo",ROUNDUP(NPER(IF(D7="",0,D7)/12,-G7,C7),0)))) -> 36 | I7: =IF(OR(H7="",NOT(ISNUMBER(H7))),"",EDATE(TODAY(),H7)) -> 47392 | J7: =IF(OR(H7="",NOT(ISNUMBER(H7))),"",IF(H7=0,0,MAX(0,G7*NPER(IF(D7="",0,D7)/12,-G7,C7)-C7))) -> 1152.2303 | K7: =IF(N7=0,"",COUNTIF($O$6:$O$25,"<"&O7)+1) -> 3 | L7: =IF(N7=0,"",COUNTIF($P$6:$P$25,">"&P7)+1) -> 2 | N7: =IF(OR(B7="",C7="",C7<=0),0,1) -> 1 | O7: =IF(N7=1,C7+ROW()/1000000,"") -> 9800 | P7: =IF(N7=1,IF(D7="",0,D7)-ROW()/1000000,"") -> 0.074993
B8: Medical bill / Cuenta médica | C8: 650 | D8: 0 | E8: 50 | F8: 0 | G8: =IF(OR(B8="",C8=""),"",IF(E8="",0,E8)+IF(F8="",0,F8)) -> 50 | H8: =IF(G8="","",IF(C8<=0,0,IF(G8<=C8*IF(D8="",0,D8)/12,"⚠ Payment too low / Pago muy bajo",ROUNDUP(NPER(IF(D8="",0,D8)/12,-G8,C8),0)))) -> 13 | I8: =IF(OR(H8="",NOT(ISNUMBER(H8))),"",EDATE(TODAY(),H8)) -> 46692 | J8: =IF(OR(H8="",NOT(ISNUMBER(H8))),"",IF(H8=0,0,MAX(0,G8*NPER(IF(D8="",0,D8)/12,-G8,C8)-C8))) -> 0 | K8: =IF(N8=0,"",COUNTIF($O$6:$O$25,"<"&O8)+1) -> 1 | L8: =IF(N8=0,"",COUNTIF($P$6:$P$25,">"&P8)+1) -> 4 | N8: =IF(OR(B8="",C8="",C8<=0),0,1) -> 1 | O8: =IF(N8=1,C8+ROW()/1000000,"") -> 650.00001 | P8: =IF(N8=1,IF(D8="",0,D8)-ROW()/1000000,"") -> -8e-06
B9: Student loan / Préstamo estudiantil | C9: 12000 | D9: 0.055 | E9: 140 | F9: 0 | G9: =IF(OR(B9="",C9=""),"",IF(E9="",0,E9)+IF(F9="",0,F9)) -> 140 | H9: =IF(G9="","",IF(C9<=0,0,IF(G9<=C9*IF(D9="",0,D9)/12,"⚠ Payment too low / Pago muy bajo",ROUNDUP(NPER(IF(D9="",0,D9)/12,-G9,C9),0)))) -> 110 | I9: =IF(OR(H9="",NOT(ISNUMBER(H9))),"",EDATE(TODAY(),H9)) -> 49644 | J9: =IF(OR(H9="",NOT(ISNUMBER(H9))),"",IF(H9=0,0,MAX(0,G9*NPER(IF(D9="",0,D9)/12,-G9,C9)-C9))) -> 3276.8147 | K9: =IF(N9=0,"",COUNTIF($O$6:$O$25,"<"&O9)+1) -> 4 | L9: =IF(N9=0,"",COUNTIF($P$6:$P$25,">"&P9)+1) -> 3 | N9: =IF(OR(B9="",C9="",C9<=0),0,1) -> 1 | O9: =IF(N9=1,C9+ROW()/1000000,"") -> 12000 | P9: =IF(N9=1,IF(D9="",0,D9)-ROW()/1000000,"") -> 0.054991
G10: =IF(OR(B10="",C10=""),"",IF(E10="",0,E10)+IF(F10="",0,F10)) | H10: =IF(G10="","",IF(C10<=0,0,IF(G10<=C10*IF(D10="",0,D10)/12,"⚠ Payment too low / Pago muy bajo",ROUNDUP(NPER(IF(D10="",0,D10)/12,-G10,C10),0)))) | I10: =IF(OR(H10="",NOT(ISNUMBER(H10))),"",EDATE(TODAY(),H10)) | J10: =IF(OR(H10="",NOT(ISNUMBER(H10))),"",IF(H10=0,0,MAX(0,G10*NPER(IF(D10="",0,D10)/12,-G10,C10)-C10))) | K10: =IF(N10=0,"",COUNTIF($O$6:$O$25,"<"&O10)+1) | L10: =IF(N10=0,"",COUNTIF($P$6:$P$25,">"&P10)+1) | N10: =IF(OR(B10="",C10="",C10<=0),0,1) -> 0 | O10: =IF(N10=1,C10+ROW()/1000000,"") | P10: =IF(N10=1,IF(D10="",0,D10)-ROW()/1000000,"")
G11: =IF(OR(B11="",C11=""),"",IF(E11="",0,E11)+IF(F11="",0,F11)) | H11: =IF(G11="","",IF(C11<=0,0,IF(G11<=C11*IF(D11="",0,D11)/12,"⚠ Payment too low / Pago muy bajo",ROUNDUP(NPER(IF(D11="",0,D11)/12,-G11,C11),0)))) | I11: =IF(OR(H11="",NOT(ISNUMBER(H11))),"",EDATE(TODAY(),H11)) | J11: =IF(OR(H11="",NOT(ISNUMBER(H11))),"",IF(H11=0,0,MAX(0,G11*NPER(IF(D11="",0,D11)/12,-G11,C11)-C11))) | K11: =IF(N11=0,"",COUNTIF($O$6:$O$25,"<"&O11)+1) | L11: =IF(N11=0,"",COUNTIF($P$6:$P$25,">"&P11)+1) | N11: =IF(OR(B11="",C11="",C11<=0),0,1) -> 0 | O11: =IF(N11=1,C11+ROW()/1000000,"") | P11: =IF(N11=1,IF(D11="",0,D11)-ROW()/1000000,"")
G12: =IF(OR(B12="",C12=""),"",IF(E12="",0,E12)+IF(F12="",0,F12)) | H12: =IF(G12="","",IF(C12<=0,0,IF(G12<=C12*IF(D12="",0,D12)/12,"⚠ Payment too low / Pago muy bajo",ROUNDUP(NPER(IF(D12="",0,D12)/12,-G12,C12),0)))) | I12: =IF(OR(H12="",NOT(ISNUMBER(H12))),"",EDATE(TODAY(),H12)) | J12: =IF(OR(H12="",NOT(ISNUMBER(H12))),"",IF(H12=0,0,MAX(0,G12*NPER(IF(D12="",0,D12)/12,-G12,C12)-C12))) | K12: =IF(N12=0,"",COUNTIF($O$6:$O$25,"<"&O12)+1) | L12: =IF(N12=0,"",COUNTIF($P$6:$P$25,">"&P12)+1) | N12: =IF(OR(B12="",C12="",C12<=0),0,1) -> 0 | O12: =IF(N12=1,C12+ROW()/1000000,"") | P12: =IF(N12=1,IF(D12="",0,D12)-ROW()/1000000,"")
G13: =IF(OR(B13="",C13=""),"",IF(E13="",0,E13)+IF(F13="",0,F13)) | H13: =IF(G13="","",IF(C13<=0,0,IF(G13<=C13*IF(D13="",0,D13)/12,"⚠ Payment too low / Pago muy bajo",ROUNDUP(NPER(IF(D13="",0,D13)/12,-G13,C13),0)))) | I13: =IF(OR(H13="",NOT(ISNUMBER(H13))),"",EDATE(TODAY(),H13)) | J13: =IF(OR(H13="",NOT(ISNUMBER(H13))),"",IF(H13=0,0,MAX(0,G13*NPER(IF(D13="",0,D13)/12,-G13,C13)-C13))) | K13: =IF(N13=0,"",COUNTIF($O$6:$O$25,"<"&O13)+1) | L13: =IF(N13=0,"",COUNTIF($P$6:$P$25,">"&P13)+1) | N13: =IF(OR(B13="",C13="",C13<=0),0,1) -> 0 | O13: =IF(N13=1,C13+ROW()/1000000,"") | P13: =IF(N13=1,IF(D13="",0,D13)-ROW()/1000000,"")
G14: =IF(OR(B14="",C14=""),"",IF(E14="",0,E14)+IF(F14="",0,F14)) | H14: =IF(G14="","",IF(C14<=0,0,IF(G14<=C14*IF(D14="",0,D14)/12,"⚠ Payment too low / Pago muy bajo",ROUNDUP(NPER(IF(D14="",0,D14)/12,-G14,C14),0)))) | I14: =IF(OR(H14="",NOT(ISNUMBER(H14))),"",EDATE(TODAY(),H14)) | J14: =IF(OR(H14="",NOT(ISNUMBER(H14))),"",IF(H14=0,0,MAX(0,G14*NPER(IF(D14="",0,D14)/12,-G14,C14)-C14))) | K14: =IF(N14=0,"",COUNTIF($O$6:$O$25,"<"&O14)+1) | L14: =IF(N14=0,"",COUNTIF($P$6:$P$25,">"&P14)+1) | N14: =IF(OR(B14="",C14="",C14<=0),0,1) -> 0 | O14: =IF(N14=1,C14+ROW()/1000000,"") | P14: =IF(N14=1,IF(D14="",0,D14)-ROW()/1000000,"")
G15: =IF(OR(B15="",C15=""),"",IF(E15="",0,E15)+IF(F15="",0,F15)) | H15: =IF(G15="","",IF(C15<=0,0,IF(G15<=C15*IF(D15="",0,D15)/12,"⚠ Payment too low / Pago muy bajo",ROUNDUP(NPER(IF(D15="",0,D15)/12,-G15,C15),0)))) | I15: =IF(OR(H15="",NOT(ISNUMBER(H15))),"",EDATE(TODAY(),H15)) | J15: =IF(OR(H15="",NOT(ISNUMBER(H15))),"",IF(H15=0,0,MAX(0,G15*NPER(IF(D15="",0,D15)/12,-G15,C15)-C15))) | K15: =IF(N15=0,"",COUNTIF($O$6:$O$25,"<"&O15)+1) | L15: =IF(N15=0,"",COUNTIF($P$6:$P$25,">"&P15)+1) | N15: =IF(OR(B15="",C15="",C15<=0),0,1) -> 0 | O15: =IF(N15=1,C15+ROW()/1000000,"") | P15: =IF(N15=1,IF(D15="",0,D15)-ROW()/1000000,"")
G16: =IF(OR(B16="",C16=""),"",IF(E16="",0,E16)+IF(F16="",0,F16)) | H16: =IF(G16="","",IF(C16<=0,0,IF(G16<=C16*IF(D16="",0,D16)/12,"⚠ Payment too low / Pago muy bajo",ROUNDUP(NPER(IF(D16="",0,D16)/12,-G16,C16),0)))) | I16: =IF(OR(H16="",NOT(ISNUMBER(H16))),"",EDATE(TODAY(),H16)) | J16: =IF(OR(H16="",NOT(ISNUMBER(H16))),"",IF(H16=0,0,MAX(0,G16*NPER(IF(D16="",0,D16)/12,-G16,C16)-C16))) | K16: =IF(N16=0,"",COUNTIF($O$6:$O$25,"<"&O16)+1) | L16: =IF(N16=0,"",COUNTIF($P$6:$P$25,">"&P16)+1) | N16: =IF(OR(B16="",C16="",C16<=0),0,1) -> 0 | O16: =IF(N16=1,C16+ROW()/1000000,"") | P16: =IF(N16=1,IF(D16="",0,D16)-ROW()/1000000,"")
G17: =IF(OR(B17="",C17=""),"",IF(E17="",0,E17)+IF(F17="",0,F17)) | H17: =IF(G17="","",IF(C17<=0,0,IF(G17<=C17*IF(D17="",0,D17)/12,"⚠ Payment too low / Pago muy bajo",ROUNDUP(NPER(IF(D17="",0,D17)/12,-G17,C17),0)))) | I17: =IF(OR(H17="",NOT(ISNUMBER(H17))),"",EDATE(TODAY(),H17)) | J17: =IF(OR(H17="",NOT(ISNUMBER(H17))),"",IF(H17=0,0,MAX(0,G17*NPER(IF(D17="",0,D17)/12,-G17,C17)-C17))) | K17: =IF(N17=0,"",COUNTIF($O$6:$O$25,"<"&O17)+1) | L17: =IF(N17=0,"",COUNTIF($P$6:$P$25,">"&P17)+1) | N17: =IF(OR(B17="",C17="",C17<=0),0,1) -> 0 | O17: =IF(N17=1,C17+ROW()/1000000,"") | P17: =IF(N17=1,IF(D17="",0,D17)-ROW()/1000000,"")
G18: =IF(OR(B18="",C18=""),"",IF(E18="",0,E18)+IF(F18="",0,F18)) | H18: =IF(G18="","",IF(C18<=0,0,IF(G18<=C18*IF(D18="",0,D18)/12,"⚠ Payment too low / Pago muy bajo",ROUNDUP(NPER(IF(D18="",0,D18)/12,-G18,C18),0)))) | I18: =IF(OR(H18="",NOT(ISNUMBER(H18))),"",EDATE(TODAY(),H18)) | J18: =IF(OR(H18="",NOT(ISNUMBER(H18))),"",IF(H18=0,0,MAX(0,G18*NPER(IF(D18="",0,D18)/12,-G18,C18)-C18))) | K18: =IF(N18=0,"",COUNTIF($O$6:$O$25,"<"&O18)+1) | L18: =IF(N18=0,"",COUNTIF($P$6:$P$25,">"&P18)+1) | N18: =IF(OR(B18="",C18="",C18<=0),0,1) -> 0 | O18: =IF(N18=1,C18+ROW()/1000000,"") | P18: =IF(N18=1,IF(D18="",0,D18)-ROW()/1000000,"")
G19: =IF(OR(B19="",C19=""),"",IF(E19="",0,E19)+IF(F19="",0,F19)) | H19: =IF(G19="","",IF(C19<=0,0,IF(G19<=C19*IF(D19="",0,D19)/12,"⚠ Payment too low / Pago muy bajo",ROUNDUP(NPER(IF(D19="",0,D19)/12,-G19,C19),0)))) | I19: =IF(OR(H19="",NOT(ISNUMBER(H19))),"",EDATE(TODAY(),H19)) | J19: =IF(OR(H19="",NOT(ISNUMBER(H19))),"",IF(H19=0,0,MAX(0,G19*NPER(IF(D19="",0,D19)/12,-G19,C19)-C19))) | K19: =IF(N19=0,"",COUNTIF($O$6:$O$25,"<"&O19)+1) | L19: =IF(N19=0,"",COUNTIF($P$6:$P$25,">"&P19)+1) | N19: =IF(OR(B19="",C19="",C19<=0),0,1) -> 0 | O19: =IF(N19=1,C19+ROW()/1000000,"") | P19: =IF(N19=1,IF(D19="",0,D19)-ROW()/1000000,"")
G20: =IF(OR(B20="",C20=""),"",IF(E20="",0,E20)+IF(F20="",0,F20)) | H20: =IF(G20="","",IF(C20<=0,0,IF(G20<=C20*IF(D20="",0,D20)/12,"⚠ Payment too low / Pago muy bajo",ROUNDUP(NPER(IF(D20="",0,D20)/12,-G20,C20),0)))) | I20: =IF(OR(H20="",NOT(ISNUMBER(H20))),"",EDATE(TODAY(),H20)) | J20: =IF(OR(H20="",NOT(ISNUMBER(H20))),"",IF(H20=0,0,MAX(0,G20*NPER(IF(D20="",0,D20)/12,-G20,C20)-C20))) | K20: =IF(N20=0,"",COUNTIF($O$6:$O$25,"<"&O20)+1) | L20: =IF(N20=0,"",COUNTIF($P$6:$P$25,">"&P20)+1) | N20: =IF(OR(B20="",C20="",C20<=0),0,1) -> 0 | O20: =IF(N20=1,C20+ROW()/1000000,"") | P20: =IF(N20=1,IF(D20="",0,D20)-ROW()/1000000,"")
G21: =IF(OR(B21="",C21=""),"",IF(E21="",0,E21)+IF(F21="",0,F21)) | H21: =IF(G21="","",IF(C21<=0,0,IF(G21<=C21*IF(D21="",0,D21)/12,"⚠ Payment too low / Pago muy bajo",ROUNDUP(NPER(IF(D21="",0,D21)/12,-G21,C21),0)))) | I21: =IF(OR(H21="",NOT(ISNUMBER(H21))),"",EDATE(TODAY(),H21)) | J21: =IF(OR(H21="",NOT(ISNUMBER(H21))),"",IF(H21=0,0,MAX(0,G21*NPER(IF(D21="",0,D21)/12,-G21,C21)-C21))) | K21: =IF(N21=0,"",COUNTIF($O$6:$O$25,"<"&O21)+1) | L21: =IF(N21=0,"",COUNTIF($P$6:$P$25,">"&P21)+1) | N21: =IF(OR(B21="",C21="",C21<=0),0,1) -> 0 | O21: =IF(N21=1,C21+ROW()/1000000,"") | P21: =IF(N21=1,IF(D21="",0,D21)-ROW()/1000000,"")
... G25: =IF(OR(B25="",C25=""),"",IF(E25="",0,E25)+IF(F25="",0,F25)) | H25: =IF(G25="","",IF(C25<=0,0,IF(G25<=C25*IF(D25="",0,D25)/12,"⚠ Payment too low / Pago muy bajo",ROUNDUP(NPER(IF(D25="",0,D25)/12,-G25,C25),0)))) | I25: =IF(OR(H25="",NOT(ISNUMBER(H25))),"",EDATE(TODAY(),H25)) | J25: =IF(OR(H25="",NOT(ISNUMBER(H25))),"",IF(H25=0,0,MAX(0,G25*NPER(IF(D25="",0,D25)/12,-G25,C25)-C25))) | K25: =IF(N25=0,"",COUNTIF($O$6:$O$25,"<"&O25)+1) | L25: =IF(N25=0,"",COUNTIF($P$6:$P$25,">"&P25)+1) | N25: =IF(OR(B25="",C25="",C25<=0),0,1) -> 0 | O25: =IF(N25=1,C25+ROW()/1000000,"") | P25: =IF(N25=1,IF(D25="",0,D25)-ROW()/1000000,"")
B27: TOTAL DEBT / DEUDA TOTAL | G27: =SUM(C6:C25) -> 24850
B28: TOTAL MONTHLY PAYMENTS / PAGOS MENSUALES | G28: =SUM(G6:G25) -> 625
B29: TOTAL INTEREST (estimate) / INTERÉS TOTAL | G29: =SUM(J6:J25) -> 5125.4251

Sheet Quick Start Guide
B1: ProfitTrack
B2: Quick Start Guide / Guía Rápida
B3: Up and running in 5 minutes. • Listo en 5 minutos.
B6: # | C6: ENGLISH | D6: ESPAÑOL
B7: 1 | C7: Clear the example data: on Transactions select B6:G175 and press Delete. Replace the example goals and debts with yours. | D7: Borra los datos de ejemplo: en Transactions selecciona B6:G175 y presiona Suprimir. Reemplaza las metas y deudas de ejemplo con las tuyas.
B8: 2 | C8: Budget: enter your monthly income, then give every dollar a job across the categories until 'Left to plan' is $0. Rename categories or add your own in the empty yellow rows. | D8: Budget (Presupuesto): escribe tu ingreso mensual y asigna cada dólar a las categorías hasta que 'Por asignar' sea $0. Renombra categorías o agrega las tuyas en las filas amarillas vacías.
B9: 3 | C9: Each category belongs to a group: Needs, Wants or Savings & Debt. This powers the 50/30/20 check on the Dashboard. | D9: Cada categoría pertenece a un grupo: Necesidades, Gustos o Ahorro y Deuda. Esto alimenta la regla 50/30/20 del Panel.
B10: 4 | C10: Transactions: log every paycheck and every expense – date, description, category (dropdown) and amount (always positive). The type fills in automatically. | D10: Transactions (Movimientos): registra cada cheque y cada gasto – fecha, descripción, categoría (lista) y monto (siempre positivo). El tipo se llena solo.
B11: 5 | C11: The Check column flags a missing date, amount or category, and categories that aren't in your Budget yet. | D11: La columna Revisar marca si falta fecha, monto o categoría, y categorías que todavía no están en tu Presupuesto.
B12: 6 | C12: Dashboard: pick a month and year (yellow cells). See income, spending, money left over, budget vs. actual for every category, the 50/30/20 check and your whole year. | D12: Dashboard (Panel): elige mes y año (celdas amarillas). Mira ingresos, gastos, sobrante, presupuesto vs. real por categoría, la regla 50/30/20 y todo tu año.
B13: 7 | C13: Savings Goals: add a goal, target amount, what you've saved and a target date – get a progress bar and how much to save each month. | D13: Savings Goals (Metas): agrega una meta, el monto, lo que llevas ahorrado y una fecha – verás una barra de avance y cuánto ahorrar cada mes.
B14: 8 | C14: Debts: enter balance, APR and payments – see months to pay off, payoff date and total interest, plus Snowball and Avalanche payoff order. | D14: Debts (Deudas): escribe saldo, interés anual y pagos – verás meses para pagar, fecha de pago e interés total, más el orden Bola de Nieve y Avalancha.
B15: 9 | C15: Weekly habit: 10 minutes every Sunday to log receipts and check the Dashboard. Small habits, big results! | D15: Hábito semanal: 10 minutos cada domingo para registrar recibos y revisar el Panel. ¡Pequeños hábitos, grandes resultados!
