Workbook

Sheet Cover
B4: RESELLER TOOLKIT • KIT PARA REVENDEDORES
B6: ProfitTrack
B9: Reseller Inventory Tracker
B10: Control de Inventario para Revendedores
B11: eBay • Facebook Marketplace • Etsy • Poshmark • Mercari • Depop
B15: WHAT'S INSIDE / CONTENIDO (click to open • clic para abrir)
C17: 📊 Dashboard / Panel
C18: Stock value, stale items, sell-through, oldest items / Valor del inventario, artículos estancados, tasa de venta
C20: 📦 Inventory / Inventario
C21: Every item from purchase to sale – days held & alerts automatic / Cada artículo de la compra a la venta – días y alertas automáticos
C23: ⚙️ Settings / Configuración
C24: Stale-item alert days & your categories / Días de alerta y tus categorías
C26: 🚀 Quick Start Guide / Guía Rápida
C27: Step-by-step setup in 5 minutes / Configuración paso a paso en 5 minutos
B30: 💻 PC / Mac • 📱 iPhone / Android — Excel • Google Sheets | Computadora y celular — Excel • Google Sheets
B32: Start here → Quick Start Guide | Empieza aquí → Guía Rápida
B35: © ProfitTrack • v1.0 • For personal use only – do not resell or redistribute / Solo para uso personal – prohibida su reventa o distribución

Sheet Dashboard
B1: ProfitTrack
B2: Dashboard / Panel de Control
B3: What you own, what it's worth and what's not moving. Updates automatically. • Qué tienes, cuánto vale y qué no se vende. Se actualiza solo.
B6: ITEMS IN STOCK | C6: INVENTORY VALUE (COST) | E6: POTENTIAL REVENUE | H6: STALE ITEMS
B7: Artículos en Inventario | C7: Valor del Inventario (Costo) | E7: Ingresos Potenciales | H7: Artículos Estancados
B8: =SUM(Inventory!$S$6:$S$1005) -> 15 | C8: =ROUND(SUMIFS(Inventory!$G$6:$G$1005,Inventory!$S$6:$S$1005,1),2) -> 283 | E8: =ROUND(SUMIFS(Inventory!$I$6:$I$1005,Inventory!$S$6:$S$1005,1),2) -> 1107 | H8: =SUM(Inventory!$Z$6:$Z$1005) -> 6
B9: =SUM(Inventory!$AA$6:$AA$1005) -> 4 | C9: =IF(B8=0,0,C8/B8) -> 18.866667 | E9: =SUM(Inventory!$AC$6:$AC$1005) -> 844 | H9: =SUMIFS(Inventory!$G$6:$G$1005,Inventory!$Z$6:$Z$1005,1) -> 115
B11: ITEMS SOLD | C11: AVG. DAYS TO SELL | E11: SELL-THROUGH RATE | H11: GROSS PROFIT (SOLD)
B12: Artículos Vendidos | C12: Días Promedio para Vender | E12: Tasa de Venta | H12: Ganancia Bruta (Vendidos)
B13: =SUM(Inventory!$T$6:$T$1005) -> 6 | C13: =IF(SUM(Inventory!$Y$6:$Y$1005)=0,0,SUM(Inventory!$X$6:$X$1005)/SUM(Inventory!$Y$6:$Y$1005)) -> 14.666667 | E13: =IF(B8+B13=0,0,B13/(B8+B13)) -> 0.28571429 | H13: =SUM(Inventory!$AB$6:$AB$1005) -> 424.99
B14: =SUMIFS(Inventory!$L$6:$L$1005,Inventory!$T$6:$T$1005,1) -> 568.99 | C14: purchase → sale / compra → venta | E14: sold ÷ (sold + in stock) / vendidos ÷ total | H14: =IF(SUMIFS(Inventory!$G$6:$G$1005,Inventory!$T$6:$T$1005,1)=0,0,H13/SUMIFS(Inventory!$G$6:$G$1005,Inventory!$T$6:$T$1005,1)) -> 2.9513194
B17: Inventory by Category / Inventario por Categoría
B18: Category Categoría | C18: In Stock En Inventario | D18: Value at Cost Valor al Costo | E18: Potential Revenue Ingreso Potencial | F18: Sold Vendidos
B19: =IF(Settings!$F$8="","",Settings!$F$8) -> Clothing / Ropa | C19: =IF($B19="",0,COUNTIFS(Inventory!$S$6:$S$1005,1,Inventory!$D$6:$D$1005,$B19)) -> 4 | D19: =IF($B19="",0,ROUND(SUMIFS(Inventory!$G$6:$G$1005,Inventory!$S$6:$S$1005,1,Inventory!$D$6:$D$1005,$B19),2)) -> 41 | E19: =IF($B19="",0,ROUND(SUMIFS(Inventory!$I$6:$I$1005,Inventory!$S$6:$S$1005,1,Inventory!$D$6:$D$1005,$B19),2)) -> 257 | F19: =IF($B19="",0,COUNTIFS(Inventory!$T$6:$T$1005,1,Inventory!$D$6:$D$1005,$B19)) -> 1
B20: =IF(Settings!$F$9="","",Settings!$F$9) -> Shoes / Zapatos | C20: =IF($B20="",0,COUNTIFS(Inventory!$S$6:$S$1005,1,Inventory!$D$6:$D$1005,$B20)) -> 1 | D20: =IF($B20="",0,ROUND(SUMIFS(Inventory!$G$6:$G$1005,Inventory!$S$6:$S$1005,1,Inventory!$D$6:$D$1005,$B20),2)) -> 18 | E20: =IF($B20="",0,ROUND(SUMIFS(Inventory!$I$6:$I$1005,Inventory!$S$6:$S$1005,1,Inventory!$D$6:$D$1005,$B20),2)) -> 85 | F20: =IF($B20="",0,COUNTIFS(Inventory!$T$6:$T$1005,1,Inventory!$D$6:$D$1005,$B20)) -> 1
B21: =IF(Settings!$F$10="","",Settings!$F$10) -> Bags & Accessories / Bolsos y Accesorios | C21: =IF($B21="",0,COUNTIFS(Inventory!$S$6:$S$1005,1,Inventory!$D$6:$D$1005,$B21)) -> 1 | D21: =IF($B21="",0,ROUND(SUMIFS(Inventory!$G$6:$G$1005,Inventory!$S$6:$S$1005,1,Inventory!$D$6:$D$1005,$B21),2)) -> 20 | E21: =IF($B21="",0,ROUND(SUMIFS(Inventory!$I$6:$I$1005,Inventory!$S$6:$S$1005,1,Inventory!$D$6:$D$1005,$B21),2)) -> 120 | F21: =IF($B21="",0,COUNTIFS(Inventory!$T$6:$T$1005,1,Inventory!$D$6:$D$1005,$B21)) -> 0
B22: =IF(Settings!$F$11="","",Settings!$F$11) -> Jewelry & Watches / Joyería y Relojes | C22: =IF($B22="",0,COUNTIFS(Inventory!$S$6:$S$1005,1,Inventory!$D$6:$D$1005,$B22)) -> 2 | D22: =IF($B22="",0,ROUND(SUMIFS(Inventory!$G$6:$G$1005,Inventory!$S$6:$S$1005,1,Inventory!$D$6:$D$1005,$B22),2)) -> 23 | E22: =IF($B22="",0,ROUND(SUMIFS(Inventory!$I$6:$I$1005,Inventory!$S$6:$S$1005,1,Inventory!$D$6:$D$1005,$B22),2)) -> 115 | F22: =IF($B22="",0,COUNTIFS(Inventory!$T$6:$T$1005,1,Inventory!$D$6:$D$1005,$B22)) -> 0
B23: =IF(Settings!$F$12="","",Settings!$F$12) -> Home & Kitchen / Hogar y Cocina | C23: =IF($B23="",0,COUNTIFS(Inventory!$S$6:$S$1005,1,Inventory!$D$6:$D$1005,$B23)) -> 3 | D23: =IF($B23="",0,ROUND(SUMIFS(Inventory!$G$6:$G$1005,Inventory!$S$6:$S$1005,1,Inventory!$D$6:$D$1005,$B23),2)) -> 82 | E23: =IF($B23="",0,ROUND(SUMIFS(Inventory!$I$6:$I$1005,Inventory!$S$6:$S$1005,1,Inventory!$D$6:$D$1005,$B23),2)) -> 265 | F23: =IF($B23="",0,COUNTIFS(Inventory!$T$6:$T$1005,1,Inventory!$D$6:$D$1005,$B23)) -> 1
B24: =IF(Settings!$F$13="","",Settings!$F$13) -> Electronics / Electrónicos | C24: =IF($B24="",0,COUNTIFS(Inventory!$S$6:$S$1005,1,Inventory!$D$6:$D$1005,$B24)) -> 1 | D24: =IF($B24="",0,ROUND(SUMIFS(Inventory!$G$6:$G$1005,Inventory!$S$6:$S$1005,1,Inventory!$D$6:$D$1005,$B24),2)) -> 20 | E24: =IF($B24="",0,ROUND(SUMIFS(Inventory!$I$6:$I$1005,Inventory!$S$6:$S$1005,1,Inventory!$D$6:$D$1005,$B24),2)) -> 0 | F24: =IF($B24="",0,COUNTIFS(Inventory!$T$6:$T$1005,1,Inventory!$D$6:$D$1005,$B24)) -> 2
B25: =IF(Settings!$F$14="","",Settings!$F$14) -> Toys & Collectibles / Juguetes y Coleccionables | C25: =IF($B25="",0,COUNTIFS(Inventory!$S$6:$S$1005,1,Inventory!$D$6:$D$1005,$B25)) -> 1 | D25: =IF($B25="",0,ROUND(SUMIFS(Inventory!$G$6:$G$1005,Inventory!$S$6:$S$1005,1,Inventory!$D$6:$D$1005,$B25),2)) -> 60 | E25: =IF($B25="",0,ROUND(SUMIFS(Inventory!$I$6:$I$1005,Inventory!$S$6:$S$1005,1,Inventory!$D$6:$D$1005,$B25),2)) -> 150 | F25: =IF($B25="",0,COUNTIFS(Inventory!$T$6:$T$1005,1,Inventory!$D$6:$D$1005,$B25)) -> 0
B26: =IF(Settings!$F$15="","",Settings!$F$15) -> Books & Media / Libros y Medios | C26: =IF($B26="",0,COUNTIFS(Inventory!$S$6:$S$1005,1,Inventory!$D$6:$D$1005,$B26)) -> 1 | D26: =IF($B26="",0,ROUND(SUMIFS(Inventory!$G$6:$G$1005,Inventory!$S$6:$S$1005,1,Inventory!$D$6:$D$1005,$B26),2)) -> 12 | E26: =IF($B26="",0,ROUND(SUMIFS(Inventory!$I$6:$I$1005,Inventory!$S$6:$S$1005,1,Inventory!$D$6:$D$1005,$B26),2)) -> 60 | F26: =IF($B26="",0,COUNTIFS(Inventory!$T$6:$T$1005,1,Inventory!$D$6:$D$1005,$B26)) -> 0
B27: =IF(Settings!$F$16="","",Settings!$F$16) -> Vintage & Antiques / Vintage y Antigüedades | C27: =IF($B27="",0,COUNTIFS(Inventory!$S$6:$S$1005,1,Inventory!$D$6:$D$1005,$B27)) -> 1 | D27: =IF($B27="",0,ROUND(SUMIFS(Inventory!$G$6:$G$1005,Inventory!$S$6:$S$1005,1,Inventory!$D$6:$D$1005,$B27),2)) -> 7 | E27: =IF($B27="",0,ROUND(SUMIFS(Inventory!$I$6:$I$1005,Inventory!$S$6:$S$1005,1,Inventory!$D$6:$D$1005,$B27),2)) -> 55 | F27: =IF($B27="",0,COUNTIFS(Inventory!$T$6:$T$1005,1,Inventory!$D$6:$D$1005,$B27)) -> 1
B28: =IF(Settings!$F$17="","",Settings!$F$17) -> Other / Otro | C28: =IF($B28="",0,COUNTIFS(Inventory!$S$6:$S$1005,1,Inventory!$D$6:$D$1005,$B28)) -> 0 | D28: =IF($B28="",0,ROUND(SUMIFS(Inventory!$G$6:$G$1005,Inventory!$S$6:$S$1005,1,Inventory!$D$6:$D$1005,$B28),2)) -> 0 | E28: =IF($B28="",0,ROUND(SUMIFS(Inventory!$I$6:$I$1005,Inventory!$S$6:$S$1005,1,Inventory!$D$6:$D$1005,$B28),2)) -> 0 | F28: =IF($B28="",0,COUNTIFS(Inventory!$T$6:$T$1005,1,Inventory!$D$6:$D$1005,$B28)) -> 0
B29: =IF(Settings!$F$18="","",Settings!$F$18) | C29: =IF($B29="",0,COUNTIFS(Inventory!$S$6:$S$1005,1,Inventory!$D$6:$D$1005,$B29)) -> 0 | D29: =IF($B29="",0,ROUND(SUMIFS(Inventory!$G$6:$G$1005,Inventory!$S$6:$S$1005,1,Inventory!$D$6:$D$1005,$B29),2)) -> 0 | E29: =IF($B29="",0,ROUND(SUMIFS(Inventory!$I$6:$I$1005,Inventory!$S$6:$S$1005,1,Inventory!$D$6:$D$1005,$B29),2)) -> 0 | F29: =IF($B29="",0,COUNTIFS(Inventory!$T$6:$T$1005,1,Inventory!$D$6:$D$1005,$B29)) -> 0
B30: =IF(Settings!$F$19="","",Settings!$F$19) | C30: =IF($B30="",0,COUNTIFS(Inventory!$S$6:$S$1005,1,Inventory!$D$6:$D$1005,$B30)) -> 0 | D30: =IF($B30="",0,ROUND(SUMIFS(Inventory!$G$6:$G$1005,Inventory!$S$6:$S$1005,1,Inventory!$D$6:$D$1005,$B30),2)) -> 0 | E30: =IF($B30="",0,ROUND(SUMIFS(Inventory!$I$6:$I$1005,Inventory!$S$6:$S$1005,1,Inventory!$D$6:$D$1005,$B30),2)) -> 0 | F30: =IF($B30="",0,COUNTIFS(Inventory!$T$6:$T$1005,1,Inventory!$D$6:$D$1005,$B30)) -> 0
B31: Uncategorized / Sin categoría | C31: =C32-SUM(C19:C30) -> 0 | D31: =ROUND(D32-SUM(D19:D30),2) -> 0 | E31: =ROUND(E32-SUM(E19:E30),2) -> 0 | F31: =F32-SUM(F19:F30) -> 0
B32: TOTAL | C32: =B8 -> 15 | D32: =C8 -> 283 | E32: =E8 -> 1107 | F32: =B13 -> 6
B35: Unsold Items by Age / Artículos sin Vender por Antigüedad
B36: Age Antigüedad | C36: Items Artículos | D36: Value at Cost Valor al Costo | E36: Potential Revenue Ingreso Potencial | F36: % of Items % de Artículos
B37: 0–30 days / días | C37: =COUNTIF(Inventory!$V$6:$V$1005,1) -> 4 | D37: =ROUND(SUMIFS(Inventory!$G$6:$G$1005,Inventory!$V$6:$V$1005,1),2) -> 110 | E37: =ROUND(SUMIFS(Inventory!$I$6:$I$1005,Inventory!$V$6:$V$1005,1),2) -> 360 | F37: =IF($C$42=0,0,C37/$C$42) -> 0.26666667
B38: 31–60 days / días | C38: =COUNTIF(Inventory!$V$6:$V$1005,2) -> 2 | D38: =ROUND(SUMIFS(Inventory!$G$6:$G$1005,Inventory!$V$6:$V$1005,2),2) -> 22 | E38: =ROUND(SUMIFS(Inventory!$I$6:$I$1005,Inventory!$V$6:$V$1005,2),2) -> 106 | F38: =IF($C$42=0,0,C38/$C$42) -> 0.13333333
B39: 61–90 days / días | C39: =COUNTIF(Inventory!$V$6:$V$1005,3) -> 3 | D39: =ROUND(SUMIFS(Inventory!$G$6:$G$1005,Inventory!$V$6:$V$1005,3),2) -> 36 | E39: =ROUND(SUMIFS(Inventory!$I$6:$I$1005,Inventory!$V$6:$V$1005,3),2) -> 170 | F39: =IF($C$42=0,0,C39/$C$42) -> 0.2
B40: 90+ days / días | C40: =COUNTIF(Inventory!$V$6:$V$1005,4) -> 6 | D40: =ROUND(SUMIFS(Inventory!$G$6:$G$1005,Inventory!$V$6:$V$1005,4),2) -> 115 | E40: =ROUND(SUMIFS(Inventory!$I$6:$I$1005,Inventory!$V$6:$V$1005,4),2) -> 471 | F40: =IF($C$42=0,0,C40/$C$42) -> 0.4
B41: No purchase date / Sin fecha | C41: =COUNTIF(Inventory!$V$6:$V$1005,5) -> 0 | D41: =ROUND(SUMIFS(Inventory!$G$6:$G$1005,Inventory!$V$6:$V$1005,5),2) -> 0 | E41: =ROUND(SUMIFS(Inventory!$I$6:$I$1005,Inventory!$V$6:$V$1005,5),2) -> 0 | F41: =IF($C$42=0,0,C41/$C$42) -> 0
B42: IN STOCK / EN INVENTARIO | C42: =SUM(C37:C41) -> 15 | D42: =SUM(D37:D41) -> 283 | E42: =SUM(E37:E41) -> 1107 | F42: =IF(C42=0,0,1) -> 1
B45: 10 Oldest Unsold Items – reprice, relist or bundle / 10 Artículos sin Vender más Antiguos – baja el precio o vuelve a publicar
B46: Item Artículo | C46: SKU Código | D46: Days Held Días | E46: Cost Costo | F46: List Price Precio | H46: Platform Plataforma | J46: Location Ubicación | K46: Alert Alerta
B47: =IFERROR(IF(LARGE(Inventory!$W$6:$W$1005,1)<-100000000000000,"—",INDEX(Inventory!$C$6:$C$1005,MATCH(LARGE(Inventory!$W$6:$W$1005,1),Inventory!$W$6:$W$1005,0))),"—") -> Levi's 501 Jeans 32x30 | C47: =IFERROR(IF(LARGE(Inventory!$W$6:$W$1005,1)<-100000000000000,"",INDEX(Inventory!$B$6:$B$1005,MATCH(LARGE(Inventory!$W$6:$W$1005,1),Inventory!$W$6:$W$1005,0))),"") -> A-001 | D47: =IFERROR(IF(LARGE(Inventory!$W$6:$W$1005,1)<-100000000000000,"",INDEX(Inventory!$N$6:$N$1005,MATCH(LARGE(Inventory!$W$6:$W$1005,1),Inventory!$W$6:$W$1005,0))),"") -> 206 | E47: =IFERROR(IF(LARGE(Inventory!$W$6:$W$1005,1)<-100000000000000,"",INDEX(Inventory!$G$6:$G$1005,MATCH(LARGE(Inventory!$W$6:$W$1005,1),Inventory!$W$6:$W$1005,0))),"") -> 6 | F47: =IFERROR(IF(LARGE(Inventory!$W$6:$W$1005,1)<-100000000000000,"",INDEX(Inventory!$I$6:$I$1005,MATCH(LARGE(Inventory!$W$6:$W$1005,1),Inventory!$W$6:$W$1005,0))),"") -> 38 | H47: =IFERROR(IF(LARGE(Inventory!$W$6:$W$1005,1)<-100000000000000,"",INDEX(Inventory!$H$6:$H$1005,MATCH(LARGE(Inventory!$W$6:$W$1005,1),Inventory!$W$6:$W$1005,0))),"") -> Poshmark | J47: =IFERROR(IF(LARGE(Inventory!$W$6:$W$1005,1)<-100000000000000,"",INDEX(Inventory!$M$6:$M$1005,MATCH(LARGE(Inventory!$W$6:$W$1005,1),Inventory!$W$6:$W$1005,0))),"") -> Bin 1 | K47: =IFERROR(IF(LARGE(Inventory!$W$6:$W$1005,1)<-100000000000000,"",INDEX(Inventory!$Q$6:$Q$1005,MATCH(LARGE(Inventory!$W$6:$W$1005,1),Inventory!$W$6:$W$1005,0))),"") -> ⚠ STALE – REPRICE / ESTANCADO
B48: =IFERROR(IF(LARGE(Inventory!$W$6:$W$1005,2)<-100000000000000,"—",INDEX(Inventory!$C$6:$C$1005,MATCH(LARGE(Inventory!$W$6:$W$1005,2),Inventory!$W$6:$W$1005,0))),"—") -> Coach Leather Crossbody | C48: =IFERROR(IF(LARGE(Inventory!$W$6:$W$1005,2)<-100000000000000,"",INDEX(Inventory!$B$6:$B$1005,MATCH(LARGE(Inventory!$W$6:$W$1005,2),Inventory!$W$6:$W$1005,0))),"") -> A-003 | D48: =IFERROR(IF(LARGE(Inventory!$W$6:$W$1005,2)<-100000000000000,"",INDEX(Inventory!$N$6:$N$1005,MATCH(LARGE(Inventory!$W$6:$W$1005,2),Inventory!$W$6:$W$1005,0))),"") -> 182 | E48: =IFERROR(IF(LARGE(Inventory!$W$6:$W$1005,2)<-100000000000000,"",INDEX(Inventory!$G$6:$G$1005,MATCH(LARGE(Inventory!$W$6:$W$1005,2),Inventory!$W$6:$W$1005,0))),"") -> 20 | F48: =IFERROR(IF(LARGE(Inventory!$W$6:$W$1005,2)<-100000000000000,"",INDEX(Inventory!$I$6:$I$1005,MATCH(LARGE(Inventory!$W$6:$W$1005,2),Inventory!$W$6:$W$1005,0))),"") -> 120 | H48: =IFERROR(IF(LARGE(Inventory!$W$6:$W$1005,2)<-100000000000000,"",INDEX(Inventory!$H$6:$H$1005,MATCH(LARGE(Inventory!$W$6:$W$1005,2),Inventory!$W$6:$W$1005,0))),"") -> Poshmark | J48: =IFERROR(IF(LARGE(Inventory!$W$6:$W$1005,2)<-100000000000000,"",INDEX(Inventory!$M$6:$M$1005,MATCH(LARGE(Inventory!$W$6:$W$1005,2),Inventory!$W$6:$W$1005,0))),"") -> Shelf B | K48: =IFERROR(IF(LARGE(Inventory!$W$6:$W$1005,2)<-100000000000000,"",INDEX(Inventory!$Q$6:$Q$1005,MATCH(LARGE(Inventory!$W$6:$W$1005,2),Inventory!$W$6:$W$1005,0))),"") -> ⚠ STALE – REPRICE / ESTANCADO
B49: =IFERROR(IF(LARGE(Inventory!$W$6:$W$1005,3)<-100000000000000,"—",INDEX(Inventory!$C$6:$C$1005,MATCH(LARGE(Inventory!$W$6:$W$1005,3),Inventory!$W$6:$W$1005,0))),"—") -> Lululemon Align Leggings | C49: =IFERROR(IF(LARGE(Inventory!$W$6:$W$1005,3)<-100000000000000,"",INDEX(Inventory!$B$6:$B$1005,MATCH(LARGE(Inventory!$W$6:$W$1005,3),Inventory!$W$6:$W$1005,0))),"") -> A-006 | D49: =IFERROR(IF(LARGE(Inventory!$W$6:$W$1005,3)<-100000000000000,"",INDEX(Inventory!$N$6:$N$1005,MATCH(LARGE(Inventory!$W$6:$W$1005,3),Inventory!$W$6:$W$1005,0))),"") -> 143 | E49: =IFERROR(IF(LARGE(Inventory!$W$6:$W$1005,3)<-100000000000000,"",INDEX(Inventory!$G$6:$G$1005,MATCH(LARGE(Inventory!$W$6:$W$1005,3),Inventory!$W$6:$W$1005,0))),"") -> 10 | F49: =IFERROR(IF(LARGE(Inventory!$W$6:$W$1005,3)<-100000000000000,"",INDEX(Inventory!$I$6:$I$1005,MATCH(LARGE(Inventory!$W$6:$W$1005,3),Inventory!$W$6:$W$1005,0))),"") -> 48 | H49: =IFERROR(IF(LARGE(Inventory!$W$6:$W$1005,3)<-100000000000000,"",INDEX(Inventory!$H$6:$H$1005,MATCH(LARGE(Inventory!$W$6:$W$1005,3),Inventory!$W$6:$W$1005,0))),"") -> Poshmark | J49: =IFERROR(IF(LARGE(Inventory!$W$6:$W$1005,3)<-100000000000000,"",INDEX(Inventory!$M$6:$M$1005,MATCH(LARGE(Inventory!$W$6:$W$1005,3),Inventory!$W$6:$W$1005,0))),"") -> Bin 1 | K49: =IFERROR(IF(LARGE(Inventory!$W$6:$W$1005,3)<-100000000000000,"",INDEX(Inventory!$Q$6:$Q$1005,MATCH(LARGE(Inventory!$W$6:$W$1005,3),Inventory!$W$6:$W$1005,0))),"") -> ⚠ STALE – REPRICE / ESTANCADO
...

Sheet Inventory
B1: ProfitTrack
B2: Inventory / Inventario
B3: One row per item. Type in the light-teal columns only – grey columns calculate automatically. • Una fila por artículo. Escribe solo en las columnas verde claro – las grises se calculan solas.
B5: SKU Código | C5: Item Name Artículo | D5: Category Categoría | E5: Source Fuente | F5: Purchase Date Fecha de Compra | G5: Cost Costo | H5: Platform Plataforma | I5: List Price Precio Publicado | J5: Status Estado | K5: Sold Date Fecha de Venta | L5: Sold Price Precio de Venta | M5: Location / Bin Ubicación | N5: Days Held Días | O5: Potential Profit Ganancia Potencial | P5: Gross Profit Ganancia Bruta | Q5: Age Alert Alerta | S5: Helper – do not edit: unsold | T5: Helper – do not edit: sold | U5: Helper – do not edit: age | V5: Helper – do not edit: age bucket | W5: Helper – do not edit: oldest key | X5: Helper – do not edit: days to sell | Y5: Helper – do not edit: has days to sell | Z5: Helper – do not edit: stale | AA5: Helper – do not edit: not listed | AB5: Helper – do not edit: gross profit | AC5: Helper – do not edit: potential profit
B6: A-001 | C6: Levi's 501 Jeans 32x30 | D6: Clothing / Ropa | E6: Goodwill | F6: 46089 | G6: 6 | H6: Poshmark | I6: 38 | J6: Listed / Publicado | M6: Bin 1 | N6: =IF(S6=1,IF(U6<0,"",U6),IF(Y6=1,X6,"")) -> 206 | O6: =IF(S6=1,IF(ISNUMBER(I6),I6-G6,""),"") -> 32 | P6: =IF(T6=1,IF(ISNUMBER(L6),L6-G6,""),"") | Q6: =IF(C6="","",IF(T6=1,"✔ SOLD / VENDIDO",IF(S6=0,"— CLOSED / CERRADO",IF(U6<0,"⚠ ADD DATE / AGREGA FECHA",IF(U6>=Settings!$C$8,"⚠ STALE – REPRICE / ESTANCADO",IF(U6>=Settings!$C$7,"● WATCH / VIGILAR","✔ FRESH / RECIENTE")))))) -> ⚠ STALE – REPRICE / ESTANCADO | S6: =IF(C6="",0,IF(OR(J6="",J6="In Stock / En Inventario",J6="Listed / Publicado"),1,0)) -> 1 | T6: =IF(C6="",0,IF(J6="Sold / Vendido",1,0)) -> 0 | U6: =IF(S6=1,IF(ISNUMBER(F6),TODAY()-F6,-1),-1) -> 206 | V6: =IF(U6<0,IF(S6=1,5,0),IF(U6<=30,1,IF(U6<=60,2,IF(U6<=90,3,4)))) -> 4 | W6: =IF(U6<0,-1000000000000000,U6+ROW()/1000000) -> 206.00001 | X6: =IF(T6=1,IF(AND(ISNUMBER(F6),ISNUMBER(K6)),K6-F6,0),0) -> 0 | Y6: =IF(T6=1,IF(AND(ISNUMBER(F6),ISNUMBER(K6)),1,0),0) -> 0 | Z6: =IF(U6>=Settings!$C$8,1,0) -> 1 | AA6: =IF(S6=1,IF(J6="Listed / Publicado",0,1),0) -> 0 | AB6: =IF(T6=1,IF(ISNUMBER(L6),L6-G6,0),0) -> 0 | AC6: =IF(S6=1,IF(ISNUMBER(I6),I6-G6,0),0) -> 32
B7: A-002 | C7: Nike Air Max 90 – Size 10 | D7: Shoes / Zapatos | E7: Garage sale | F7: 46096 | G7: 15 | H7: eBay | I7: 95 | J7: Sold / Vendido | K7: 46114 | L7: 89.99 | M7: Shelf A | N7: =IF(S7=1,IF(U7<0,"",U7),IF(Y7=1,X7,"")) -> 18 | O7: =IF(S7=1,IF(ISNUMBER(I7),I7-G7,""),"") | P7: =IF(T7=1,IF(ISNUMBER(L7),L7-G7,""),"") -> 74.99 | Q7: =IF(C7="","",IF(T7=1,"✔ SOLD / VENDIDO",IF(S7=0,"— CLOSED / CERRADO",IF(U7<0,"⚠ ADD DATE / AGREGA FECHA",IF(U7>=Settings!$C$8,"⚠ STALE – REPRICE / ESTANCADO",IF(U7>=Settings!$C$7,"● WATCH / VIGILAR","✔ FRESH / RECIENTE")))))) -> ✔ SOLD / VENDIDO | S7: =IF(C7="",0,IF(OR(J7="",J7="In Stock / En Inventario",J7="Listed / Publicado"),1,0)) -> 0 | T7: =IF(C7="",0,IF(J7="Sold / Vendido",1,0)) -> 1 | U7: =IF(S7=1,IF(ISNUMBER(F7),TODAY()-F7,-1),-1) -> -1 | V7: =IF(U7<0,IF(S7=1,5,0),IF(U7<=30,1,IF(U7<=60,2,IF(U7<=90,3,4)))) -> 0 | W7: =IF(U7<0,-1000000000000000,U7+ROW()/1000000) -> -1e+15 | X7: =IF(T7=1,IF(AND(ISNUMBER(F7),ISNUMBER(K7)),K7-F7,0),0) -> 18 | Y7: =IF(T7=1,IF(AND(ISNUMBER(F7),ISNUMBER(K7)),1,0),0) -> 1 | Z7: =IF(U7>=Settings!$C$8,1,0) -> 0 | AA7: =IF(S7=1,IF(J7="Listed / Publicado",0,1),0) -> 0 | AB7: =IF(T7=1,IF(ISNUMBER(L7),L7-G7,0),0) -> 74.99 | AC7: =IF(S7=1,IF(ISNUMBER(I7),I7-G7,0),0) -> 0
B8: A-003 | C8: Coach Leather Crossbody | D8: Bags & Accessories / Bolsos y Accesorios | E8: Estate sale | F8: 46113 | G8: 20 | H8: Poshmark | I8: 120 | J8: Listed / Publicado | M8: Shelf B | N8: =IF(S8=1,IF(U8<0,"",U8),IF(Y8=1,X8,"")) -> 182 | O8: =IF(S8=1,IF(ISNUMBER(I8),I8-G8,""),"") -> 100 | P8: =IF(T8=1,IF(ISNUMBER(L8),L8-G8,""),"") | Q8: =IF(C8="","",IF(T8=1,"✔ SOLD / VENDIDO",IF(S8=0,"— CLOSED / CERRADO",IF(U8<0,"⚠ ADD DATE / AGREGA FECHA",IF(U8>=Settings!$C$8,"⚠ STALE – REPRICE / ESTANCADO",IF(U8>=Settings!$C$7,"● WATCH / VIGILAR","✔ FRESH / RECIENTE")))))) -> ⚠ STALE – REPRICE / ESTANCADO | S8: =IF(C8="",0,IF(OR(J8="",J8="In Stock / En Inventario",J8="Listed / Publicado"),1,0)) -> 1 | T8: =IF(C8="",0,IF(J8="Sold / Vendido",1,0)) -> 0 | U8: =IF(S8=1,IF(ISNUMBER(F8),TODAY()-F8,-1),-1) -> 182 | V8: =IF(U8<0,IF(S8=1,5,0),IF(U8<=30,1,IF(U8<=60,2,IF(U8<=90,3,4)))) -> 4 | W8: =IF(U8<0,-1000000000000000,U8+ROW()/1000000) -> 182.00001 | X8: =IF(T8=1,IF(AND(ISNUMBER(F8),ISNUMBER(K8)),K8-F8,0),0) -> 0 | Y8: =IF(T8=1,IF(AND(ISNUMBER(F8),ISNUMBER(K8)),1,0),0) -> 0 | Z8: =IF(U8>=Settings!$C$8,1,0) -> 1 | AA8: =IF(S8=1,IF(J8="Listed / Publicado",0,1),0) -> 0 | AB8: =IF(T8=1,IF(ISNUMBER(L8),L8-G8,0),0) -> 0 | AC8: =IF(S8=1,IF(ISNUMBER(I8),I8-G8,0),0) -> 100
B9: A-004 | C9: Pyrex Butterprint Bowl | D9: Home & Kitchen / Hogar y Cocina | E9: Thrift store | F9: 46124 | G9: 8 | H9: Facebook Marketplace | I9: 45 | J9: Sold / Vendido | K9: 46145 | L9: 40 | M9: Shelf C | N9: =IF(S9=1,IF(U9<0,"",U9),IF(Y9=1,X9,"")) -> 21 | O9: =IF(S9=1,IF(ISNUMBER(I9),I9-G9,""),"") | P9: =IF(T9=1,IF(ISNUMBER(L9),L9-G9,""),"") -> 32 | Q9: =IF(C9="","",IF(T9=1,"✔ SOLD / VENDIDO",IF(S9=0,"— CLOSED / CERRADO",IF(U9<0,"⚠ ADD DATE / AGREGA FECHA",IF(U9>=Settings!$C$8,"⚠ STALE – REPRICE / ESTANCADO",IF(U9>=Settings!$C$7,"● WATCH / VIGILAR","✔ FRESH / RECIENTE")))))) -> ✔ SOLD / VENDIDO | S9: =IF(C9="",0,IF(OR(J9="",J9="In Stock / En Inventario",J9="Listed / Publicado"),1,0)) -> 0 | T9: =IF(C9="",0,IF(J9="Sold / Vendido",1,0)) -> 1 | U9: =IF(S9=1,IF(ISNUMBER(F9),TODAY()-F9,-1),-1) -> -1 | V9: =IF(U9<0,IF(S9=1,5,0),IF(U9<=30,1,IF(U9<=60,2,IF(U9<=90,3,4)))) -> 0 | W9: =IF(U9<0,-1000000000000000,U9+ROW()/1000000) -> -1e+15 | X9: =IF(T9=1,IF(AND(ISNUMBER(F9),ISNUMBER(K9)),K9-F9,0),0) -> 21 | Y9: =IF(T9=1,IF(AND(ISNUMBER(F9),ISNUMBER(K9)),1,0),0) -> 1 | Z9: =IF(U9>=Settings!$C$8,1,0) -> 0 | AA9: =IF(S9=1,IF(J9="Listed / Publicado",0,1),0) -> 0 | AB9: =IF(T9=1,IF(ISNUMBER(L9),L9-G9,0),0) -> 32 | AC9: =IF(S9=1,IF(ISNUMBER(I9),I9-G9,0),0) -> 0
B10: A-005 | C10: Vintage Polaroid SX-70 | D10: Electronics / Electrónicos | E10: Flea market | F10: 46144 | G10: 45 | H10: eBay | I10: 220 | J10: Sold / Vendido | K10: 46162 | L10: 210 | M10: Shelf D | N10: =IF(S10=1,IF(U10<0,"",U10),IF(Y10=1,X10,"")) -> 18 | O10: =IF(S10=1,IF(ISNUMBER(I10),I10-G10,""),"") | P10: =IF(T10=1,IF(ISNUMBER(L10),L10-G10,""),"") -> 165 | Q10: =IF(C10="","",IF(T10=1,"✔ SOLD / VENDIDO",IF(S10=0,"— CLOSED / CERRADO",IF(U10<0,"⚠ ADD DATE / AGREGA FECHA",IF(U10>=Settings!$C$8,"⚠ STALE – REPRICE / ESTANCADO",IF(U10>=Settings!$C$7,"● WATCH / VIGILAR","✔ FRESH / RECIENTE")))))) -> ✔ SOLD / VENDIDO | S10: =IF(C10="",0,IF(OR(J10="",J10="In Stock / En Inventario",J10="Listed / Publicado"),1,0)) -> 0 | T10: =IF(C10="",0,IF(J10="Sold / Vendido",1,0)) -> 1 | U10: =IF(S10=1,IF(ISNUMBER(F10),TODAY()-F10,-1),-1) -> -1 | V10: =IF(U10<0,IF(S10=1,5,0),IF(U10<=30,1,IF(U10<=60,2,IF(U10<=90,3,4)))) -> 0 | W10: =IF(U10<0,-1000000000000000,U10+ROW()/1000000) -> -1e+15 | X10: =IF(T10=1,IF(AND(ISNUMBER(F10),ISNUMBER(K10)),K10-F10,0),0) -> 18 | Y10: =IF(T10=1,IF(AND(ISNUMBER(F10),ISNUMBER(K10)),1,0),0) -> 1 | Z10: =IF(U10>=Settings!$C$8,1,0) -> 0 | AA10: =IF(S10=1,IF(J10="Listed / Publicado",0,1),0) -> 0 | AB10: =IF(T10=1,IF(ISNUMBER(L10),L10-G10,0),0) -> 165 | AC10: =IF(S10=1,IF(ISNUMBER(I10),I10-G10,0),0) -> 0
B11: A-006 | C11: Lululemon Align Leggings | D11: Clothing / Ropa | E11: Goodwill | F11: 46152 | G11: 10 | H11: Poshmark | I11: 48 | J11: Listed / Publicado | M11: Bin 1 | N11: =IF(S11=1,IF(U11<0,"",U11),IF(Y11=1,X11,"")) -> 143 | O11: =IF(S11=1,IF(ISNUMBER(I11),I11-G11,""),"") -> 38 | P11: =IF(T11=1,IF(ISNUMBER(L11),L11-G11,""),"") | Q11: =IF(C11="","",IF(T11=1,"✔ SOLD / VENDIDO",IF(S11=0,"— CLOSED / CERRADO",IF(U11<0,"⚠ ADD DATE / AGREGA FECHA",IF(U11>=Settings!$C$8,"⚠ STALE – REPRICE / ESTANCADO",IF(U11>=Settings!$C$7,"● WATCH / VIGILAR","✔ FRESH / RECIENTE")))))) -> ⚠ STALE – REPRICE / ESTANCADO | S11: =IF(C11="",0,IF(OR(J11="",J11="In Stock / En Inventario",J11="Listed / Publicado"),1,0)) -> 1 | T11: =IF(C11="",0,IF(J11="Sold / Vendido",1,0)) -> 0 | U11: =IF(S11=1,IF(ISNUMBER(F11),TODAY()-F11,-1),-1) -> 143 | V11: =IF(U11<0,IF(S11=1,5,0),IF(U11<=30,1,IF(U11<=60,2,IF(U11<=90,3,4)))) -> 4 | W11: =IF(U11<0,-1000000000000000,U11+ROW()/1000000) -> 143.00001 | X11: =IF(T11=1,IF(AND(ISNUMBER(F11),ISNUMBER(K11)),K11-F11,0),0) -> 0 | Y11: =IF(T11=1,IF(AND(ISNUMBER(F11),ISNUMBER(K11)),1,0),0) -> 0 | Z11: =IF(U11>=Settings!$C$8,1,0) -> 1 | AA11: =IF(S11=1,IF(J11="Listed / Publicado",0,1),0) -> 0 | AB11: =IF(T11=1,IF(ISNUMBER(L11),L11-G11,0),0) -> 0 | AC11: =IF(S11=1,IF(ISNUMBER(I11),I11-G11,0),0) -> 38
B12: A-007 | C12: LEGO Star Wars Lot | D12: Toys & Collectibles / Juguetes y Coleccionables | E12: Facebook | F12: 46160 | G12: 60 | H12: eBay | I12: 150 | J12: Listed / Publicado | M12: Shelf E | N12: =IF(S12=1,IF(U12<0,"",U12),IF(Y12=1,X12,"")) -> 135 | O12: =IF(S12=1,IF(ISNUMBER(I12),I12-G12,""),"") -> 90 | P12: =IF(T12=1,IF(ISNUMBER(L12),L12-G12,""),"") | Q12: =IF(C12="","",IF(T12=1,"✔ SOLD / VENDIDO",IF(S12=0,"— CLOSED / CERRADO",IF(U12<0,"⚠ ADD DATE / AGREGA FECHA",IF(U12>=Settings!$C$8,"⚠ STALE – REPRICE / ESTANCADO",IF(U12>=Settings!$C$7,"● WATCH / VIGILAR","✔ FRESH / RECIENTE")))))) -> ⚠ STALE – REPRICE / ESTANCADO | S12: =IF(C12="",0,IF(OR(J12="",J12="In Stock / En Inventario",J12="Listed / Publicado"),1,0)) -> 1 | T12: =IF(C12="",0,IF(J12="Sold / Vendido",1,0)) -> 0 | U12: =IF(S12=1,IF(ISNUMBER(F12),TODAY()-F12,-1),-1) -> 135 | V12: =IF(U12<0,IF(S12=1,5,0),IF(U12<=30,1,IF(U12<=60,2,IF(U12<=90,3,4)))) -> 4 | W12: =IF(U12<0,-1000000000000000,U12+ROW()/1000000) -> 135.00001 | X12: =IF(T12=1,IF(AND(ISNUMBER(F12),ISNUMBER(K12)),K12-F12,0),0) -> 0 | Y12: =IF(T12=1,IF(AND(ISNUMBER(F12),ISNUMBER(K12)),1,0),0) -> 0 | Z12: =IF(U12>=Settings!$C$8,1,0) -> 1 | AA12: =IF(S12=1,IF(J12="Listed / Publicado",0,1),0) -> 0 | AB12: =IF(T12=1,IF(ISNUMBER(L12),L12-G12,0),0) -> 0 | AC12: =IF(S12=1,IF(ISNUMBER(I12),I12-G12,0),0) -> 90
B13: A-008 | C13: Harry Potter Hardcover Set | D13: Books & Media / Libros y Medios | E13: Library sale | F13: 46174 | G13: 12 | H13: eBay | I13: 60 | J13: In Stock / En Inventario | M13: Bin 4 | N13: =IF(S13=1,IF(U13<0,"",U13),IF(Y13=1,X13,"")) -> 121 | O13: =IF(S13=1,IF(ISNUMBER(I13),I13-G13,""),"") -> 48 | P13: =IF(T13=1,IF(ISNUMBER(L13),L13-G13,""),"") | Q13: =IF(C13="","",IF(T13=1,"✔ SOLD / VENDIDO",IF(S13=0,"— CLOSED / CERRADO",IF(U13<0,"⚠ ADD DATE / AGREGA FECHA",IF(U13>=Settings!$C$8,"⚠ STALE – REPRICE / ESTANCADO",IF(U13>=Settings!$C$7,"● WATCH / VIGILAR","✔ FRESH / RECIENTE")))))) -> ⚠ STALE – REPRICE / ESTANCADO | S13: =IF(C13="",0,IF(OR(J13="",J13="In Stock / En Inventario",J13="Listed / Publicado"),1,0)) -> 1 | T13: =IF(C13="",0,IF(J13="Sold / Vendido",1,0)) -> 0 | U13: =IF(S13=1,IF(ISNUMBER(F13),TODAY()-F13,-1),-1) -> 121 | V13: =IF(U13<0,IF(S13=1,5,0),IF(U13<=30,1,IF(U13<=60,2,IF(U13<=90,3,4)))) -> 4 | W13: =IF(U13<0,-1000000000000000,U13+ROW()/1000000) -> 121.00001 | X13: =IF(T13=1,IF(AND(ISNUMBER(F13),ISNUMBER(K13)),K13-F13,0),0) -> 0 | Y13: =IF(T13=1,IF(AND(ISNUMBER(F13),ISNUMBER(K13)),1,0),0) -> 0 | Z13: =IF(U13>=Settings!$C$8,1,0) -> 1 | AA13: =IF(S13=1,IF(J13="Listed / Publicado",0,1),0) -> 1 | AB13: =IF(T13=1,IF(ISNUMBER(L13),L13-G13,0),0) -> 0 | AC13: =IF(S13=1,IF(ISNUMBER(I13),I13-G13,0),0) -> 48
B14: A-009 | C14: Mid-Century Teak Bowl | D14: Vintage & Antiques / Vintage y Antigüedades | E14: Estate sale | F14: 46187 | G14: 7 | H14: Etsy | I14: 55 | J14: Listed / Publicado | M14: Shelf C | N14: =IF(S14=1,IF(U14<0,"",U14),IF(Y14=1,X14,"")) -> 108 | O14: =IF(S14=1,IF(ISNUMBER(I14),I14-G14,""),"") -> 48 | P14: =IF(T14=1,IF(ISNUMBER(L14),L14-G14,""),"") | Q14: =IF(C14="","",IF(T14=1,"✔ SOLD / VENDIDO",IF(S14=0,"— CLOSED / CERRADO",IF(U14<0,"⚠ ADD DATE / AGREGA FECHA",IF(U14>=Settings!$C$8,"⚠ STALE – REPRICE / ESTANCADO",IF(U14>=Settings!$C$7,"● WATCH / VIGILAR","✔ FRESH / RECIENTE")))))) -> ⚠ STALE – REPRICE / ESTANCADO | S14: =IF(C14="",0,IF(OR(J14="",J14="In Stock / En Inventario",J14="Listed / Publicado"),1,0)) -> 1 | T14: =IF(C14="",0,IF(J14="Sold / Vendido",1,0)) -> 0 | U14: =IF(S14=1,IF(ISNUMBER(F14),TODAY()-F14,-1),-1) -> 108 | V14: =IF(U14<0,IF(S14=1,5,0),IF(U14<=30,1,IF(U14<=60,2,IF(U14<=90,3,4)))) -> 4 | W14: =IF(U14<0,-1000000000000000,U14+ROW()/1000000) -> 108.00001 | X14: =IF(T14=1,IF(AND(ISNUMBER(F14),ISNUMBER(K14)),K14-F14,0),0) -> 0 | Y14: =IF(T14=1,IF(AND(ISNUMBER(F14),ISNUMBER(K14)),1,0),0) -> 0 | Z14: =IF(U14>=Settings!$C$8,1,0) -> 1 | AA14: =IF(S14=1,IF(J14="Listed / Publicado",0,1),0) -> 0 | AB14: =IF(T14=1,IF(ISNUMBER(L14),L14-G14,0),0) -> 0 | AC14: =IF(S14=1,IF(ISNUMBER(I14),I14-G14,0),0) -> 48
B15: A-010 | C15: Patagonia Better Sweater M | D15: Clothing / Ropa | E15: Savers | F15: 46201 | G15: 12 | H15: eBay | I15: 64 | J15: Sold / Vendido | K15: 46212 | L15: 64 | M15: Bin 2 | N15: =IF(S15=1,IF(U15<0,"",U15),IF(Y15=1,X15,"")) -> 11 | O15: =IF(S15=1,IF(ISNUMBER(I15),I15-G15,""),"") | P15: =IF(T15=1,IF(ISNUMBER(L15),L15-G15,""),"") -> 52 | Q15: =IF(C15="","",IF(T15=1,"✔ SOLD / VENDIDO",IF(S15=0,"— CLOSED / CERRADO",IF(U15<0,"⚠ ADD DATE / AGREGA FECHA",IF(U15>=Settings!$C$8,"⚠ STALE – REPRICE / ESTANCADO",IF(U15>=Settings!$C$7,"● WATCH / VIGILAR","✔ FRESH / RECIENTE")))))) -> ✔ SOLD / VENDIDO | S15: =IF(C15="",0,IF(OR(J15="",J15="In Stock / En Inventario",J15="Listed / Publicado"),1,0)) -> 0 | T15: =IF(C15="",0,IF(J15="Sold / Vendido",1,0)) -> 1 | U15: =IF(S15=1,IF(ISNUMBER(F15),TODAY()-F15,-1),-1) -> -1 | V15: =IF(U15<0,IF(S15=1,5,0),IF(U15<=30,1,IF(U15<=60,2,IF(U15<=90,3,4)))) -> 0 | W15: =IF(U15<0,-1000000000000000,U15+ROW()/1000000) -> -1e+15 | X15: =IF(T15=1,IF(AND(ISNUMBER(F15),ISNUMBER(K15)),K15-F15,0),0) -> 11 | Y15: =IF(T15=1,IF(AND(ISNUMBER(F15),ISNUMBER(K15)),1,0),0) -> 1 | Z15: =IF(U15>=Settings!$C$8,1,0) -> 0 | AA15: =IF(S15=1,IF(J15="Listed / Publicado",0,1),0) -> 0 | AB15: =IF(T15=1,IF(ISNUMBER(L15),L15-G15,0),0) -> 52 | AC15: =IF(S15=1,IF(ISNUMBER(I15),I15-G15,0),0) -> 0
B16: A-011 | C16: Fossil Men's Watch | D16: Jewelry & Watches / Joyería y Relojes | E16: Garage sale | F16: 46208 | G16: 8 | H16: eBay | I16: 45 | J16: Listed / Publicado | M16: Drawer 1 | N16: =IF(S16=1,IF(U16<0,"",U16),IF(Y16=1,X16,"")) -> 87 | O16: =IF(S16=1,IF(ISNUMBER(I16),I16-G16,""),"") -> 37 | P16: =IF(T16=1,IF(ISNUMBER(L16),L16-G16,""),"") | Q16: =IF(C16="","",IF(T16=1,"✔ SOLD / VENDIDO",IF(S16=0,"— CLOSED / CERRADO",IF(U16<0,"⚠ ADD DATE / AGREGA FECHA",IF(U16>=Settings!$C$8,"⚠ STALE – REPRICE / ESTANCADO",IF(U16>=Settings!$C$7,"● WATCH / VIGILAR","✔ FRESH / RECIENTE")))))) -> ● WATCH / VIGILAR | S16: =IF(C16="",0,IF(OR(J16="",J16="In Stock / En Inventario",J16="Listed / Publicado"),1,0)) -> 1 | T16: =IF(C16="",0,IF(J16="Sold / Vendido",1,0)) -> 0 | U16: =IF(S16=1,IF(ISNUMBER(F16),TODAY()-F16,-1),-1) -> 87 | V16: =IF(U16<0,IF(S16=1,5,0),IF(U16<=30,1,IF(U16<=60,2,IF(U16<=90,3,4)))) -> 3 | W16: =IF(U16<0,-1000000000000000,U16+ROW()/1000000) -> 87.000016 | X16: =IF(T16=1,IF(AND(ISNUMBER(F16),ISNUMBER(K16)),K16-F16,0),0) -> 0 | Y16: =IF(T16=1,IF(AND(ISNUMBER(F16),ISNUMBER(K16)),1,0),0) -> 0 | Z16: =IF(U16>=Settings!$C$8,1,0) -> 0 | AA16: =IF(S16=1,IF(J16="Listed / Publicado",0,1),0) -> 0 | AB16: =IF(T16=1,IF(ISNUMBER(L16),L16-G16,0),0) -> 0 | AC16: =IF(S16=1,IF(ISNUMBER(I16),I16-G16,0),0) -> 37
B17: A-012 | C17: KitchenAid Mixer Bowl | D17: Home & Kitchen / Hogar y Cocina | E17: Thrift store | F17: 46215 | G17: 10 | H17: Facebook Marketplace | I17: 40 | J17: Listed / Publicado | M17: Shelf C | N17: =IF(S17=1,IF(U17<0,"",U17),IF(Y17=1,X17,"")) -> 80 | O17: =IF(S17=1,IF(ISNUMBER(I17),I17-G17,""),"") -> 30 | P17: =IF(T17=1,IF(ISNUMBER(L17),L17-G17,""),"") | Q17: =IF(C17="","",IF(T17=1,"✔ SOLD / VENDIDO",IF(S17=0,"— CLOSED / CERRADO",IF(U17<0,"⚠ ADD DATE / AGREGA FECHA",IF(U17>=Settings!$C$8,"⚠ STALE – REPRICE / ESTANCADO",IF(U17>=Settings!$C$7,"● WATCH / VIGILAR","✔ FRESH / RECIENTE")))))) -> ● WATCH / VIGILAR | S17: =IF(C17="",0,IF(OR(J17="",J17="In Stock / En Inventario",J17="Listed / Publicado"),1,0)) -> 1 | T17: =IF(C17="",0,IF(J17="Sold / Vendido",1,0)) -> 0 | U17: =IF(S17=1,IF(ISNUMBER(F17),TODAY()-F17,-1),-1) -> 80 | V17: =IF(U17<0,IF(S17=1,5,0),IF(U17<=30,1,IF(U17<=60,2,IF(U17<=90,3,4)))) -> 3 | W17: =IF(U17<0,-1000000000000000,U17+ROW()/1000000) -> 80.000017 | X17: =IF(T17=1,IF(AND(ISNUMBER(F17),ISNUMBER(K17)),K17-F17,0),0) -> 0 | Y17: =IF(T17=1,IF(AND(ISNUMBER(F17),ISNUMBER(K17)),1,0),0) -> 0 | Z17: =IF(U17>=Settings!$C$8,1,0) -> 0 | AA17: =IF(S17=1,IF(J17="Listed / Publicado",0,1),0) -> 0 | AB17: =IF(T17=1,IF(ISNUMBER(L17),L17-G17,0),0) -> 0 | AC17: =IF(S17=1,IF(ISNUMBER(I17),I17-G17,0),0) -> 30
B18: A-013 | C18: Funko Pop Exclusive | D18: Toys & Collectibles / Juguetes y Coleccionables | E18: Flea market | F18: 46223 | G18: 14 | H18: Other | I18: 22 | J18: Donated / Donado | M18: Bin 5 | N18: =IF(S18=1,IF(U18<0,"",U18),IF(Y18=1,X18,"")) | O18: =IF(S18=1,IF(ISNUMBER(I18),I18-G18,""),"") | P18: =IF(T18=1,IF(ISNUMBER(L18),L18-G18,""),"") | Q18: =IF(C18="","",IF(T18=1,"✔ SOLD / VENDIDO",IF(S18=0,"— CLOSED / CERRADO",IF(U18<0,"⚠ ADD DATE / AGREGA FECHA",IF(U18>=Settings!$C$8,"⚠ STALE – REPRICE / ESTANCADO",IF(U18>=Settings!$C$7,"● WATCH / VIGILAR","✔ FRESH / RECIENTE")))))) -> — CLOSED / CERRADO | S18: =IF(C18="",0,IF(OR(J18="",J18="In Stock / En Inventario",J18="Listed / Publicado"),1,0)) -> 0 | T18: =IF(C18="",0,IF(J18="Sold / Vendido",1,0)) -> 0 | U18: =IF(S18=1,IF(ISNUMBER(F18),TODAY()-F18,-1),-1) -> -1 | V18: =IF(U18<0,IF(S18=1,5,0),IF(U18<=30,1,IF(U18<=60,2,IF(U18<=90,3,4)))) -> 0 | W18: =IF(U18<0,-1000000000000000,U18+ROW()/1000000) -> -1e+15 | X18: =IF(T18=1,IF(AND(ISNUMBER(F18),ISNUMBER(K18)),K18-F18,0),0) -> 0 | Y18: =IF(T18=1,IF(AND(ISNUMBER(F18),ISNUMBER(K18)),1,0),0) -> 0 | Z18: =IF(U18>=Settings!$C$8,1,0) -> 0 | AA18: =IF(S18=1,IF(J18="Listed / Publicado",0,1),0) -> 0 | AB18: =IF(T18=1,IF(ISNUMBER(L18),L18-G18,0),0) -> 0 | AC18: =IF(S18=1,IF(ISNUMBER(I18),I18-G18,0),0) -> 0
B19: A-014 | C19: Dr. Martens 1460 – Size 8 | D19: Shoes / Zapatos | E19: Goodwill | F19: 46229 | G19: 18 | H19: Poshmark | I19: 85 | J19: Listed / Publicado | M19: Shelf A | N19: =IF(S19=1,IF(U19<0,"",U19),IF(Y19=1,X19,"")) -> 66 | O19: =IF(S19=1,IF(ISNUMBER(I19),I19-G19,""),"") -> 67 | P19: =IF(T19=1,IF(ISNUMBER(L19),L19-G19,""),"") | Q19: =IF(C19="","",IF(T19=1,"✔ SOLD / VENDIDO",IF(S19=0,"— CLOSED / CERRADO",IF(U19<0,"⚠ ADD DATE / AGREGA FECHA",IF(U19>=Settings!$C$8,"⚠ STALE – REPRICE / ESTANCADO",IF(U19>=Settings!$C$7,"● WATCH / VIGILAR","✔ FRESH / RECIENTE")))))) -> ● WATCH / VIGILAR | S19: =IF(C19="",0,IF(OR(J19="",J19="In Stock / En Inventario",J19="Listed / Publicado"),1,0)) -> 1 | T19: =IF(C19="",0,IF(J19="Sold / Vendido",1,0)) -> 0 | U19: =IF(S19=1,IF(ISNUMBER(F19),TODAY()-F19,-1),-1) -> 66 | V19: =IF(U19<0,IF(S19=1,5,0),IF(U19<=30,1,IF(U19<=60,2,IF(U19<=90,3,4)))) -> 3 | W19: =IF(U19<0,-1000000000000000,U19+ROW()/1000000) -> 66.000019 | X19: =IF(T19=1,IF(AND(ISNUMBER(F19),ISNUMBER(K19)),K19-F19,0),0) -> 0 | Y19: =IF(T19=1,IF(AND(ISNUMBER(F19),ISNUMBER(K19)),1,0),0) -> 0 | Z19: =IF(U19>=Settings!$C$8,1,0) -> 0 | AA19: =IF(S19=1,IF(J19="Listed / Publicado",0,1),0) -> 0 | AB19: =IF(T19=1,IF(ISNUMBER(L19),L19-G19,0),0) -> 0 | AC19: =IF(S19=1,IF(ISNUMBER(I19),I19-G19,0),0) -> 67
B20: A-015 | C20: Nintendo Switch Games (4) | D20: Electronics / Electrónicos | E20: Facebook | F20: 46237 | G20: 60 | H20: Facebook Marketplace | I20: 110 | J20: Sold / Vendido | K20: 46244 | L20: 110 | M20: Shelf D | N20: =IF(S20=1,IF(U20<0,"",U20),IF(Y20=1,X20,"")) -> 7 | O20: =IF(S20=1,IF(ISNUMBER(I20),I20-G20,""),"") | P20: =IF(T20=1,IF(ISNUMBER(L20),L20-G20,""),"") -> 50 | Q20: =IF(C20="","",IF(T20=1,"✔ SOLD / VENDIDO",IF(S20=0,"— CLOSED / CERRADO",IF(U20<0,"⚠ ADD DATE / AGREGA FECHA",IF(U20>=Settings!$C$8,"⚠ STALE – REPRICE / ESTANCADO",IF(U20>=Settings!$C$7,"● WATCH / VIGILAR","✔ FRESH / RECIENTE")))))) -> ✔ SOLD / VENDIDO | S20: =IF(C20="",0,IF(OR(J20="",J20="In Stock / En Inventario",J20="Listed / Publicado"),1,0)) -> 0 | T20: =IF(C20="",0,IF(J20="Sold / Vendido",1,0)) -> 1 | U20: =IF(S20=1,IF(ISNUMBER(F20),TODAY()-F20,-1),-1) -> -1 | V20: =IF(U20<0,IF(S20=1,5,0),IF(U20<=30,1,IF(U20<=60,2,IF(U20<=90,3,4)))) -> 0 | W20: =IF(U20<0,-1000000000000000,U20+ROW()/1000000) -> -1e+15 | X20: =IF(T20=1,IF(AND(ISNUMBER(F20),ISNUMBER(K20)),K20-F20,0),0) -> 7 | Y20: =IF(T20=1,IF(AND(ISNUMBER(F20),ISNUMBER(K20)),1,0),0) -> 1 | Z20: =IF(U20>=Settings!$C$8,1,0) -> 0 | AA20: =IF(S20=1,IF(J20="Listed / Publicado",0,1),0) -> 0 | AB20: =IF(T20=1,IF(ISNUMBER(L20),L20-G20,0),0) -> 50 | AC20: =IF(S20=1,IF(ISNUMBER(I20),I20-G20,0),0) -> 0
B21: A-016 | C21: Anthropologie Maxi Dress | D21: Clothing / Ropa | E21: Thrift store | F21: 46245 | G21: 7 | H21: Poshmark | I21: 36 | J21: Listed / Publicado | M21: Bin 2 | N21: =IF(S21=1,IF(U21<0,"",U21),IF(Y21=1,X21,"")) -> 50 | O21: =IF(S21=1,IF(ISNUMBER(I21),I21-G21,""),"") -> 29 | P21: =IF(T21=1,IF(ISNUMBER(L21),L21-G21,""),"") | Q21: =IF(C21="","",IF(T21=1,"✔ SOLD / VENDIDO",IF(S21=0,"— CLOSED / CERRADO",IF(U21<0,"⚠ ADD DATE / AGREGA FECHA",IF(U21>=Settings!$C$8,"⚠ STALE – REPRICE / ESTANCADO",IF(U21>=Settings!$C$7,"● WATCH / VIGILAR","✔ FRESH / RECIENTE")))))) -> ✔ FRESH / RECIENTE | S21: =IF(C21="",0,IF(OR(J21="",J21="In Stock / En Inventario",J21="Listed / Publicado"),1,0)) -> 1 | T21: =IF(C21="",0,IF(J21="Sold / Vendido",1,0)) -> 0 | U21: =IF(S21=1,IF(ISNUMBER(F21),TODAY()-F21,-1),-1) -> 50 | V21: =IF(U21<0,IF(S21=1,5,0),IF(U21<=30,1,IF(U21<=60,2,IF(U21<=90,3,4)))) -> 2 | W21: =IF(U21<0,-1000000000000000,U21+ROW()/1000000) -> 50.000021 | X21: =IF(T21=1,IF(AND(ISNUMBER(F21),ISNUMBER(K21)),K21-F21,0),0) -> 0 | Y21: =IF(T21=1,IF(AND(ISNUMBER(F21),ISNUMBER(K21)),1,0),0) -> 0 | Z21: =IF(U21>=Settings!$C$8,1,0) -> 0 | AA21: =IF(S21=1,IF(J21="Listed / Publicado",0,1),0) -> 0 | AB21: =IF(T21=1,IF(ISNUMBER(L21),L21-G21,0),0) -> 0 | AC21: =IF(S21=1,IF(ISNUMBER(I21),I21-G21,0),0) -> 29
B22: A-017 | C22: Vintage Band Tee – Nirvana | D22: Vintage & Antiques / Vintage y Antigüedades | E22: Estate sale | F22: 46253 | G22: 4 | H22: Etsy | I22: 55 | J22: Sold / Vendido | K22: 46266 | L22: 55 | M22: Bin 3 | N22: =IF(S22=1,IF(U22<0,"",U22),IF(Y22=1,X22,"")) -> 13 | O22: =IF(S22=1,IF(ISNUMBER(I22),I22-G22,""),"") | P22: =IF(T22=1,IF(ISNUMBER(L22),L22-G22,""),"") -> 51 | Q22: =IF(C22="","",IF(T22=1,"✔ SOLD / VENDIDO",IF(S22=0,"— CLOSED / CERRADO",IF(U22<0,"⚠ ADD DATE / AGREGA FECHA",IF(U22>=Settings!$C$8,"⚠ STALE – REPRICE / ESTANCADO",IF(U22>=Settings!$C$7,"● WATCH / VIGILAR","✔ FRESH / RECIENTE")))))) -> ✔ SOLD / VENDIDO | S22: =IF(C22="",0,IF(OR(J22="",J22="In Stock / En Inventario",J22="Listed / Publicado"),1,0)) -> 0 | T22: =IF(C22="",0,IF(J22="Sold / Vendido",1,0)) -> 1 | U22: =IF(S22=1,IF(ISNUMBER(F22),TODAY()-F22,-1),-1) -> -1 | V22: =IF(U22<0,IF(S22=1,5,0),IF(U22<=30,1,IF(U22<=60,2,IF(U22<=90,3,4)))) -> 0 | W22: =IF(U22<0,-1000000000000000,U22+ROW()/1000000) -> -1e+15 | X22: =IF(T22=1,IF(AND(ISNUMBER(F22),ISNUMBER(K22)),K22-F22,0),0) -> 13 | Y22: =IF(T22=1,IF(AND(ISNUMBER(F22),ISNUMBER(K22)),1,0),0) -> 1 | Z22: =IF(U22>=Settings!$C$8,1,0) -> 0 | AA22: =IF(S22=1,IF(J22="Listed / Publicado",0,1),0) -> 0 | AB22: =IF(T22=1,IF(ISNUMBER(L22),L22-G22,0),0) -> 51 | AC22: =IF(S22=1,IF(ISNUMBER(I22),I22-G22,0),0) -> 0
B23: A-018 | C23: Pandora Charm Bracelet | D23: Jewelry & Watches / Joyería y Relojes | E23: Garage sale | F23: 46264 | G23: 15 | H23: eBay | I23: 70 | J23: Listed / Publicado | M23: Drawer 1 | N23: =IF(S23=1,IF(U23<0,"",U23),IF(Y23=1,X23,"")) -> 31 | O23: =IF(S23=1,IF(ISNUMBER(I23),I23-G23,""),"") -> 55 | P23: =IF(T23=1,IF(ISNUMBER(L23),L23-G23,""),"") | Q23: =IF(C23="","",IF(T23=1,"✔ SOLD / VENDIDO",IF(S23=0,"— CLOSED / CERRADO",IF(U23<0,"⚠ ADD DATE / AGREGA FECHA",IF(U23>=Settings!$C$8,"⚠ STALE – REPRICE / ESTANCADO",IF(U23>=Settings!$C$7,"● WATCH / VIGILAR","✔ FRESH / RECIENTE")))))) -> ✔ FRESH / RECIENTE | S23: =IF(C23="",0,IF(OR(J23="",J23="In Stock / En Inventario",J23="Listed / Publicado"),1,0)) -> 1 | T23: =IF(C23="",0,IF(J23="Sold / Vendido",1,0)) -> 0 | U23: =IF(S23=1,IF(ISNUMBER(F23),TODAY()-F23,-1),-1) -> 31 | V23: =IF(U23<0,IF(S23=1,5,0),IF(U23<=30,1,IF(U23<=60,2,IF(U23<=90,3,4)))) -> 2 | W23: =IF(U23<0,-1000000000000000,U23+ROW()/1000000) -> 31.000023 | X23: =IF(T23=1,IF(AND(ISNUMBER(F23),ISNUMBER(K23)),K23-F23,0),0) -> 0 | Y23: =IF(T23=1,IF(AND(ISNUMBER(F23),ISNUMBER(K23)),1,0),0) -> 0 | Z23: =IF(U23>=Settings!$C$8,1,0) -> 0 | AA23: =IF(S23=1,IF(J23="Listed / Publicado",0,1),0) -> 0 | AB23: =IF(T23=1,IF(ISNUMBER(L23),L23-G23,0),0) -> 0 | AC23: =IF(S23=1,IF(ISNUMBER(I23),I23-G23,0),0) -> 55
B24: A-019 | C24: Carhartt Detroit Jacket | D24: Clothing / Ropa | E24: Bins outlet | F24: 46271 | G24: 18 | H24: eBay | I24: 135 | J24: Listed / Publicado | M24: Rack 1 | N24: =IF(S24=1,IF(U24<0,"",U24),IF(Y24=1,X24,"")) -> 24 | O24: =IF(S24=1,IF(ISNUMBER(I24),I24-G24,""),"") -> 117 | P24: =IF(T24=1,IF(ISNUMBER(L24),L24-G24,""),"") | Q24: =IF(C24="","",IF(T24=1,"✔ SOLD / VENDIDO",IF(S24=0,"— CLOSED / CERRADO",IF(U24<0,"⚠ ADD DATE / AGREGA FECHA",IF(U24>=Settings!$C$8,"⚠ STALE – REPRICE / ESTANCADO",IF(U24>=Settings!$C$7,"● WATCH / VIGILAR","✔ FRESH / RECIENTE")))))) -> ✔ FRESH / RECIENTE | S24: =IF(C24="",0,IF(OR(J24="",J24="In Stock / En Inventario",J24="Listed / Publicado"),1,0)) -> 1 | T24: =IF(C24="",0,IF(J24="Sold / Vendido",1,0)) -> 0 | U24: =IF(S24=1,IF(ISNUMBER(F24),TODAY()-F24,-1),-1) -> 24 | V24: =IF(U24<0,IF(S24=1,5,0),IF(U24<=30,1,IF(U24<=60,2,IF(U24<=90,3,4)))) -> 1 | W24: =IF(U24<0,-1000000000000000,U24+ROW()/1000000) -> 24.000024 | X24: =IF(T24=1,IF(AND(ISNUMBER(F24),ISNUMBER(K24)),K24-F24,0),0) -> 0 | Y24: =IF(T24=1,IF(AND(ISNUMBER(F24),ISNUMBER(K24)),1,0),0) -> 0 | Z24: =IF(U24>=Settings!$C$8,1,0) -> 0 | AA24: =IF(S24=1,IF(J24="Listed / Publicado",0,1),0) -> 0 | AB24: =IF(T24=1,IF(ISNUMBER(L24),L24-G24,0),0) -> 0 | AC24: =IF(S24=1,IF(ISNUMBER(I24),I24-G24,0),0) -> 117
B25: A-020 | C25: Le Creuset Dutch Oven | D25: Home & Kitchen / Hogar y Cocina | E25: Estate sale | F25: 46278 | G25: 60 | H25: Facebook Marketplace | I25: 180 | J25: In Stock / En Inventario | M25: Shelf C | N25: =IF(S25=1,IF(U25<0,"",U25),IF(Y25=1,X25,"")) -> 17 | O25: =IF(S25=1,IF(ISNUMBER(I25),I25-G25,""),"") -> 120 | P25: =IF(T25=1,IF(ISNUMBER(L25),L25-G25,""),"") | Q25: =IF(C25="","",IF(T25=1,"✔ SOLD / VENDIDO",IF(S25=0,"— CLOSED / CERRADO",IF(U25<0,"⚠ ADD DATE / AGREGA FECHA",IF(U25>=Settings!$C$8,"⚠ STALE – REPRICE / ESTANCADO",IF(U25>=Settings!$C$7,"● WATCH / VIGILAR","✔ FRESH / RECIENTE")))))) -> ✔ FRESH / RECIENTE | S25: =IF(C25="",0,IF(OR(J25="",J25="In Stock / En Inventario",J25="Listed / Publicado"),1,0)) -> 1 | T25: =IF(C25="",0,IF(J25="Sold / Vendido",1,0)) -> 0 | U25: =IF(S25=1,IF(ISNUMBER(F25),TODAY()-F25,-1),-1) -> 17 | V25: =IF(U25<0,IF(S25=1,5,0),IF(U25<=30,1,IF(U25<=60,2,IF(U25<=90,3,4)))) -> 1 | W25: =IF(U25<0,-1000000000000000,U25+ROW()/1000000) -> 17.000025 | X25: =IF(T25=1,IF(AND(ISNUMBER(F25),ISNUMBER(K25)),K25-F25,0),0) -> 0 | Y25: =IF(T25=1,IF(AND(ISNUMBER(F25),ISNUMBER(K25)),1,0),0) -> 0 | Z25: =IF(U25>=Settings!$C$8,1,0) -> 0 | AA25: =IF(S25=1,IF(J25="Listed / Publicado",0,1),0) -> 1 | AB25: =IF(T25=1,IF(ISNUMBER(L25),L25-G25,0),0) -> 0 | AC25: =IF(S25=1,IF(ISNUMBER(I25),I25-G25,0),0) -> 120
B26: A-021 | C26: Kindle Paperwhite | D26: Electronics / Electrónicos | E26: Goodwill | F26: 46285 | G26: 20 | J26: In Stock / En Inventario | M26: Shelf D | N26: =IF(S26=1,IF(U26<0,"",U26),IF(Y26=1,X26,"")) -> 10 | O26: =IF(S26=1,IF(ISNUMBER(I26),I26-G26,""),"") | P26: =IF(T26=1,IF(ISNUMBER(L26),L26-G26,""),"") | Q26: =IF(C26="","",IF(T26=1,"✔ SOLD / VENDIDO",IF(S26=0,"— CLOSED / CERRADO",IF(U26<0,"⚠ ADD DATE / AGREGA FECHA",IF(U26>=Settings!$C$8,"⚠ STALE – REPRICE / ESTANCADO",IF(U26>=Settings!$C$7,"● WATCH / VIGILAR","✔ FRESH / RECIENTE")))))) -> ✔ FRESH / RECIENTE | S26: =IF(C26="",0,IF(OR(J26="",J26="In Stock / En Inventario",J26="Listed / Publicado"),1,0)) -> 1 | T26: =IF(C26="",0,IF(J26="Sold / Vendido",1,0)) -> 0 | U26: =IF(S26=1,IF(ISNUMBER(F26),TODAY()-F26,-1),-1) -> 10 | V26: =IF(U26<0,IF(S26=1,5,0),IF(U26<=30,1,IF(U26<=60,2,IF(U26<=90,3,4)))) -> 1 | W26: =IF(U26<0,-1000000000000000,U26+ROW()/1000000) -> 10.000026 | X26: =IF(T26=1,IF(AND(ISNUMBER(F26),ISNUMBER(K26)),K26-F26,0),0) -> 0 | Y26: =IF(T26=1,IF(AND(ISNUMBER(F26),ISNUMBER(K26)),1,0),0) -> 0 | Z26: =IF(U26>=Settings!$C$8,1,0) -> 0 | AA26: =IF(S26=1,IF(J26="Listed / Publicado",0,1),0) -> 1 | AB26: =IF(T26=1,IF(ISNUMBER(L26),L26-G26,0),0) -> 0 | AC26: =IF(S26=1,IF(ISNUMBER(I26),I26-G26,0),0) -> 0
B27: A-022 | C27: Vintage Pyrex Casserole | D27: Home & Kitchen / Hogar y Cocina | E27: Thrift store | F27: 46292 | G27: 12 | H27: Etsy | I27: 45 | J27: In Stock / En Inventario | M27: Shelf C | N27: =IF(S27=1,IF(U27<0,"",U27),IF(Y27=1,X27,"")) -> 3 | O27: =IF(S27=1,IF(ISNUMBER(I27),I27-G27,""),"") -> 33 | P27: =IF(T27=1,IF(ISNUMBER(L27),L27-G27,""),"") | Q27: =IF(C27="","",IF(T27=1,"✔ SOLD / VENDIDO",IF(S27=0,"— CLOSED / CERRADO",IF(U27<0,"⚠ ADD DATE / AGREGA FECHA",IF(U27>=Settings!$C$8,"⚠ STALE – REPRICE / ESTANCADO",IF(U27>=Settings!$C$7,"● WATCH / VIGILAR","✔ FRESH / RECIENTE")))))) -> ✔ FRESH / RECIENTE | S27: =IF(C27="",0,IF(OR(J27="",J27="In Stock / En Inventario",J27="Listed / Publicado"),1,0)) -> 1 | T27: =IF(C27="",0,IF(J27="Sold / Vendido",1,0)) -> 0 | U27: =IF(S27=1,IF(ISNUMBER(F27),TODAY()-F27,-1),-1) -> 3 | V27: =IF(U27<0,IF(S27=1,5,0),IF(U27<=30,1,IF(U27<=60,2,IF(U27<=90,3,4)))) -> 1 | W27: =IF(U27<0,-1000000000000000,U27+ROW()/1000000) -> 3.000027 | X27: =IF(T27=1,IF(AND(ISNUMBER(F27),ISNUMBER(K27)),K27-F27,0),0) -> 0 | Y27: =IF(T27=1,IF(AND(ISNUMBER(F27),ISNUMBER(K27)),1,0),0) -> 0 | Z27: =IF(U27>=Settings!$C$8,1,0) -> 0 | AA27: =IF(S27=1,IF(J27="Listed / Publicado",0,1),0) -> 1 | AB27: =IF(T27=1,IF(ISNUMBER(L27),L27-G27,0),0) -> 0 | AC27: =IF(S27=1,IF(ISNUMBER(I27),I27-G27,0),0) -> 33
N28: =IF(S28=1,IF(U28<0,"",U28),IF(Y28=1,X28,"")) | O28: =IF(S28=1,IF(ISNUMBER(I28),I28-G28,""),"") | P28: =IF(T28=1,IF(ISNUMBER(L28),L28-G28,""),"") | Q28: =IF(C28="","",IF(T28=1,"✔ SOLD / VENDIDO",IF(S28=0,"— CLOSED / CERRADO",IF(U28<0,"⚠ ADD DATE / AGREGA FECHA",IF(U28>=Settings!$C$8,"⚠ STALE – REPRICE / ESTANCADO",IF(U28>=Settings!$C$7,"● WATCH / VIGILAR","✔ FRESH / RECIENTE")))))) | S28: =IF(C28="",0,IF(OR(J28="",J28="In Stock / En Inventario",J28="Listed / Publicado"),1,0)) -> 0 | T28: =IF(C28="",0,IF(J28="Sold / Vendido",1,0)) -> 0 | U28: =IF(S28=1,IF(ISNUMBER(F28),TODAY()-F28,-1),-1) -> -1 | V28: =IF(U28<0,IF(S28=1,5,0),IF(U28<=30,1,IF(U28<=60,2,IF(U28<=90,3,4)))) -> 0 | W28: =IF(U28<0,-1000000000000000,U28+ROW()/1000000) -> -1e+15 | X28: =IF(T28=1,IF(AND(ISNUMBER(F28),ISNUMBER(K28)),K28-F28,0),0) -> 0 | Y28: =IF(T28=1,IF(AND(ISNUMBER(F28),ISNUMBER(K28)),1,0),0) -> 0 | Z28: =IF(U28>=Settings!$C$8,1,0) -> 0 | AA28: =IF(S28=1,IF(J28="Listed / Publicado",0,1),0) -> 0 | AB28: =IF(T28=1,IF(ISNUMBER(L28),L28-G28,0),0) -> 0 | AC28: =IF(S28=1,IF(ISNUMBER(I28),I28-G28,0),0) -> 0
N29: =IF(S29=1,IF(U29<0,"",U29),IF(Y29=1,X29,"")) | O29: =IF(S29=1,IF(ISNUMBER(I29),I29-G29,""),"") | P29: =IF(T29=1,IF(ISNUMBER(L29),L29-G29,""),"") | Q29: =IF(C29="","",IF(T29=1,"✔ SOLD / VENDIDO",IF(S29=0,"— CLOSED / CERRADO",IF(U29<0,"⚠ ADD DATE / AGREGA FECHA",IF(U29>=Settings!$C$8,"⚠ STALE – REPRICE / ESTANCADO",IF(U29>=Settings!$C$7,"● WATCH / VIGILAR","✔ FRESH / RECIENTE")))))) | S29: =IF(C29="",0,IF(OR(J29="",J29="In Stock / En Inventario",J29="Listed / Publicado"),1,0)) -> 0 | T29: =IF(C29="",0,IF(J29="Sold / Vendido",1,0)) -> 0 | U29: =IF(S29=1,IF(ISNUMBER(F29),TODAY()-F29,-1),-1) -> -1 | V29: =IF(U29<0,IF(S29=1,5,0),IF(U29<=30,1,IF(U29<=60,2,IF(U29<=90,3,4)))) -> 0 | W29: =IF(U29<0,-1000000000000000,U29+ROW()/1000000) -> -1e+15 | X29: =IF(T29=1,IF(AND(ISNUMBER(F29),ISNUMBER(K29)),K29-F29,0),0) -> 0 | Y29: =IF(T29=1,IF(AND(ISNUMBER(F29),ISNUMBER(K29)),1,0),0) -> 0 | Z29: =IF(U29>=Settings!$C$8,1,0) -> 0 | AA29: =IF(S29=1,IF(J29="Listed / Publicado",0,1),0) -> 0 | AB29: =IF(T29=1,IF(ISNUMBER(L29),L29-G29,0),0) -> 0 | AC29: =IF(S29=1,IF(ISNUMBER(I29),I29-G29,0),0) -> 0
N30: =IF(S30=1,IF(U30<0,"",U30),IF(Y30=1,X30,"")) | O30: =IF(S30=1,IF(ISNUMBER(I30),I30-G30,""),"") | P30: =IF(T30=1,IF(ISNUMBER(L30),L30-G30,""),"") | Q30: =IF(C30="","",IF(T30=1,"✔ SOLD / VENDIDO",IF(S30=0,"— CLOSED / CERRADO",IF(U30<0,"⚠ ADD DATE / AGREGA FECHA",IF(U30>=Settings!$C$8,"⚠ STALE – REPRICE / ESTANCADO",IF(U30>=Settings!$C$7,"● WATCH / VIGILAR","✔ FRESH / RECIENTE")))))) | S30: =IF(C30="",0,IF(OR(J30="",J30="In Stock / En Inventario",J30="Listed / Publicado"),1,0)) -> 0 | T30: =IF(C30="",0,IF(J30="Sold / Vendido",1,0)) -> 0 | U30: =IF(S30=1,IF(ISNUMBER(F30),TODAY()-F30,-1),-1) -> -1 | V30: =IF(U30<0,IF(S30=1,5,0),IF(U30<=30,1,IF(U30<=60,2,IF(U30<=90,3,4)))) -> 0 | W30: =IF(U30<0,-1000000000000000,U30+ROW()/1000000) -> -1e+15 | X30: =IF(T30=1,IF(AND(ISNUMBER(F30),ISNUMBER(K30)),K30-F30,0),0) -> 0 | Y30: =IF(T30=1,IF(AND(ISNUMBER(F30),ISNUMBER(K30)),1,0),0) -> 0 | Z30: =IF(U30>=Settings!$C$8,1,0) -> 0 | AA30: =IF(S30=1,IF(J30="Listed / Publicado",0,1),0) -> 0 | AB30: =IF(T30=1,IF(ISNUMBER(L30),L30-G30,0),0) -> 0 | AC30: =IF(S30=1,IF(ISNUMBER(I30),I30-G30,0),0) -> 0
N31: =IF(S31=1,IF(U31<0,"",U31),IF(Y31=1,X31,"")) | O31: =IF(S31=1,IF(ISNUMBER(I31),I31-G31,""),"") | P31: =IF(T31=1,IF(ISNUMBER(L31),L31-G31,""),"") | Q31: =IF(C31="","",IF(T31=1,"✔ SOLD / VENDIDO",IF(S31=0,"— CLOSED / CERRADO",IF(U31<0,"⚠ ADD DATE / AGREGA FECHA",IF(U31>=Settings!$C$8,"⚠ STALE – REPRICE / ESTANCADO",IF(U31>=Settings!$C$7,"● WATCH / VIGILAR","✔ FRESH / RECIENTE")))))) | S31: =IF(C31="",0,IF(OR(J31="",J31="In Stock / En Inventario",J31="Listed / Publicado"),1,0)) -> 0 | T31: =IF(C31="",0,IF(J31="Sold / Vendido",1,0)) -> 0 | U31: =IF(S31=1,IF(ISNUMBER(F31),TODAY()-F31,-1),-1) -> -1 | V31: =IF(U31<0,IF(S31=1,5,0),IF(U31<=30,1,IF(U31<=60,2,IF(U31<=90,3,4)))) -> 0 | W31: =IF(U31<0,-1000000000000000,U31+ROW()/1000000) -> -1e+15 | X31: =IF(T31=1,IF(AND(ISNUMBER(F31),ISNUMBER(K31)),K31-F31,0),0) -> 0 | Y31: =IF(T31=1,IF(AND(ISNUMBER(F31),ISNUMBER(K31)),1,0),0) -> 0 | Z31: =IF(U31>=Settings!$C$8,1,0) -> 0 | AA31: =IF(S31=1,IF(J31="Listed / Publicado",0,1),0) -> 0 | AB31: =IF(T31=1,IF(ISNUMBER(L31),L31-G31,0),0) -> 0 | AC31: =IF(S31=1,IF(ISNUMBER(I31),I31-G31,0),0) -> 0
N32: =IF(S32=1,IF(U32<0,"",U32),IF(Y32=1,X32,"")) | O32: =IF(S32=1,IF(ISNUMBER(I32),I32-G32,""),"") | P32: =IF(T32=1,IF(ISNUMBER(L32),L32-G32,""),"") | Q32: =IF(C32="","",IF(T32=1,"✔ SOLD / VENDIDO",IF(S32=0,"— CLOSED / CERRADO",IF(U32<0,"⚠ ADD DATE / AGREGA FECHA",IF(U32>=Settings!$C$8,"⚠ STALE – REPRICE / ESTANCADO",IF(U32>=Settings!$C$7,"● WATCH / VIGILAR","✔ FRESH / RECIENTE")))))) | S32: =IF(C32="",0,IF(OR(J32="",J32="In Stock / En Inventario",J32="Listed / Publicado"),1,0)) -> 0 | T32: =IF(C32="",0,IF(J32="Sold / Vendido",1,0)) -> 0 | U32: =IF(S32=1,IF(ISNUMBER(F32),TODAY()-F32,-1),-1) -> -1 | V32: =IF(U32<0,IF(S32=1,5,0),IF(U32<=30,1,IF(U32<=60,2,IF(U32<=90,3,4)))) -> 0 | W32: =IF(U32<0,-1000000000000000,U32+ROW()/1000000) -> -1e+15 | X32: =IF(T32=1,IF(AND(ISNUMBER(F32),ISNUMBER(K32)),K32-F32,0),0) -> 0 | Y32: =IF(T32=1,IF(AND(ISNUMBER(F32),ISNUMBER(K32)),1,0),0) -> 0 | Z32: =IF(U32>=Settings!$C$8,1,0) -> 0 | AA32: =IF(S32=1,IF(J32="Listed / Publicado",0,1),0) -> 0 | AB32: =IF(T32=1,IF(ISNUMBER(L32),L32-G32,0),0) -> 0 | AC32: =IF(S32=1,IF(ISNUMBER(I32),I32-G32,0),0) -> 0
N33: =IF(S33=1,IF(U33<0,"",U33),IF(Y33=1,X33,"")) | O33: =IF(S33=1,IF(ISNUMBER(I33),I33-G33,""),"") | P33: =IF(T33=1,IF(ISNUMBER(L33),L33-G33,""),"") | Q33: =IF(C33="","",IF(T33=1,"✔ SOLD / VENDIDO",IF(S33=0,"— CLOSED / CERRADO",IF(U33<0,"⚠ ADD DATE / AGREGA FECHA",IF(U33>=Settings!$C$8,"⚠ STALE – REPRICE / ESTANCADO",IF(U33>=Settings!$C$7,"● WATCH / VIGILAR","✔ FRESH / RECIENTE")))))) | S33: =IF(C33="",0,IF(OR(J33="",J33="In Stock / En Inventario",J33="Listed / Publicado"),1,0)) -> 0 | T33: =IF(C33="",0,IF(J33="Sold / Vendido",1,0)) -> 0 | U33: =IF(S33=1,IF(ISNUMBER(F33),TODAY()-F33,-1),-1) -> -1 | V33: =IF(U33<0,IF(S33=1,5,0),IF(U33<=30,1,IF(U33<=60,2,IF(U33<=90,3,4)))) -> 0 | W33: =IF(U33<0,-1000000000000000,U33+ROW()/1000000) -> -1e+15 | X33: =IF(T33=1,IF(AND(ISNUMBER(F33),ISNUMBER(K33)),K33-F33,0),0) -> 0 | Y33: =IF(T33=1,IF(AND(ISNUMBER(F33),ISNUMBER(K33)),1,0),0) -> 0 | Z33: =IF(U33>=Settings!$C$8,1,0) -> 0 | AA33: =IF(S33=1,IF(J33="Listed / Publicado",0,1),0) -> 0 | AB33: =IF(T33=1,IF(ISNUMBER(L33),L33-G33,0),0) -> 0 | AC33: =IF(S33=1,IF(ISNUMBER(I33),I33-G33,0),0) -> 0
N34: =IF(S34=1,IF(U34<0,"",U34),IF(Y34=1,X34,"")) | O34: =IF(S34=1,IF(ISNUMBER(I34),I34-G34,""),"") | P34: =IF(T34=1,IF(ISNUMBER(L34),L34-G34,""),"") | Q34: =IF(C34="","",IF(T34=1,"✔ SOLD / VENDIDO",IF(S34=0,"— CLOSED / CERRADO",IF(U34<0,"⚠ ADD DATE / AGREGA FECHA",IF(U34>=Settings!$C$8,"⚠ STALE – REPRICE / ESTANCADO",IF(U34>=Settings!$C$7,"● WATCH / VIGILAR","✔ FRESH / RECIENTE")))))) | S34: =IF(C34="",0,IF(OR(J34="",J34="In Stock / En Inventario",J34="Listed / Publicado"),1,0)) -> 0 | T34: =IF(C34="",0,IF(J34="Sold / Vendido",1,0)) -> 0 | U34: =IF(S34=1,IF(ISNUMBER(F34),TODAY()-F34,-1),-1) -> -1 | V34: =IF(U34<0,IF(S34=1,5,0),IF(U34<=30,1,IF(U34<=60,2,IF(U34<=90,3,4)))) -> 0 | W34: =IF(U34<0,-1000000000000000,U34+ROW()/1000000) -> -1e+15 | X34: =IF(T34=1,IF(AND(ISNUMBER(F34),ISNUMBER(K34)),K34-F34,0),0) -> 0 | Y34: =IF(T34=1,IF(AND(ISNUMBER(F34),ISNUMBER(K34)),1,0),0) -> 0 | Z34: =IF(U34>=Settings!$C$8,1,0) -> 0 | AA34: =IF(S34=1,IF(J34="Listed / Publicado",0,1),0) -> 0 | AB34: =IF(T34=1,IF(ISNUMBER(L34),L34-G34,0),0) -> 0 | AC34: =IF(S34=1,IF(ISNUMBER(I34),I34-G34,0),0) -> 0
N35: =IF(S35=1,IF(U35<0,"",U35),IF(Y35=1,X35,"")) | O35: =IF(S35=1,IF(ISNUMBER(I35),I35-G35,""),"") | P35: =IF(T35=1,IF(ISNUMBER(L35),L35-G35,""),"") | Q35: =IF(C35="","",IF(T35=1,"✔ SOLD / VENDIDO",IF(S35=0,"— CLOSED / CERRADO",IF(U35<0,"⚠ ADD DATE / AGREGA FECHA",IF(U35>=Settings!$C$8,"⚠ STALE – REPRICE / ESTANCADO",IF(U35>=Settings!$C$7,"● WATCH / VIGILAR","✔ FRESH / RECIENTE")))))) | S35: =IF(C35="",0,IF(OR(J35="",J35="In Stock / En Inventario",J35="Listed / Publicado"),1,0)) -> 0 | T35: =IF(C35="",0,IF(J35="Sold / Vendido",1,0)) -> 0 | U35: =IF(S35=1,IF(ISNUMBER(F35),TODAY()-F35,-1),-1) -> -1 | V35: =IF(U35<0,IF(S35=1,5,0),IF(U35<=30,1,IF(U35<=60,2,IF(U35<=90,3,4)))) -> 0 | W35: =IF(U35<0,-1000000000000000,U35+ROW()/1000000) -> -1e+15 | X35: =IF(T35=1,IF(AND(ISNUMBER(F35),ISNUMBER(K35)),K35-F35,0),0) -> 0 | Y35: =IF(T35=1,IF(AND(ISNUMBER(F35),ISNUMBER(K35)),1,0),0) -> 0 | Z35: =IF(U35>=Settings!$C$8,1,0) -> 0 | AA35: =IF(S35=1,IF(J35="Listed / Publicado",0,1),0) -> 0 | AB35: =IF(T35=1,IF(ISNUMBER(L35),L35-G35,0),0) -> 0 | AC35: =IF(S35=1,IF(ISNUMBER(I35),I35-G35,0),0) -> 0
N36: =IF(S36=1,IF(U36<0,"",U36),IF(Y36=1,X36,"")) | O36: =IF(S36=1,IF(ISNUMBER(I36),I36-G36,""),"") | P36: =IF(T36=1,IF(ISNUMBER(L36),L36-G36,""),"") | Q36: =IF(C36="","",IF(T36=1,"✔ SOLD / VENDIDO",IF(S36=0,"— CLOSED / CERRADO",IF(U36<0,"⚠ ADD DATE / AGREGA FECHA",IF(U36>=Settings!$C$8,"⚠ STALE – REPRICE / ESTANCADO",IF(U36>=Settings!$C$7,"● WATCH / VIGILAR","✔ FRESH / RECIENTE")))))) | S36: =IF(C36="",0,IF(OR(J36="",J36="In Stock / En Inventario",J36="Listed / Publicado"),1,0)) -> 0 | T36: =IF(C36="",0,IF(J36="Sold / Vendido",1,0)) -> 0 | U36: =IF(S36=1,IF(ISNUMBER(F36),TODAY()-F36,-1),-1) -> -1 | V36: =IF(U36<0,IF(S36=1,5,0),IF(U36<=30,1,IF(U36<=60,2,IF(U36<=90,3,4)))) -> 0 | W36: =IF(U36<0,-1000000000000000,U36+ROW()/1000000) -> -1e+15 | X36: =IF(T36=1,IF(AND(ISNUMBER(F36),ISNUMBER(K36)),K36-F36,0),0) -> 0 | Y36: =IF(T36=1,IF(AND(ISNUMBER(F36),ISNUMBER(K36)),1,0),0) -> 0 | Z36: =IF(U36>=Settings!$C$8,1,0) -> 0 | AA36: =IF(S36=1,IF(J36="Listed / Publicado",0,1),0) -> 0 | AB36: =IF(T36=1,IF(ISNUMBER(L36),L36-G36,0),0) -> 0 | AC36: =IF(S36=1,IF(ISNUMBER(I36),I36-G36,0),0) -> 0
N37: =IF(S37=1,IF(U37<0,"",U37),IF(Y37=1,X37,"")) | O37: =IF(S37=1,IF(ISNUMBER(I37),I37-G37,""),"") | P37: =IF(T37=1,IF(ISNUMBER(L37),L37-G37,""),"") | Q37: =IF(C37="","",IF(T37=1,"✔ SOLD / VENDIDO",IF(S37=0,"— CLOSED / CERRADO",IF(U37<0,"⚠ ADD DATE / AGREGA FECHA",IF(U37>=Settings!$C$8,"⚠ STALE – REPRICE / ESTANCADO",IF(U37>=Settings!$C$7,"● WATCH / VIGILAR","✔ FRESH / RECIENTE")))))) | S37: =IF(C37="",0,IF(OR(J37="",J37="In Stock / En Inventario",J37="Listed / Publicado"),1,0)) -> 0 | T37: =IF(C37="",0,IF(J37="Sold / Vendido",1,0)) -> 0 | U37: =IF(S37=1,IF(ISNUMBER(F37),TODAY()-F37,-1),-1) -> -1 | V37: =IF(U37<0,IF(S37=1,5,0),IF(U37<=30,1,IF(U37<=60,2,IF(U37<=90,3,4)))) -> 0 | W37: =IF(U37<0,-1000000000000000,U37+ROW()/1000000) -> -1e+15 | X37: =IF(T37=1,IF(AND(ISNUMBER(F37),ISNUMBER(K37)),K37-F37,0),0) -> 0 | Y37: =IF(T37=1,IF(AND(ISNUMBER(F37),ISNUMBER(K37)),1,0),0) -> 0 | Z37: =IF(U37>=Settings!$C$8,1,0) -> 0 | AA37: =IF(S37=1,IF(J37="Listed / Publicado",0,1),0) -> 0 | AB37: =IF(T37=1,IF(ISNUMBER(L37),L37-G37,0),0) -> 0 | AC37: =IF(S37=1,IF(ISNUMBER(I37),I37-G37,0),0) -> 0
N38: =IF(S38=1,IF(U38<0,"",U38),IF(Y38=1,X38,"")) | O38: =IF(S38=1,IF(ISNUMBER(I38),I38-G38,""),"") | P38: =IF(T38=1,IF(ISNUMBER(L38),L38-G38,""),"") | Q38: =IF(C38="","",IF(T38=1,"✔ SOLD / VENDIDO",IF(S38=0,"— CLOSED / CERRADO",IF(U38<0,"⚠ ADD DATE / AGREGA FECHA",IF(U38>=Settings!$C$8,"⚠ STALE – REPRICE / ESTANCADO",IF(U38>=Settings!$C$7,"● WATCH / VIGILAR","✔ FRESH / RECIENTE")))))) | S38: =IF(C38="",0,IF(OR(J38="",J38="In Stock / En Inventario",J38="Listed / Publicado"),1,0)) -> 0 | T38: =IF(C38="",0,IF(J38="Sold / Vendido",1,0)) -> 0 | U38: =IF(S38=1,IF(ISNUMBER(F38),TODAY()-F38,-1),-1) -> -1 | V38: =IF(U38<0,IF(S38=1,5,0),IF(U38<=30,1,IF(U38<=60,2,IF(U38<=90,3,4)))) -> 0 | W38: =IF(U38<0,-1000000000000000,U38+ROW()/1000000) -> -1e+15 | X38: =IF(T38=1,IF(AND(ISNUMBER(F38),ISNUMBER(K38)),K38-F38,0),0) -> 0 | Y38: =IF(T38=1,IF(AND(ISNUMBER(F38),ISNUMBER(K38)),1,0),0) -> 0 | Z38: =IF(U38>=Settings!$C$8,1,0) -> 0 | AA38: =IF(S38=1,IF(J38="Listed / Publicado",0,1),0) -> 0 | AB38: =IF(T38=1,IF(ISNUMBER(L38),L38-G38,0),0) -> 0 | AC38: =IF(S38=1,IF(ISNUMBER(I38),I38-G38,0),0) -> 0
N39: =IF(S39=1,IF(U39<0,"",U39),IF(Y39=1,X39,"")) | O39: =IF(S39=1,IF(ISNUMBER(I39),I39-G39,""),"") | P39: =IF(T39=1,IF(ISNUMBER(L39),L39-G39,""),"") | Q39: =IF(C39="","",IF(T39=1,"✔ SOLD / VENDIDO",IF(S39=0,"— CLOSED / CERRADO",IF(U39<0,"⚠ ADD DATE / AGREGA FECHA",IF(U39>=Settings!$C$8,"⚠ STALE – REPRICE / ESTANCADO",IF(U39>=Settings!$C$7,"● WATCH / VIGILAR","✔ FRESH / RECIENTE")))))) | S39: =IF(C39="",0,IF(OR(J39="",J39="In Stock / En Inventario",J39="Listed / Publicado"),1,0)) -> 0 | T39: =IF(C39="",0,IF(J39="Sold / Vendido",1,0)) -> 0 | U39: =IF(S39=1,IF(ISNUMBER(F39),TODAY()-F39,-1),-1) -> -1 | V39: =IF(U39<0,IF(S39=1,5,0),IF(U39<=30,1,IF(U39<=60,2,IF(U39<=90,3,4)))) -> 0 | W39: =IF(U39<0,-1000000000000000,U39+ROW()/1000000) -> -1e+15 | X39: =IF(T39=1,IF(AND(ISNUMBER(F39),ISNUMBER(K39)),K39-F39,0),0) -> 0 | Y39: =IF(T39=1,IF(AND(ISNUMBER(F39),ISNUMBER(K39)),1,0),0) -> 0 | Z39: =IF(U39>=Settings!$C$8,1,0) -> 0 | AA39: =IF(S39=1,IF(J39="Listed / Publicado",0,1),0) -> 0 | AB39: =IF(T39=1,IF(ISNUMBER(L39),L39-G39,0),0) -> 0 | AC39: =IF(S39=1,IF(ISNUMBER(I39),I39-G39,0),0) -> 0
... N1005: =IF(S1005=1,IF(U1005<0,"",U1005),IF(Y1005=1,X1005,"")) | O1005: =IF(S1005=1,IF(ISNUMBER(I1005),I1005-G1005,""),"") | P1005: =IF(T1005=1,IF(ISNUMBER(L1005),L1005-G1005,""),"") | Q1005: =IF(C1005="","",IF(T1005=1,"✔ SOLD / VENDIDO",IF(S1005=0,"— CLOSED / CERRADO",IF(U1005<0,"⚠ ADD DATE / AGREGA FECHA",IF(U1005>=Settings!$C$8,"⚠ STALE – REPRICE / ESTANCADO",IF(U1005>=Settings!$C$7,"● WATCH / VIGILAR","✔ FRESH / RECIENTE")))))) | S1005: =IF(C1005="",0,IF(OR(J1005="",J1005="In Stock / En Inventario",J1005="Listed / Publicado"),1,0)) -> 0 | T1005: =IF(C1005="",0,IF(J1005="Sold / Vendido",1,0)) -> 0 | U1005: =IF(S1005=1,IF(ISNUMBER(F1005),TODAY()-F1005,-1),-1) -> -1 | V1005: =IF(U1005<0,IF(S1005=1,5,0),IF(U1005<=30,1,IF(U1005<=60,2,IF(U1005<=90,3,4)))) -> 0 | W1005: =IF(U1005<0,-1000000000000000,U1005+ROW()/1000000) -> -1e+15 | X1005: =IF(T1005=1,IF(AND(ISNUMBER(F1005),ISNUMBER(K1005)),K1005-F1005,0),0) -> 0 | Y1005: =IF(T1005=1,IF(AND(ISNUMBER(F1005),ISNUMBER(K1005)),1,0),0) -> 0 | Z1005: =IF(U1005>=Settings!$C$8,1,0) -> 0 | AA1005: =IF(S1005=1,IF(J1005="Listed / Publicado",0,1),0) -> 0 | AB1005: =IF(T1005=1,IF(ISNUMBER(L1005),L1005-G1005,0),0) -> 0 | AC1005: =IF(S1005=1,IF(ISNUMBER(I1005),I1005-G1005,0),0) -> 0

